<?xml version="1.0" ?>
<!-- =================================================================================== -->
<!-- |    This document was autogenerated by xacro from cob4-8.urdf.xacro              | -->
<!-- |    EDITING THIS FILE BY HAND IS NOT RECOMMENDED                                 | -->
<!-- =================================================================================== -->
<robot name="cob4-8" xmlns:xacro="http://www.ros.org/wiki/xacro">
  <material name="IPA/LightGrey">
    <color rgba="0.7 0.7 0.7 1.0"/>
  </material>
  <material name="IPA/DarkGrey">
    <color rgba="0.4 0.4 0.4 1.0"/>
  </material>
  <material name="IPA/Black">
    <color rgba="0.0 0.0 0.0 1.0"/>
  </material>
  <material name="IPA/Metall">
    <color rgba="0.7 0.7 0.7 1.0"/>
  </material>
  <material name="IPA/YellowRubber">
    <color rgba="0.4 0.27 0.16 1.0"/>
  </material>
  <material name="IPA/Orange">
    <color rgba="1.0 0.4 0.0 1.0"/>
  </material>
  <material name="IPA/Blue">
    <color rgba="0.0 0.0 0.5 1.0"/>
  </material>
  <!-- *********************** -->
  <!-- upper robot calibration -->
  <!-- *********************** -->
  <!-- *********************************** -->
  <!-- kinematic chain reference positions -->
  <!-- *********************************** -->
  <!-- this feature is no longer supported as urdfdom does not parse the according 'calibration_rising' tag -->
  <!-- *********************** -->
  <!-- upper robot calibration -->
  <!-- *********************** -->
  <!-- *********************************** -->
  <!-- kinematic chain reference positions -->
  <!-- *********************************** -->
  <!-- this feature is no longer supported as urdfdom does not parse the according 'calibration_rising' tag -->
  <!-- *********************** -->
  <!-- upper robot calibration -->
  <!-- *********************** -->
  <!-- *********************************** -->
  <!-- kinematic chain reference positions -->
  <!-- *********************************** -->
  <!-- this feature is no longer supported as urdfdom does not parse the according 'calibration_rising' tag -->
  <link name="base_footprint"/>
  <joint name="base_footprint_joint" type="fixed">
    <origin rpy="0 0 0" xyz="0 0 0"/>
    <parent link="base_footprint"/>
    <child link="base_link"/>
  </joint>
  <link name="base_link">
    <inertial>
      <origin xyz="0 0 0"/>
      <mass value="100"/>
      <inertia ixx="5.652232699207" ixy="-0.009719934438" ixz="1.293988226423" iyy="5.669473158652" iyz="-0.007379583694" izz="3.683196351726"/>
    </inertial>
    <visual>
      <origin rpy="0 0 0" xyz="0 0 0"/>
      <geometry>
        <mesh filename="package://cob_description/meshes/cob4_base/base.dae"/>
        <!--box size="0.01 0.01 0.01" /-->
      </geometry>
    </visual>
    <collision>
      <origin rpy="0 0 0" xyz="0 0 0"/>
      <geometry>
        <mesh filename="package://cob_description/meshes/cob4_base/base_collision.stl"/>
        <!--box size="0.01 0.01 0.01" /-->
      </geometry>
    </collision>
  </link>
  <joint name="fl_caster_rotation_joint" type="continuous">
    <origin rpy="0 0 0" xyz="0.12422 0.21515 0.08"/>
    <parent link="base_link"/>
    <child link="fl_caster_rotation_link"/>
    <axis xyz="0 0 1"/>
    <safety_controller k_velocity="10"/>
    <limit effort="100" velocity="117.81"/>
    <dynamics damping="0.0" friction="0.0"/>
  </joint>
  <link name="fl_caster_rotation_link">
    <inertial>
      <origin xyz="0 0 0"/>
      <mass value="5.9"/>
      <inertia ixx="0.04" ixy="-0.0007" ixz="0.0" iyy="0.02" iyz="-0.000004" izz="0.05"/>
    </inertial>
    <visual>
      <geometry>
        <mesh filename="package://cob_description/meshes/drive_wheel/caster.stl"/>
      </geometry>
      <material name="IPA/LightGrey"/>
    </visual>
    <collision>
      <geometry>
        <box size="0.001 0.001 0.001"/>
      </geometry>
    </collision>
  </link>
  <transmission name="fl_caster_rotation_trans">
    <type>transmission_interface/SimpleTransmission</type>
    <joint name="fl_caster_rotation_joint">
      <hardwareInterface>VelocityJointInterface</hardwareInterface>
    </joint>
    <actuator name="fl_caster_rotation_motor">
      <mechanicalReduction>-79.2380952381</mechanicalReduction>
    </actuator>
  </transmission>
  <joint name="fl_caster_r_wheel_joint" type="continuous">
    <origin rpy="0 0 0" xyz="0 -0.0 0"/>
    <parent link="fl_caster_rotation_link"/>
    <child link="fl_caster_r_wheel_link"/>
    <axis xyz="0 1 0"/>
    <safety_controller k_velocity="10"/>
    <limit effort="100" velocity="19.95"/>
    <dynamics damping="0.0" friction="0.0"/>
  </joint>
  <link name="fl_caster_r_wheel_link">
    <inertial>
      <origin xyz="0 0 0"/>
      <mass value="0.44036"/>
      <inertia ixx="0.012411765597" ixy="-0.000711733678" ixz="0.00050272983" iyy="0.015218160428" iyz="-0.000004273467" izz="0.011763977943"/>
    </inertial>
    <visual>
      <geometry>
        <mesh filename="package://cob_description/meshes/drive_wheel/wheel.dae"/>
      </geometry>
    </visual>
    <collision>
      <geometry>
        <mesh filename="package://cob_description/meshes/drive_wheel/wheel.stl"/>
      </geometry>
    </collision>
  </link>
  <gazebo reference="fl_caster_r_wheel_link">
    <gravity>true</gravity>
    <self_collide>false</self_collide>
  </gazebo>
  <transmission name="fl_caster_r_wheel_trans">
    <type>transmission_interface/SimpleTransmission</type>
    <joint name="fl_caster_r_wheel_joint">
      <hardwareInterface>VelocityJointInterface</hardwareInterface>
    </joint>
    <actuator name="fl_caster_r_wheel_motor">
      <mechanicalReduction>-79.2380952381</mechanicalReduction>
    </actuator>
  </transmission>
  <gazebo reference="fl_caster_rotation_link">
    <gravity>true</gravity>
    <self_collide>false</self_collide>
    <material value="IPA/Metal"/>
  </gazebo>
  <joint name="b_caster_rotation_joint" type="continuous">
    <origin rpy="0 0 0" xyz="-0.24844 0.0 0.08"/>
    <parent link="base_link"/>
    <child link="b_caster_rotation_link"/>
    <axis xyz="0 0 1"/>
    <safety_controller k_velocity="10"/>
    <limit effort="100" velocity="117.81"/>
    <dynamics damping="0.0" friction="0.0"/>
  </joint>
  <link name="b_caster_rotation_link">
    <inertial>
      <origin xyz="0 0 0"/>
      <mass value="5.9"/>
      <inertia ixx="0.04" ixy="-0.0007" ixz="0.0" iyy="0.02" iyz="-0.000004" izz="0.05"/>
    </inertial>
    <visual>
      <geometry>
        <mesh filename="package://cob_description/meshes/drive_wheel/caster.stl"/>
      </geometry>
      <material name="IPA/LightGrey"/>
    </visual>
    <collision>
      <geometry>
        <box size="0.001 0.001 0.001"/>
      </geometry>
    </collision>
  </link>
  <transmission name="b_caster_rotation_trans">
    <type>transmission_interface/SimpleTransmission</type>
    <joint name="b_caster_rotation_joint">
      <hardwareInterface>VelocityJointInterface</hardwareInterface>
    </joint>
    <actuator name="b_caster_rotation_motor">
      <mechanicalReduction>-79.2380952381</mechanicalReduction>
    </actuator>
  </transmission>
  <joint name="b_caster_r_wheel_joint" type="continuous">
    <origin rpy="0 0 0" xyz="0 -0.0 0"/>
    <parent link="b_caster_rotation_link"/>
    <child link="b_caster_r_wheel_link"/>
    <axis xyz="0 1 0"/>
    <safety_controller k_velocity="10"/>
    <limit effort="100" velocity="19.95"/>
    <dynamics damping="0.0" friction="0.0"/>
  </joint>
  <link name="b_caster_r_wheel_link">
    <inertial>
      <origin xyz="0 0 0"/>
      <mass value="0.44036"/>
      <inertia ixx="0.012411765597" ixy="-0.000711733678" ixz="0.00050272983" iyy="0.015218160428" iyz="-0.000004273467" izz="0.011763977943"/>
    </inertial>
    <visual>
      <geometry>
        <mesh filename="package://cob_description/meshes/drive_wheel/wheel.dae"/>
      </geometry>
    </visual>
    <collision>
      <geometry>
        <mesh filename="package://cob_description/meshes/drive_wheel/wheel.stl"/>
      </geometry>
    </collision>
  </link>
  <gazebo reference="b_caster_r_wheel_link">
    <gravity>true</gravity>
    <self_collide>false</self_collide>
  </gazebo>
  <transmission name="b_caster_r_wheel_trans">
    <type>transmission_interface/SimpleTransmission</type>
    <joint name="b_caster_r_wheel_joint">
      <hardwareInterface>VelocityJointInterface</hardwareInterface>
    </joint>
    <actuator name="b_caster_r_wheel_motor">
      <mechanicalReduction>-79.2380952381</mechanicalReduction>
    </actuator>
  </transmission>
  <gazebo reference="b_caster_rotation_link">
    <gravity>true</gravity>
    <self_collide>false</self_collide>
    <material value="IPA/Metal"/>
  </gazebo>
  <joint name="fr_caster_rotation_joint" type="continuous">
    <origin rpy="0 0 0" xyz="0.12422 -0.21515 0.08"/>
    <parent link="base_link"/>
    <child link="fr_caster_rotation_link"/>
    <axis xyz="0 0 1"/>
    <safety_controller k_velocity="10"/>
    <limit effort="100" velocity="117.81"/>
    <dynamics damping="0.0" friction="0.0"/>
  </joint>
  <link name="fr_caster_rotation_link">
    <inertial>
      <origin xyz="0 0 0"/>
      <mass value="5.9"/>
      <inertia ixx="0.04" ixy="-0.0007" ixz="0.0" iyy="0.02" iyz="-0.000004" izz="0.05"/>
    </inertial>
    <visual>
      <geometry>
        <mesh filename="package://cob_description/meshes/drive_wheel/caster.stl"/>
      </geometry>
      <material name="IPA/LightGrey"/>
    </visual>
    <collision>
      <geometry>
        <box size="0.001 0.001 0.001"/>
      </geometry>
    </collision>
  </link>
  <transmission name="fr_caster_rotation_trans">
    <type>transmission_interface/SimpleTransmission</type>
    <joint name="fr_caster_rotation_joint">
      <hardwareInterface>VelocityJointInterface</hardwareInterface>
    </joint>
    <actuator name="fr_caster_rotation_motor">
      <mechanicalReduction>-79.2380952381</mechanicalReduction>
    </actuator>
  </transmission>
  <joint name="fr_caster_r_wheel_joint" type="continuous">
    <origin rpy="0 0 0" xyz="0 -0.0 0"/>
    <parent link="fr_caster_rotation_link"/>
    <child link="fr_caster_r_wheel_link"/>
    <axis xyz="0 1 0"/>
    <safety_controller k_velocity="10"/>
    <limit effort="100" velocity="19.95"/>
    <dynamics damping="0.0" friction="0.0"/>
  </joint>
  <link name="fr_caster_r_wheel_link">
    <inertial>
      <origin xyz="0 0 0"/>
      <mass value="0.44036"/>
      <inertia ixx="0.012411765597" ixy="-0.000711733678" ixz="0.00050272983" iyy="0.015218160428" iyz="-0.000004273467" izz="0.011763977943"/>
    </inertial>
    <visual>
      <geometry>
        <mesh filename="package://cob_description/meshes/drive_wheel/wheel.dae"/>
      </geometry>
    </visual>
    <collision>
      <geometry>
        <mesh filename="package://cob_description/meshes/drive_wheel/wheel.stl"/>
      </geometry>
    </collision>
  </link>
  <gazebo reference="fr_caster_r_wheel_link">
    <gravity>true</gravity>
    <self_collide>false</self_collide>
  </gazebo>
  <transmission name="fr_caster_r_wheel_trans">
    <type>transmission_interface/SimpleTransmission</type>
    <joint name="fr_caster_r_wheel_joint">
      <hardwareInterface>VelocityJointInterface</hardwareInterface>
    </joint>
    <actuator name="fr_caster_r_wheel_motor">
      <mechanicalReduction>-79.2380952381</mechanicalReduction>
    </actuator>
  </transmission>
  <gazebo reference="fr_caster_rotation_link">
    <gravity>true</gravity>
    <self_collide>false</self_collide>
    <material value="IPA/Metal"/>
  </gazebo>
  <gazebo reference="base_link">
    <gravity>true</gravity>
    <self_collide>false</self_collide>
    <sensor name="base_contact_sensor" type="contact">
      <always_on>true</always_on>
      <update_rate>100.0</update_rate>
      <contact>
        <collision>base_link_collision</collision>
        <topic>base_bumper</topic>
      </contact>
      <plugin filename="libgazebo_ros_bumper.so" name="base_gazebo_ros_bumper_controller">
        <frameName>world</frameName>
        <bumperTopicName>base_bumper</bumperTopicName>
      </plugin>
    </sensor>
  </gazebo>
  <gazebo>
    <plugin filename="libgazebo_ros_p3d.so" name="p3d_base_controller">
      <alwaysOn>true</alwaysOn>
      <updateRate>100.0</updateRate>
      <bodyName>base_link</bodyName>
      <topicName>base_pose_ground_truth</topicName>
      <frameName>map</frameName>
      <xyzOffsets>25.7 25.7 0</xyzOffsets>
      <!-- initialize odometry for fake localization-->
      <rpyOffsets>0 0 0</rpyOffsets>
      <gaussianNoise>0.01</gaussianNoise>
    </plugin>
    <canonicalBody>base_footprint</canonicalBody>
  </gazebo>
  <!-- ros_control plugin -->
  <gazebo>
    <plugin filename="libhwi_switch_gazebo_ros_control.so" name="ros_control">
      <robotNamespace>base</robotNamespace>
      <filterJointsParam>joint_names</filterJointsParam>
    </plugin>
  </gazebo>
  <joint name="base_laser_front_joint" type="fixed">
    <origin rpy="0.0 0.0 0.0" xyz="0.244 0.0 0.20858"/>
    <parent link="base_link"/>
    <child link="base_laser_front_link"/>
  </joint>
  <link name="base_laser_front_link" type="laser">
    <inertial>
      <mass value="1.2"/>
      <origin rpy="0 0 0" xyz="0 0 0"/>
      <inertia ixx="0.0029999988" ixy="0.0" ixz="0.0" iyy="0.0029999988" iyz="0.0" izz="0.0015"/>
    </inertial>
    <visual>
      <origin rpy="0 0 0" xyz="0 0 0"/>
      <geometry>
        <mesh filename="package://cob_description/meshes/sensors/sick_s300_laser.dae"/>
        <!--box size="0.001 0.001 0.001" /-->
      </geometry>
      <material name="IPA/LightGrey"/>
    </visual>
    <collision>
      <origin rpy="0 0 0" xyz="0 0 0"/>
      <geometry>
        <mesh filename="package://cob_description/meshes/sensors/sick_s300_laser_collision.stl"/>
      </geometry>
    </collision>
  </link>
  <gazebo reference="base_laser_front_link">
    <sensor name="base_laser_front" type="ray">
      <always_on>true</always_on>
      <update_rate>12.0</update_rate>
      <pose>0 0 0 0 0 0</pose>
      <visualize>false</visualize>
      <ray>
        <scan>
          <horizontal>
            <samples>541</samples>
            <resolution>1.0</resolution>
            <min_angle>-2.3562</min_angle>
            <max_angle>2.3562</max_angle>
          </horizontal>
        </scan>
        <range>
          <min>0.05</min>
          <max>29.5</max>
          <resolution>0.03</resolution>
        </range>
        <noise>
          <type>gaussian</type>
          <mean>0.0</mean>
          <stddev>0.02</stddev>
        </noise>
      </ray>
      <plugin filename="libgazebo_ros_laser.so" name="gazebo_ros_base_laser_front_controller">
        <topicName>base_laser_front/scan_raw</topicName>
        <frameName>base_laser_front_link</frameName>
      </plugin>
    </sensor>
  </gazebo>
  <joint name="base_laser_left_joint" type="fixed">
    <origin rpy="0.0 0.0 2.094" xyz="-0.122 0.21131 0.20858"/>
    <parent link="base_link"/>
    <child link="base_laser_left_link"/>
  </joint>
  <link name="base_laser_left_link" type="laser">
    <inertial>
      <mass value="1.2"/>
      <origin rpy="0 0 0" xyz="0 0 0"/>
      <inertia ixx="0.0029999988" ixy="0.0" ixz="0.0" iyy="0.0029999988" iyz="0.0" izz="0.0015"/>
    </inertial>
    <visual>
      <origin rpy="0 0 0" xyz="0 0 0"/>
      <geometry>
        <mesh filename="package://cob_description/meshes/sensors/sick_s300_laser.dae"/>
        <!--box size="0.001 0.001 0.001" /-->
      </geometry>
      <material name="IPA/LightGrey"/>
    </visual>
    <collision>
      <origin rpy="0 0 0" xyz="0 0 0"/>
      <geometry>
        <mesh filename="package://cob_description/meshes/sensors/sick_s300_laser_collision.stl"/>
      </geometry>
    </collision>
  </link>
  <gazebo reference="base_laser_left_link">
    <sensor name="base_laser_left" type="ray">
      <always_on>true</always_on>
      <update_rate>12.0</update_rate>
      <pose>0 0 0 0 0 0</pose>
      <visualize>false</visualize>
      <ray>
        <scan>
          <horizontal>
            <samples>541</samples>
            <resolution>1.0</resolution>
            <min_angle>-2.3562</min_angle>
            <max_angle>2.3562</max_angle>
          </horizontal>
        </scan>
        <range>
          <min>0.05</min>
          <max>29.5</max>
          <resolution>0.03</resolution>
        </range>
        <noise>
          <type>gaussian</type>
          <mean>0.0</mean>
          <stddev>0.02</stddev>
        </noise>
      </ray>
      <plugin filename="libgazebo_ros_laser.so" name="gazebo_ros_base_laser_left_controller">
        <topicName>base_laser_left/scan_raw</topicName>
        <frameName>base_laser_left_link</frameName>
      </plugin>
    </sensor>
  </gazebo>
  <joint name="base_laser_right_joint" type="fixed">
    <origin rpy="0.0 0.0 -2.094" xyz="-0.122 -0.21131 0.20858"/>
    <parent link="base_link"/>
    <child link="base_laser_right_link"/>
  </joint>
  <link name="base_laser_right_link" type="laser">
    <inertial>
      <mass value="1.2"/>
      <origin rpy="0 0 0" xyz="0 0 0"/>
      <inertia ixx="0.0029999988" ixy="0.0" ixz="0.0" iyy="0.0029999988" iyz="0.0" izz="0.0015"/>
    </inertial>
    <visual>
      <origin rpy="0 0 0" xyz="0 0 0"/>
      <geometry>
        <mesh filename="package://cob_description/meshes/sensors/sick_s300_laser.dae"/>
        <!--box size="0.001 0.001 0.001" /-->
      </geometry>
      <material name="IPA/LightGrey"/>
    </visual>
    <collision>
      <origin rpy="0 0 0" xyz="0 0 0"/>
      <geometry>
        <mesh filename="package://cob_description/meshes/sensors/sick_s300_laser_collision.stl"/>
      </geometry>
    </collision>
  </link>
  <gazebo reference="base_laser_right_link">
    <sensor name="base_laser_right" type="ray">
      <always_on>true</always_on>
      <update_rate>12.0</update_rate>
      <pose>0 0 0 0 0 0</pose>
      <visualize>false</visualize>
      <ray>
        <scan>
          <horizontal>
            <samples>541</samples>
            <resolution>1.0</resolution>
            <min_angle>-2.3562</min_angle>
            <max_angle>2.3562</max_angle>
          </horizontal>
        </scan>
        <range>
          <min>0.05</min>
          <max>29.5</max>
          <resolution>0.03</resolution>
        </range>
        <noise>
          <type>gaussian</type>
          <mean>0.0</mean>
          <stddev>0.02</stddev>
        </noise>
      </ray>
      <plugin filename="libgazebo_ros_laser.so" name="gazebo_ros_base_laser_right_controller">
        <topicName>base_laser_right/scan_raw</topicName>
        <frameName>base_laser_right_link</frameName>
      </plugin>
    </sensor>
  </gazebo>
  <joint name="torso_base_joint" type="fixed">
    <origin rpy="0.0 0.0 0.0" xyz="0.0 0.0 0.26411"/>
    <parent link="base_link"/>
    <child link="torso_base_link"/>
  </joint>
  <link name="torso_base_link">
    <inertial>
      <mass value="0.01"/>
      <origin xyz="0 0 0"/>
      <inertia ixx="0.001" ixy="0.0" ixz="0.0" iyy="0.001" iyz="0.0" izz="0.001"/>
    </inertial>
    <!--
       <xacro:cylinder_inertial radius="0.300" length="0.046" mass="5.0">
        <origin xyz="0.03 0.08 0.01" rpy="0 0 0" />
      </xacro:cylinder_inertial>
-->
    <visual>
      <origin rpy="0 0 0" xyz="0 0 0"/>
      <geometry>
        <box size="0.001 0.001 0.001"/>
      </geometry>
    </visual>
    <collision>
      <origin rpy="0 0 0" xyz="0 0 0"/>
      <geometry>
        <box size="0.001 0.001 0.001"/>
      </geometry>
    </collision>
  </link>
  <joint name="torso_1_joint" type="fixed">
    <origin rpy="0 0 0" xyz="0 0 0.04642"/>
    <parent link="torso_base_link"/>
    <child link="torso_1_link"/>
  </joint>
  <link name="torso_1_link">
    <inertial>
      <mass value="0.01"/>
      <origin xyz="0 0 0"/>
      <inertia ixx="0.001" ixy="0.0" ixz="0.0" iyy="0.001" iyz="0.0" izz="0.001"/>
    </inertial>
    <!--
      <xacro:hollow_spherical_cap_inertial r="0.295" h="0.075" t="0.010" mass="6">
        <origin xyz="0 0 ${0.075/2}" rpy="0 0 0"/>
      </xacro:hollow_spherical_cap_inertial>
-->
    <visual>
      <origin rpy="0 0 0" xyz="0 0 0"/>
      <geometry>
        <box size="0.001 0.001 0.001"/>
      </geometry>
    </visual>
    <collision>
      <origin rpy="0 0 0" xyz="0 0 0"/>
      <geometry>
        <box size="0.001 0.001 0.001"/>
      </geometry>
    </collision>
  </link>
  <joint name="torso_2_joint" type="fixed">
    <origin rpy="0.5236 0 0" xyz="0 0.14734 0.07547"/>
    <parent link="torso_1_link"/>
    <child link="torso_2_link"/>
  </joint>
  <link name="torso_2_link">
    <inertial>
      <mass value="0.01"/>
      <origin xyz="0 0 0"/>
      <inertia ixx="0.001" ixy="0.0" ixz="0.0" iyy="0.001" iyz="0.0" izz="0.001"/>
    </inertial>
    <!--
      <xacro:spherical_cap_inertial r="0.295" h="0.075" mass="19.5">
        <origin xyz="0.034 0.102 0.092" rpy="0.5236 0 0"/>
      </xacro:spherical_cap_inertial>
-->
    <visual>
      <origin rpy="0 0 0" xyz="0 0 0"/>
      <geometry>
        <box size="0.001 0.001 0.001"/>
      </geometry>
    </visual>
    <collision>
      <origin rpy="0 0 0" xyz="0 0 0"/>
      <geometry>
        <box size="0.001 0.001 0.001"/>
      </geometry>
    </collision>
  </link>
  <joint name="torso_3_joint" type="fixed">
    <origin rpy="-0.5236 0 0" xyz="0 -0.09228 0.13477"/>
    <parent link="torso_2_link"/>
    <child link="torso_3_link"/>
  </joint>
  <link name="torso_3_link">
    <inertial>
      <mass value="0.01"/>
      <origin xyz="0 0 0"/>
      <inertia ixx="0.001" ixy="0.0" ixz="0.0" iyy="0.001" iyz="0.0" izz="0.001"/>
    </inertial>
    <!--
      <xacro:cylinder_inertial radius="0.250" length="0.610" mass="23.8">
        <origin xyz="-0.028 0.005 0.233" rpy="0 0 0" />
      </xacro:cylinder_inertial>
-->
    <visual>
      <origin rpy="0 0 0" xyz="0 0 0"/>
      <geometry>
        <mesh filename="package://cob_description/meshes/cob4_torso/torso_link.dae"/>
      </geometry>
    </visual>
    <collision>
      <origin rpy="0 0 0" xyz="0 0 0"/>
      <geometry>
        <mesh filename="package://cob_description/meshes/cob4_torso/torso_link_collision.stl"/>
      </geometry>
    </collision>
  </link>
  <joint name="torso_center_joint" type="fixed">
    <origin rpy="0 0 0" xyz="0.0 0.0 0.18566"/>
    <parent link="torso_3_link"/>
    <child link="torso_center_link"/>
  </joint>
  <link name="torso_center_link">
    <inertial>
      <mass value="0.01"/>
      <origin xyz="0 0 0"/>
      <inertia ixx="0.001" ixy="0.0" ixz="0.0" iyy="0.001" iyz="0.0" izz="0.001"/>
    </inertial>
    <visual>
      <origin rpy="0 0 0" xyz="0 0 0"/>
      <geometry>
        <box size="0.001 0.001 0.001"/>
      </geometry>
    </visual>
    <collision>
      <origin rpy="0 0 0" xyz="0 0 0"/>
      <geometry>
        <box size="0.001 0.001 0.001"/>
      </geometry>
    </collision>
  </link>
  <gazebo reference="torso_base_link">
    <gravity>true</gravity>
    <self_collide>false</self_collide>
  </gazebo>
  <gazebo reference="torso_1_link">
    <gravity>true</gravity>
    <self_collide>false</self_collide>
  </gazebo>
  <gazebo reference="torso_2_link">
    <gravity>true</gravity>
    <self_collide>false</self_collide>
  </gazebo>
  <gazebo reference="torso_3_link">
    <gravity>true</gravity>
    <self_collide>false</self_collide>
  </gazebo>
  <joint name="torso_cam3d_left_joint" type="fixed">
    <origin rpy="1.57079 0.0 0.468879" xyz="0.125 0.04302 0.24214"/>
    <parent link="torso_3_link"/>
    <child link="torso_cam3d_left_link"/>
  </joint>
  <link name="torso_cam3d_left_link">
    <inertial>
      <mass value="0.01"/>
      <origin xyz="0 0 0"/>
      <inertia ixx="0.001" ixy="0.0" ixz="0.0" iyy="0.001" iyz="0.0" izz="0.001"/>
    </inertial>
    <visual>
      <origin rpy="0 0 0" xyz="0 0 -0.03"/>
      <geometry>
        <box size="0.02 0.02 0.02"/>
      </geometry>
      <material name="IPA/LightGrey"/>
    </visual>
    <collision>
      <origin rpy="0 0 0" xyz="0 0 -0.03"/>
      <geometry>
        <box size="0.02 0.02 0.02"/>
      </geometry>
    </collision>
  </link>
  <gazebo reference="torso_cam3d_left_link">
    <sensor name="torso_cam3d_left_frame_sensor" type="depth">
      <always_on>true</always_on>
      <update_rate>3.0</update_rate>
      <camera>
        <horizontal_fov>1.08210413624</horizontal_fov>
        <image>
          <format>B8G8R8</format>
          <width>480</width>
          <height>640</height>
        </image>
        <clip>
          <near>0.1</near>
          <far>100</far>
        </clip>
        <noise>
          <type>gaussian</type>
          <mean>0.0</mean>
          <stddev>0.0</stddev>
        </noise>
      </camera>
      <plugin filename="libgazebo_ros_openni_kinect.so" name="torso_cam3d_left_controller">
        <updateRate>3.0</updateRate>
        <cameraName>torso_cam3d_left</cameraName>
        <frameName>torso_cam3d_left_optical_frame</frameName>
        <imageTopicName>rgb/image_raw</imageTopicName>
        <cameraInfoTopicName>rgb/camera_info</cameraInfoTopicName>
        <pointCloudTopicName>depth_registered/points</pointCloudTopicName>
        <depthImageTopicName>depth_registered/image_raw</depthImageTopicName>
        <depthImageCameraInfoTopicName>depth_registered/camera_info</depthImageCameraInfoTopicName>
        <pointCloudCutoff>0.5</pointCloudCutoff>
        <pointCloudCutoffMax>5.0</pointCloudCutoffMax>
        <baseline>0.2</baseline>
        <hackBaseline>0.0</hackBaseline>
        <distortionK1>0.0</distortionK1>
        <distortionK2>0.0</distortionK2>
        <distortionK3>0.0</distortionK3>
        <distortionT1>0.0</distortionT1>
        <distortionT2>0.0</distortionT2>
        <CxPrime>0.0</CxPrime>
        <Cx>0.0</Cx>
        <Cy>0.0</Cy>
        <focalLength>0.0</focalLength>
      </plugin>
    </sensor>
    <material>IPA/LightGrey</material>
  </gazebo>
  <joint name="torso_cam3d_right_joint" type="fixed">
    <origin rpy="1.57079 0.0 -0.368879" xyz="0.12839 -0.01802 0.24214"/>
    <parent link="torso_3_link"/>
    <child link="torso_cam3d_right_link"/>
  </joint>
  <link name="torso_cam3d_right_link">
    <inertial>
      <mass value="0.01"/>
      <origin xyz="0 0 0"/>
      <inertia ixx="0.001" ixy="0.0" ixz="0.0" iyy="0.001" iyz="0.0" izz="0.001"/>
    </inertial>
    <visual>
      <origin rpy="0 0 0" xyz="0 0 -0.03"/>
      <geometry>
        <box size="0.02 0.02 0.02"/>
      </geometry>
      <material name="IPA/LightGrey"/>
    </visual>
    <collision>
      <origin rpy="0 0 0" xyz="0 0 -0.03"/>
      <geometry>
        <box size="0.02 0.02 0.02"/>
      </geometry>
    </collision>
  </link>
  <gazebo reference="torso_cam3d_right_link">
    <sensor name="torso_cam3d_right_frame_sensor" type="depth">
      <always_on>true</always_on>
      <update_rate>3.0</update_rate>
      <camera>
        <horizontal_fov>1.08210413624</horizontal_fov>
        <image>
          <format>B8G8R8</format>
          <width>480</width>
          <height>640</height>
        </image>
        <clip>
          <near>0.1</near>
          <far>100</far>
        </clip>
        <noise>
          <type>gaussian</type>
          <mean>0.0</mean>
          <stddev>0.0</stddev>
        </noise>
      </camera>
      <plugin filename="libgazebo_ros_openni_kinect.so" name="torso_cam3d_right_controller">
        <updateRate>3.0</updateRate>
        <cameraName>torso_cam3d_right</cameraName>
        <frameName>torso_cam3d_right_optical_frame</frameName>
        <imageTopicName>rgb/image_raw</imageTopicName>
        <cameraInfoTopicName>rgb/camera_info</cameraInfoTopicName>
        <pointCloudTopicName>depth_registered/points</pointCloudTopicName>
        <depthImageTopicName>depth_registered/image_raw</depthImageTopicName>
        <depthImageCameraInfoTopicName>depth_registered/camera_info</depthImageCameraInfoTopicName>
        <pointCloudCutoff>0.5</pointCloudCutoff>
        <pointCloudCutoffMax>5.0</pointCloudCutoffMax>
        <baseline>0.2</baseline>
        <hackBaseline>0.0</hackBaseline>
        <distortionK1>0.0</distortionK1>
        <distortionK2>0.0</distortionK2>
        <distortionK3>0.0</distortionK3>
        <distortionT1>0.0</distortionT1>
        <distortionT2>0.0</distortionT2>
        <CxPrime>0.0</CxPrime>
        <Cx>0.0</Cx>
        <Cy>0.0</Cy>
        <focalLength>0.0</focalLength>
      </plugin>
    </sensor>
    <material>IPA/LightGrey</material>
  </gazebo>
  <joint name="torso_cam3d_down_joint" type="fixed">
    <origin rpy="0.0 0.61086 0.0" xyz="0.15908 0.0 0.14005"/>
    <parent link="torso_3_link"/>
    <child link="torso_cam3d_down_link"/>
  </joint>
  <link name="torso_cam3d_down_link">
    <inertial>
      <mass value="0.01"/>
      <origin xyz="0 0 0"/>
      <inertia ixx="0.001" ixy="0.0" ixz="0.0" iyy="0.001" iyz="0.0" izz="0.001"/>
    </inertial>
    <visual>
      <origin rpy="0 0 0" xyz="0 0 0"/>
      <geometry>
        <box size="0.002 0.002 0.002"/>
      </geometry>
    </visual>
    <collision>
      <origin rpy="0 0 0" xyz="0.0 0.0 0.0"/>
      <geometry>
        <box size="0.007 0.130 0.0118"/>
      </geometry>
    </collision>
  </link>
  <gazebo reference="torso_cam3d_down_link">
    <sensor name="torso_cam3d_down_depth_frame" type="depth">
      <always_on>true</always_on>
      <update_rate>30.0</update_rate>
      <camera>
        <horizontal_fov>1.29154364648</horizontal_fov>
        <image>
          <format>B8G8R8</format>
          <width>640</width>
          <height>480</height>
        </image>
        <clip>
          <near>0.15</near>
          <far>1.0</far>
        </clip>
        <noise>
          <type>gaussian</type>
          <mean>0.0</mean>
          <stddev>0.0</stddev>
        </noise>
      </camera>
      <plugin filename="libgazebo_ros_openni_kinect.so" name="torso_cam3d_down_frame_controller">
        <updateRate>30.0</updateRate>
        <cameraName>torso_cam3d_down</cameraName>
        <frameName>torso_cam3d_down_rgb_optical_frame</frameName>
        <imageTopicName>rgb/image_raw</imageTopicName>
        <cameraInfoTopicName>rgb/camera_info</cameraInfoTopicName>
        <pointCloudTopicName>depth/points</pointCloudTopicName>
        <depthImageTopicName>depth/image_raw</depthImageTopicName>
        <depthImageCameraInfoTopicName>depth/camera_info</depthImageCameraInfoTopicName>
        <pointCloudCutoff>0.5</pointCloudCutoff>
        <pointCloudCutoffMax>5.0</pointCloudCutoffMax>
        <distortionK1>0.0</distortionK1>
        <distortionK2>0.0</distortionK2>
        <distortionK3>0.0</distortionK3>
        <distortionT1>0.0</distortionT1>
        <distortionT2>0.0</distortionT2>
        <CxPrime>0.0</CxPrime>
        <Cx>0.0</Cx>
        <Cy>0.0</Cy>
        <focalLength>0.0</focalLength>
      </plugin>
    </sensor>
    <material>IPA/LightGrey</material>
  </gazebo>
  <joint name="head_base_joint" type="fixed">
    <origin rpy="0.0 0.0 0.0" xyz="0.0 0.0 0.61"/>
    <child link="head_base_link"/>
    <parent link="torso_3_link"/>
  </joint>
  <link name="head_base_link">
    <inertial>
      <mass value="0.01"/>
      <origin xyz="0 0 0"/>
      <inertia ixx="0.001" ixy="0.0" ixz="0.0" iyy="0.001" iyz="0.0" izz="0.001"/>
    </inertial>
    <visual>
      <origin rpy="0 0 0" xyz="0 0 0"/>
      <geometry>
        <box size="0.001 0.001 0.001"/>
      </geometry>
    </visual>
    <collision>
      <origin rpy="0 0 0" xyz="0 0 0"/>
      <geometry>
        <box size="0.001 0.001 0.001"/>
      </geometry>
    </collision>
  </link>
  <joint name="head_1_joint" type="revolute">
    <origin rpy="0 0 0" xyz="0 0 0.0305"/>
    <parent link="head_base_link"/>
    <child link="head_1_link"/>
    <axis xyz="0 0 1"/>
    <limit effort="100" lower="-6.2831" upper="6.2831" velocity="1.4"/>
  </joint>
  <link name="head_1_link">
    <inertial>
      <mass value="0.01"/>
      <origin xyz="0 0 0"/>
      <inertia ixx="0.001" ixy="0.0" ixz="0.0" iyy="0.001" iyz="0.0" izz="0.001"/>
    </inertial>
    <visual>
      <origin rpy="0 0 0" xyz="0 0 0"/>
      <geometry>
        <box size="0.001 0.001 0.001"/>
      </geometry>
    </visual>
    <collision>
      <origin rpy="0 0 0" xyz="0 0 0"/>
      <geometry>
        <box size="0.001 0.001 0.001"/>
      </geometry>
    </collision>
  </link>
  <joint name="head_2_joint" type="revolute">
    <origin rpy="0.349 0 0" xyz="0 -0.07725 0.00439"/>
    <parent link="head_1_link"/>
    <child link="head_2_link"/>
    <axis xyz="0 0 1"/>
    <limit effort="100" lower="-6.2831" upper="6.2831" velocity="1.4"/>
  </joint>
  <link name="head_2_link">
    <inertial>
      <mass value="0.01"/>
      <origin xyz="0 0 0"/>
      <inertia ixx="0.001" ixy="0.0" ixz="0.0" iyy="0.001" iyz="0.0" izz="0.001"/>
    </inertial>
    <visual>
      <origin rpy="0 0 0" xyz="0 0 0"/>
      <geometry>
        <box size="0.001 0.001 0.001"/>
      </geometry>
    </visual>
    <collision>
      <origin rpy="0 0 0" xyz="0 0 0"/>
      <geometry>
        <box size="0.001 0.001 0.001"/>
      </geometry>
    </collision>
  </link>
  <joint name="head_3_joint" type="revolute">
    <origin rpy="-0.349 0 0" xyz="0 0.09849 0.04476"/>
    <parent link="head_2_link"/>
    <child link="head_3_link"/>
    <axis xyz="0 0 1"/>
    <limit effort="100" lower="-6.2831" upper="6.2831" velocity="1.4"/>
  </joint>
  <link name="head_3_link">
    <inertial>
      <mass value="0.01"/>
      <origin xyz="0 0 0"/>
      <inertia ixx="0.001" ixy="0.0" ixz="0.0" iyy="0.001" iyz="0.0" izz="0.001"/>
    </inertial>
    <visual>
      <origin rpy="0 0 0" xyz="0 0 0"/>
      <geometry>
        <mesh filename="package://cob_description/meshes/cob4_head/head_link.dae"/>
      </geometry>
    </visual>
    <collision>
      <origin rpy="0 0 0" xyz="0 0 0"/>
      <geometry>
        <mesh filename="package://cob_description/meshes/cob4_head/head_link_collision.stl"/>
      </geometry>
    </collision>
  </link>
  <joint name="head_center_joint" type="fixed">
    <origin rpy="0 0 0" xyz="0.0 0.0 -0.28247"/>
    <parent link="head_3_link"/>
    <child link="head_center_link"/>
  </joint>
  <link name="head_center_link"/>
  <gazebo reference="head_base_link">
    <gravity>true</gravity>
    <self_collide>false</self_collide>
  </gazebo>
  <gazebo reference="head_1_link">
    <gravity>true</gravity>
    <self_collide>false</self_collide>
  </gazebo>
  <gazebo reference="head_2_link">
    <gravity>true</gravity>
    <self_collide>false</self_collide>
  </gazebo>
  <gazebo reference="head_3_link">
    <gravity>true</gravity>
    <self_collide>false</self_collide>
  </gazebo>
  <transmission name="head_1_trans">
    <type>transmission_interface/SimpleTransmission</type>
    <joint name="head_1_joint">
      <hardwareInterface>PositionJointInterface</hardwareInterface>
      <hardwareInterface>VelocityJointInterface</hardwareInterface>
      <!--hardwareInterface>EffortJointInterface</hardwareInterface-->
    </joint>
    <actuator name="head_1_motor">
      <mechanicalReduction>1</mechanicalReduction>
    </actuator>
  </transmission>
  <transmission name="head_2_trans">
    <type>transmission_interface/SimpleTransmission</type>
    <joint name="head_2_joint">
      <hardwareInterface>PositionJointInterface</hardwareInterface>
      <hardwareInterface>VelocityJointInterface</hardwareInterface>
      <!--hardwareInterface>EffortJointInterface</hardwareInterface-->
    </joint>
    <actuator name="head_2_motor">
      <mechanicalReduction>1</mechanicalReduction>
    </actuator>
  </transmission>
  <transmission name="head_3_trans">
    <type>transmission_interface/SimpleTransmission</type>
    <joint name="head_3_joint">
      <hardwareInterface>PositionJointInterface</hardwareInterface>
      <hardwareInterface>VelocityJointInterface</hardwareInterface>
      <!--hardwareInterface>EffortJointInterface</hardwareInterface-->
    </joint>
    <actuator name="head_3_motor">
      <mechanicalReduction>1</mechanicalReduction>
    </actuator>
  </transmission>
  <gazebo>
    <plugin filename="libhwi_switch_gazebo_ros_control.so" name="ros_control">
      <robotNamespace>head</robotNamespace>
      <filterJointsParam>joint_names</filterJointsParam>
    </plugin>
  </gazebo>
  <joint name="head_cam_joint" type="fixed">
    <origin rpy="-1.57079 -0.73 0.0" xyz="-0.181 0.0 0.325"/>
    <parent link="head_3_link"/>
    <child link="head_cam_link"/>
  </joint>
  <link name="head_cam_link">
    <inertial>
      <mass value="0.01"/>
      <origin xyz="0 0 0"/>
      <inertia ixx="0.001" ixy="0.0" ixz="0.0" iyy="0.001" iyz="0.0" izz="0.001"/>
    </inertial>
    <visual>
      <origin rpy="0 0 0" xyz="0 0 0"/>
      <geometry>
        <box size="0.002 0.002 0.002"/>
      </geometry>
    </visual>
    <collision>
      <origin rpy="0 0 0" xyz="0.0 0.0 0.0"/>
      <geometry>
        <box size="0.007 0.130 0.0118"/>
      </geometry>
    </collision>
  </link>
  <joint name="head_cam_frame_joint" type="fixed">
    <origin rpy="0 0 0" xyz="0 0 0"/>
    <parent link="head_cam_link"/>
    <child link="head_cam_frame"/>
  </joint>
  <link name="head_cam_frame"/>
  <joint name="head_cam_optical_frame_joint" type="fixed">
    <origin rpy="-1.57079632679 0 -1.57079632679" xyz="0 0 0"/>
    <parent link="head_cam_frame"/>
    <child link="head_cam_optical_frame"/>
  </joint>
  <link name="head_cam_optical_frame"/>
  <gazebo reference="head_cam_link">
    <sensor name="head_cam" type="camera">
      <update_rate>3.5</update_rate>
      <camera name="head_cam">
        <horizontal_fov>2.96705972839</horizontal_fov>
        <image>
          <format>B8G8R8</format>
          <width>2048</width>
          <height>1536</height>
        </image>
        <clip>
          <near>0.02</near>
          <far>300</far>
        </clip>
        <noise>
          <type>gaussian</type>
          <mean>0.0</mean>
          <stddev>0.007</stddev>
        </noise>
      </camera>
      <plugin filename="libgazebo_ros_camera.so" name="camera_controller">
        <alwaysOn>true</alwaysOn>
        <updateRate>3.5</updateRate>
        <cameraName>head_cam</cameraName>
        <imageTopicName>image_raw</imageTopicName>
        <cameraInfoTopicName>camera_info</cameraInfoTopicName>
        <frameName>head_cam_optical_frame</frameName>
        <hackBaseline>0.07</hackBaseline>
        <distortionK1>0.0</distortionK1>
        <distortionK2>0.0</distortionK2>
        <distortionK3>0.0</distortionK3>
        <distortionT1>0.0</distortionT1>
        <distortionT2>0.0</distortionT2>
      </plugin>
    </sensor>
    <material>IPA/LightGrey</material>
  </gazebo>
  <joint name="sensorring_base_joint" type="fixed">
    <origin rpy="0.0 0.0 0.0" xyz="0.0 0.0 0.006"/>
    <parent link="head_3_link"/>
    <child link="sensorring_base_link"/>
  </joint>
  <link name="sensorring_base_link">
    <inertial>
      <mass value="0.01"/>
      <origin xyz="0 0 0"/>
      <inertia ixx="0.001" ixy="0.0" ixz="0.0" iyy="0.001" iyz="0.0" izz="0.001"/>
    </inertial>
    <visual>
      <origin rpy="0 0 0" xyz="0 0 0"/>
      <geometry>
        <box size="0.001 0.001 0.001"/>
      </geometry>
    </visual>
    <collision>
      <origin rpy="0 0 0" xyz="0 0 0"/>
      <geometry>
        <box size="0.001 0.001 0.001"/>
      </geometry>
    </collision>
  </link>
  <joint name="sensorring_joint" type="revolute">
    <origin rpy="0 0 0" xyz="0 0 0"/>
    <parent link="sensorring_base_link"/>
    <child link="sensorring_link"/>
    <axis xyz="0 0 1"/>
    <limit effort="100" lower="-6.2831" upper="6.2831" velocity="2.62"/>
  </joint>
  <link name="sensorring_link">
    <inertial>
      <mass value="0.01"/>
      <origin xyz="0 0 0"/>
      <inertia ixx="0.001" ixy="0.0" ixz="0.0" iyy="0.001" iyz="0.0" izz="0.001"/>
    </inertial>
    <!--
      <xacro:cylinder_inertial radius="0.250" length="0.1" mass="1.0">
        <origin xyz="0 0 0" rpy="0 0 0" />
      </xacro:cylinder_inertial>
-->
    <visual>
      <origin rpy="0 0 0" xyz="0 0 0"/>
      <geometry>
        <box size="0.001 0.001 0.001"/>
      </geometry>
    </visual>
    <collision>
      <origin rpy="0 0 0" xyz="0 0 0"/>
      <geometry>
        <box size="0.001 0.001 0.001"/>
      </geometry>
    </collision>
  </link>
  <gazebo reference="sensorring_link">
    <gravity>true</gravity>
    <self_collide>false</self_collide>
    <material>IPA/DarkGrey</material>
  </gazebo>
  <transmission name="sensorring_trans">
    <type>transmission_interface/SimpleTransmission</type>
    <joint name="sensorring_joint">
      <hardwareInterface>PositionJointInterface</hardwareInterface>
      <hardwareInterface>VelocityJointInterface</hardwareInterface>
      <!--hardwareInterface>EffortJointInterface</hardwareInterface-->
    </joint>
    <actuator name="sensorring_motor">
      <mechanicalReduction>1</mechanicalReduction>
    </actuator>
  </transmission>
  <gazebo>
    <plugin filename="libhwi_switch_gazebo_ros_control.so" name="ros_control">
      <robotNamespace>sensorring</robotNamespace>
      <filterJointsParam>joint_names</filterJointsParam>
    </plugin>
  </gazebo>
  <joint name="sensorring_cam3d_joint" type="fixed">
    <origin rpy="0.0 0.0 0.0" xyz="0.096 0.0 0.0195"/>
    <parent link="sensorring_link"/>
    <child link="sensorring_cam3d_link"/>
  </joint>
  <link name="sensorring_cam3d_link">
    <inertial>
      <mass value="0.01"/>
      <origin xyz="0 0 0"/>
      <inertia ixx="0.001" ixy="0.0" ixz="0.0" iyy="0.001" iyz="0.0" izz="0.001"/>
    </inertial>
    <visual>
      <origin rpy="0 0 0" xyz="0 0 -0.03"/>
      <geometry>
        <box size="0.02 0.02 0.02"/>
      </geometry>
      <material name="IPA/LightGrey"/>
    </visual>
    <collision>
      <origin rpy="0 0 0" xyz="0 0 -0.03"/>
      <geometry>
        <box size="0.02 0.02 0.02"/>
      </geometry>
    </collision>
  </link>
  <gazebo reference="sensorring_cam3d_link">
    <sensor name="sensorring_cam3d_frame_sensor" type="depth">
      <always_on>true</always_on>
      <update_rate>3.0</update_rate>
      <camera>
        <horizontal_fov>1.08210413624</horizontal_fov>
        <image>
          <format>B8G8R8</format>
          <width>480</width>
          <height>640</height>
        </image>
        <clip>
          <near>0.1</near>
          <far>100</far>
        </clip>
        <noise>
          <type>gaussian</type>
          <mean>0.0</mean>
          <stddev>0.0</stddev>
        </noise>
      </camera>
      <plugin filename="libgazebo_ros_openni_kinect.so" name="sensorring_cam3d_controller">
        <updateRate>3.0</updateRate>
        <cameraName>sensorring_cam3d</cameraName>
        <frameName>sensorring_cam3d_optical_frame</frameName>
        <imageTopicName>rgb/image_raw</imageTopicName>
        <cameraInfoTopicName>rgb/camera_info</cameraInfoTopicName>
        <pointCloudTopicName>depth_registered/points</pointCloudTopicName>
        <depthImageTopicName>depth_registered/image_raw</depthImageTopicName>
        <depthImageCameraInfoTopicName>depth_registered/camera_info</depthImageCameraInfoTopicName>
        <pointCloudCutoff>0.5</pointCloudCutoff>
        <pointCloudCutoffMax>5.0</pointCloudCutoffMax>
        <baseline>0.2</baseline>
        <hackBaseline>0.0</hackBaseline>
        <distortionK1>0.0</distortionK1>
        <distortionK2>0.0</distortionK2>
        <distortionK3>0.0</distortionK3>
        <distortionT1>0.0</distortionT1>
        <distortionT2>0.0</distortionT2>
        <CxPrime>0.0</CxPrime>
        <Cx>0.0</Cx>
        <Cy>0.0</Cy>
        <focalLength>0.0</focalLength>
      </plugin>
    </sensor>
    <material>IPA/LightGrey</material>
  </gazebo>
  <!-- joint between base_link and cob4_arm_connector_link -->
  <joint name="arm_right_base_joint" type="fixed">
    <origin rpy="1.57097 0.0 0.0" xyz="0.0 -0.014 0.55"/>
    <parent link="torso_3_link"/>
    <child link="arm_right_base_link"/>
  </joint>
  <!-- static part of PRL100 -->
  <link name="arm_right_base_link">
    <inertial>
      <mass value="0.01"/>
      <origin xyz="0 0 0"/>
      <inertia ixx="0.001" ixy="0.0" ixz="0.0" iyy="0.001" iyz="0.0" izz="0.001"/>
    </inertial>
    <!--
      <xacro:cylinder_inertial radius="0.056" length="0.12" mass="2.0">
        <origin xyz="0 0 ${0.12/2}" rpy="0 0 0" />
      </xacro:cylinder_inertial>
  -->
    <visual>
      <origin rpy="0 0 0" xyz="0 0 0"/>
      <geometry>
        <mesh filename="package://cob_description/meshes/cob4_arm/arm_base_link.stl"/>
      </geometry>
    </visual>
    <collision>
      <origin rpy="0 0 0" xyz="0 0 0"/>
      <geometry>
        <mesh filename="package://cob_description/meshes/cob4_arm/arm_base_link.stl"/>
      </geometry>
    </collision>
  </link>
  <!-- joint between arm_base_link and arm_1_link -->
  <joint name="arm_right_1_joint" type="revolute">
    <origin rpy="0 0 0" xyz="0 0 0.139"/>
    <parent link="arm_right_base_link"/>
    <child link="arm_right_1_link"/>
    <axis xyz="0 0 1"/>
    <dynamics damping="0" friction="0"/>
    <limit effort="81.5" lower="-4.69" upper="4.69" velocity="0.66"/>
    <!--Theoretical limit +/-270 , Real Limit +/- 270-->
    <!--safety_controller k_position="20" k_velocity="50" soft_lower_limit="${-M_PI + 0.01}" soft_upper_limit="${M_PI - 0.01}" /-->
  </joint>
  <!-- prl100 rotor + shoulder flansh -->
  <link name="arm_right_1_link">
    <inertial>
      <mass value="0.01"/>
      <origin xyz="0 0 0"/>
      <inertia ixx="0.001" ixy="0.0" ixz="0.0" iyy="0.001" iyz="0.0" izz="0.001"/>
    </inertial>
    <!--
      <inertial>
        <origin xyz="0.0 0.0662 0.0473" rpy="0 0 0"/>
        <mass value="0.8"/>
        <inertia ixx="0.002034" ixy="0.0" ixz="0.0" iyy="0.001437" iyz="0.000784" izz="0.00161" />
      </inertial>
-->
    <visual>
      <origin rpy="0 0 0" xyz="0 0 0"/>
      <geometry>
        <mesh filename="package://cob_description/meshes/cob4_arm/arm_1_link.dae"/>
      </geometry>
    </visual>
    <collision>
      <origin rpy="0 0 0" xyz="0 0 0"/>
      <geometry>
        <mesh filename="package://cob_description/meshes/cob4_arm/arm_1_collision.stl"/>
      </geometry>
    </collision>
  </link>
  <!-- joint between arm_1_link and arm_2_link -->
  <joint name="arm_right_2_joint" type="revolute">
    <origin rpy="1.57079632679 0 0" xyz="0 0 0.0915"/>
    <parent link="arm_right_1_link"/>
    <child link="arm_right_2_link"/>
    <axis xyz="0 0 1"/>
    <dynamics damping="0" friction="0"/>
    <limit effort="48" lower="-1.89" upper="1.89" velocity="1.57"/>
    <!--Theoretical limit +/-170 , Real Limit +/- 110 (self collision)-->
    <!--safety_controller k_position="20" k_velocity="50" soft_lower_limit="${-2.0943 + 0.01}" soft_upper_limit="${2.0943 - 0.01}" /-->
  </joint>
  <link name="arm_right_2_link">
    <inertial>
      <mass value="0.01"/>
      <origin xyz="0 0 0"/>
      <inertia ixx="0.001" ixy="0.0" ixz="0.0" iyy="0.001" iyz="0.0" izz="0.001"/>
    </inertial>
    <!--
      <inertial>
        <origin xyz="0 0.018 -0.018" rpy="0 0 0"/>
        <mass value="3.9"/>
        <inertia ixx="0.009780" ixy="0.0" ixz="0.0" iyy="0.013300" iyz="0.0" izz="0.009780" />
      </inertial>
-->
    <visual>
      <origin rpy="0 0 0" xyz="0 0 0"/>
      <geometry>
        <mesh filename="package://cob_description/meshes/cob4_arm/arm_2_link.dae"/>
      </geometry>
    </visual>
    <collision>
      <origin rpy="0 0 0" xyz="0 0 0"/>
      <geometry>
        <mesh filename="package://cob_description/meshes/cob4_arm/arm_2_collision.stl"/>
      </geometry>
    </collision>
  </link>
  <!-- joint between arm_2_link and arm_3_link -->
  <joint name="arm_right_3_joint" type="revolute">
    <origin rpy="-1.57079632679 0 0" xyz="0 0 0"/>
    <parent link="arm_right_2_link"/>
    <child link="arm_right_3_link"/>
    <axis xyz="0 0 1"/>
    <dynamics damping="0" friction="0"/>
    <limit effort="48" lower="-2.94" upper="2.94" velocity="1.57"/>
    <!--Theoretical limit +/-170 , Real Limit +/- 170-->
    <!--safety_controller k_position="20" k_velocity="25" soft_lower_limit="${-M_PI + 0.01}" soft_upper_limit="${M_PI - 0.01}" /-->
  </joint>
  <link name="arm_right_3_link">
    <inertial>
      <mass value="0.01"/>
      <origin xyz="0 0 0"/>
      <inertia ixx="0.001" ixy="0.0" ixz="0.0" iyy="0.001" iyz="0.0" izz="0.001"/>
    </inertial>
    <!--
      <inertial>
        <origin xyz="0.0 0.06247 0.23425" rpy="0 0 0"/>
        <mass value="1.94533"/>
        <inertia ixx="0.0344" ixy="0.0" ixz="0.0077" iyy="0.0362" iyz="0.0" izz="0.0052" />
      </inertial>
-->
    <visual>
      <origin rpy="0 0 0" xyz="0 0 0"/>
      <geometry>
        <mesh filename="package://cob_description/meshes/cob4_arm/arm_3_link.dae"/>
      </geometry>
    </visual>
    <collision>
      <origin rpy="0 0 0" xyz="0 0 0"/>
      <geometry>
        <mesh filename="package://cob_description/meshes/cob4_arm/arm_3_collision.stl"/>
      </geometry>
    </collision>
  </link>
  <!-- joint between arm_3_link and arm_4_link -->
  <joint name="arm_right_4_joint" type="revolute">
    <origin rpy="1.57079632679 0 0" xyz="0 0 0.45360"/>
    <parent link="arm_right_3_link"/>
    <child link="arm_right_4_link"/>
    <axis xyz="0 0 1"/>
    <dynamics damping="0" friction="0"/>
    <limit effort="48" lower="-2.59" upper="2.59" velocity="1.57"/>
    <!--Theoretical limit +/-170 , Real Limit +/- 150 (self collision)-->
    <!--safety_controller k_position="20" k_velocity="25" soft_lower_limit="${-2.0943951 + 0.01}" soft_upper_limit="${2.0943951 - 0.01}" /-->
  </joint>
  <link name="arm_right_4_link">
    <inertial>
      <mass value="0.01"/>
      <origin xyz="0 0 0"/>
      <inertia ixx="0.001" ixy="0.0" ixz="0.0" iyy="0.001" iyz="0.0" izz="0.001"/>
    </inertial>
    <!--
      <inertial>
        <origin xyz="0 0.018 -0.018" rpy="0 0 0"/>
        <mass value="3.9"/>
        <inertia ixx="0.009780" ixy="0.0" ixz="0.0" iyy="0.013300" iyz="0.0" izz="0.009780" />
      </inertial>
-->
    <visual>
      <origin rpy="0 0 0" xyz="0 0 0"/>
      <geometry>
        <mesh filename="package://cob_description/meshes/cob4_arm/arm_4_link.dae"/>
      </geometry>
    </visual>
    <collision>
      <origin rpy="0 0 0" xyz="0 0 0"/>
      <geometry>
        <mesh filename="package://cob_description/meshes/cob4_arm/arm_4_collision.stl"/>
      </geometry>
    </collision>
  </link>
  <!-- joint between arm_4_link and arm_5_link -->
  <joint name="arm_right_5_joint" type="revolute">
    <origin rpy="-1.57079632679 0 0" xyz="0 0 0"/>
    <parent link="arm_right_4_link"/>
    <child link="arm_right_5_link"/>
    <axis xyz="0 0 1"/>
    <dynamics damping="0" friction="0"/>
    <limit effort="48" lower="-2.94" upper="2.94" velocity="1.57"/>
    <!--Theoretical limit +/-170 , Real Limit +/- 170-->
    <!--safety_controller k_position="20" k_velocity="25" soft_lower_limit="${-M_PI + 0.01}" soft_upper_limit="${M_PI - 0.01}" /-->
  </joint>
  <link name="arm_right_5_link">
    <inertial>
      <mass value="0.01"/>
      <origin xyz="0 0 0"/>
      <inertia ixx="0.001" ixy="0.0" ixz="0.0" iyy="0.001" iyz="0.0" izz="0.001"/>
    </inertial>
    <!--
      <inertial>
        <origin xyz="0.0 0.04175 0.17026" rpy="0 0 0"/>
        <mass value="1.3297"/>
        <inertia ixx="0.01" ixy="0.0" ixz="-0.0031" iyy="0.0111" iyz="0.0" izz="0.0031" />
      </inertial>
-->
    <visual>
      <origin rpy="0 0 0" xyz="0 0 0"/>
      <geometry>
        <mesh filename="package://cob_description/meshes/cob4_arm/arm_5_link.dae"/>
      </geometry>
    </visual>
    <collision>
      <origin rpy="0 0 0" xyz="0 0 0"/>
      <geometry>
        <mesh filename="package://cob_description/meshes/cob4_arm/arm_5_collision.stl"/>
      </geometry>
    </collision>
  </link>
  <!-- joint between arm_5_link and arm_6_link -->
  <joint name="arm_right_6_joint" type="revolute">
    <origin rpy="1.57079632679 0 0" xyz="0 0 0.2986"/>
    <parent link="arm_right_5_link"/>
    <child link="arm_right_6_link"/>
    <axis xyz="0 0 1"/>
    <dynamics damping="0" friction="0"/>
    <limit effort="15" lower="-2.94" upper="2.94" velocity="2.09"/>
    <!--Theoretical limit +/-170 , Real Limit -140/+170 (self collision)-->
    <!--safety_controller k_position="20" k_velocity="25" soft_lower_limit="${-2.0943951 + 0.01}" soft_upper_limit="${2.0943951 - 0.01}" /-->
  </joint>
  <link name="arm_right_6_link">
    <inertial>
      <mass value="0.01"/>
      <origin xyz="0 0 0"/>
      <inertia ixx="0.001" ixy="0.0" ixz="0.0" iyy="0.001" iyz="0.0" izz="0.001"/>
    </inertial>
    <!--
      <inertial>
        <origin xyz="0 0.012 -0.012" rpy="0 0 0"/>
        <mass value="1.9"/>
        <inertia ixx="0.002750" ixy="0.0" ixz="0.0" iyy="0.004002" iyz="0.0" izz="0.002830" />
      </inertial>
-->
    <visual>
      <origin rpy="0 0 0" xyz="0 0 0"/>
      <geometry>
        <mesh filename="package://cob_description/meshes/cob4_arm/arm_6_link.dae"/>
      </geometry>
    </visual>
    <collision>
      <origin rpy="0 0 0" xyz="0 0 0"/>
      <geometry>
        <mesh filename="package://cob_description/meshes/cob4_arm/arm_6_collision.stl"/>
      </geometry>
    </collision>
  </link>
  <!-- joint between arm_6_link and arm_7_link -->
  <joint name="arm_right_7_joint" type="revolute">
    <origin rpy="-1.57079632679 0 0" xyz="0 0 0"/>
    <parent link="arm_right_6_link"/>
    <child link="arm_right_7_link"/>
    <axis xyz="0 0 1"/>
    <dynamics damping="0" friction="0"/>
    <limit effort="15" lower="-3.73" upper="2.16" velocity="2.09"/>
    <!--Theoretical limit +127/-215 , Real Limit +127/-215-->
    <!--safety_controller k_position="20" k_velocity="25" soft_lower_limit="${-2.0943951 + 0.01}" soft_upper_limit="${2.0943951 - 0.01}" /-->
  </joint>
  <link name="arm_right_7_link">
    <inertial>
      <mass value="0.01"/>
      <origin xyz="0 0 0"/>
      <inertia ixx="0.001" ixy="0.0" ixz="0.0" iyy="0.001" iyz="0.0" izz="0.001"/>
    </inertial>
    <!--
      <xacro:cylinder_inertial radius="0.03" length="0.035" mass="0.05">
        <origin xyz="0 0 0.06" rpy="0 0 0"/>
      </xacro:cylinder_inertial>
-->
    <visual>
      <origin rpy="0 0 0" xyz="0 0 0.06"/>
      <geometry>
        <cylinder length="0.035" radius="0.03"/>
      </geometry>
      <material name="IPA/LightGrey"/>
    </visual>
    <collision>
      <origin rpy="0 0 0" xyz="0 0 0.06"/>
      <geometry>
        <cylinder length="0.035" radius="0.03"/>
      </geometry>
    </collision>
  </link>
  <gazebo reference="arm_right_base_link">
    <gravity>true</gravity>
    <self_collide>false</self_collide>
  </gazebo>
  <gazebo reference="arm_right_1_link">
    <gravity>true</gravity>
    <self_collide>false</self_collide>
  </gazebo>
  <gazebo reference="arm_right_2_link">
    <gravity>true</gravity>
    <self_collide>false</self_collide>
  </gazebo>
  <gazebo reference="arm_right_3_link">
    <gravity>true</gravity>
    <self_collide>false</self_collide>
  </gazebo>
  <gazebo reference="arm_right_4_link">
    <gravity>true</gravity>
    <self_collide>false</self_collide>
  </gazebo>
  <gazebo reference="arm_right_5_link">
    <gravity>true</gravity>
    <self_collide>false</self_collide>
  </gazebo>
  <gazebo reference="arm_right_6_link">
    <gravity>true</gravity>
    <self_collide>false</self_collide>
  </gazebo>
  <gazebo reference="arm_right_7_link">
    <gravity>true</gravity>
    <self_collide>false</self_collide>
    <material value="IPA/LightGrey"/>
  </gazebo>
  <transmission name="arm_right_1_trans">
    <type>transmission_interface/SimpleTransmission</type>
    <joint name="arm_right_1_joint">
      <hardwareInterface>PositionJointInterface</hardwareInterface>
      <hardwareInterface>VelocityJointInterface</hardwareInterface>
      <!--hardwareInterface>EffortJointInterface</hardwareInterface-->
    </joint>
    <actuator name="arm_right_1_motor">
      <mechanicalReduction>1</mechanicalReduction>
    </actuator>
  </transmission>
  <transmission name="arm_right_2_trans">
    <type>transmission_interface/SimpleTransmission</type>
    <joint name="arm_right_2_joint">
      <hardwareInterface>PositionJointInterface</hardwareInterface>
      <hardwareInterface>VelocityJointInterface</hardwareInterface>
      <!--hardwareInterface>EffortJointInterface</hardwareInterface-->
    </joint>
    <actuator name="arm_right_2_motor">
      <mechanicalReduction>1</mechanicalReduction>
    </actuator>
  </transmission>
  <transmission name="arm_right_3_trans">
    <type>transmission_interface/SimpleTransmission</type>
    <joint name="arm_right_3_joint">
      <hardwareInterface>PositionJointInterface</hardwareInterface>
      <hardwareInterface>VelocityJointInterface</hardwareInterface>
      <!--hardwareInterface>EffortJointInterface</hardwareInterface-->
    </joint>
    <actuator name="arm_right_3_motor">
      <mechanicalReduction>1</mechanicalReduction>
    </actuator>
  </transmission>
  <transmission name="arm_right_4_trans">
    <type>transmission_interface/SimpleTransmission</type>
    <joint name="arm_right_4_joint">
      <hardwareInterface>PositionJointInterface</hardwareInterface>
      <hardwareInterface>VelocityJointInterface</hardwareInterface>
      <!--hardwareInterface>EffortJointInterface</hardwareInterface-->
    </joint>
    <actuator name="arm_right_4_motor">
      <mechanicalReduction>1</mechanicalReduction>
    </actuator>
  </transmission>
  <transmission name="arm_right_5_trans">
    <type>transmission_interface/SimpleTransmission</type>
    <joint name="arm_right_5_joint">
      <hardwareInterface>PositionJointInterface</hardwareInterface>
      <hardwareInterface>VelocityJointInterface</hardwareInterface>
      <!--hardwareInterface>EffortJointInterface</hardwareInterface-->
    </joint>
    <actuator name="arm_right_5_motor">
      <mechanicalReduction>1</mechanicalReduction>
    </actuator>
  </transmission>
  <transmission name="arm_right_6_trans">
    <type>transmission_interface/SimpleTransmission</type>
    <joint name="arm_right_6_joint">
      <hardwareInterface>PositionJointInterface</hardwareInterface>
      <hardwareInterface>VelocityJointInterface</hardwareInterface>
      <!--hardwareInterface>EffortJointInterface</hardwareInterface-->
    </joint>
    <actuator name="arm_right_6_motor">
      <mechanicalReduction>1</mechanicalReduction>
    </actuator>
  </transmission>
  <transmission name="arm_right_7_trans">
    <type>transmission_interface/SimpleTransmission</type>
    <joint name="arm_right_7_joint">
      <hardwareInterface>PositionJointInterface</hardwareInterface>
      <hardwareInterface>VelocityJointInterface</hardwareInterface>
      <!--hardwareInterface>EffortJointInterface</hardwareInterface-->
    </joint>
    <actuator name="arm_right_7_motor">
      <mechanicalReduction>1</mechanicalReduction>
    </actuator>
  </transmission>
  <!-- ros_control plugin -->
  <gazebo>
    <plugin filename="libhwi_switch_gazebo_ros_control.so" name="ros_control">
      <robotNamespace>arm_right</robotNamespace>
      <filterJointsParam>joint_names</filterJointsParam>
    </plugin>
  </gazebo>
  <!-- joint between base_link and cob4_arm_connector_link -->
  <joint name="arm_left_base_joint" type="fixed">
    <origin rpy="1.57097 0.0 3.14159" xyz="0.0 0.014 0.55"/>
    <parent link="torso_3_link"/>
    <child link="arm_left_base_link"/>
  </joint>
  <!-- static part of PRL100 -->
  <link name="arm_left_base_link">
    <inertial>
      <mass value="0.01"/>
      <origin xyz="0 0 0"/>
      <inertia ixx="0.001" ixy="0.0" ixz="0.0" iyy="0.001" iyz="0.0" izz="0.001"/>
    </inertial>
    <!--
      <xacro:cylinder_inertial radius="0.056" length="0.12" mass="2.0">
        <origin xyz="0 0 ${0.12/2}" rpy="0 0 0" />
      </xacro:cylinder_inertial>
  -->
    <visual>
      <origin rpy="0 0 0" xyz="0 0 0"/>
      <geometry>
        <mesh filename="package://cob_description/meshes/cob4_arm/arm_base_link.stl"/>
      </geometry>
    </visual>
    <collision>
      <origin rpy="0 0 0" xyz="0 0 0"/>
      <geometry>
        <mesh filename="package://cob_description/meshes/cob4_arm/arm_base_link.stl"/>
      </geometry>
    </collision>
  </link>
  <!-- joint between arm_base_link and arm_1_link -->
  <joint name="arm_left_1_joint" type="revolute">
    <origin rpy="0 0 0" xyz="0 0 0.139"/>
    <parent link="arm_left_base_link"/>
    <child link="arm_left_1_link"/>
    <axis xyz="0 0 1"/>
    <dynamics damping="0" friction="0"/>
    <limit effort="81.5" lower="-4.69" upper="4.69" velocity="0.66"/>
    <!--Theoretical limit +/-270 , Real Limit +/- 270-->
    <!--safety_controller k_position="20" k_velocity="50" soft_lower_limit="${-M_PI + 0.01}" soft_upper_limit="${M_PI - 0.01}" /-->
  </joint>
  <!-- prl100 rotor + shoulder flansh -->
  <link name="arm_left_1_link">
    <inertial>
      <mass value="0.01"/>
      <origin xyz="0 0 0"/>
      <inertia ixx="0.001" ixy="0.0" ixz="0.0" iyy="0.001" iyz="0.0" izz="0.001"/>
    </inertial>
    <!--
      <inertial>
        <origin xyz="0.0 0.0662 0.0473" rpy="0 0 0"/>
        <mass value="0.8"/>
        <inertia ixx="0.002034" ixy="0.0" ixz="0.0" iyy="0.001437" iyz="0.000784" izz="0.00161" />
      </inertial>
-->
    <visual>
      <origin rpy="0 0 0" xyz="0 0 0"/>
      <geometry>
        <mesh filename="package://cob_description/meshes/cob4_arm/arm_1_link.dae"/>
      </geometry>
    </visual>
    <collision>
      <origin rpy="0 0 0" xyz="0 0 0"/>
      <geometry>
        <mesh filename="package://cob_description/meshes/cob4_arm/arm_1_collision.stl"/>
      </geometry>
    </collision>
  </link>
  <!-- joint between arm_1_link and arm_2_link -->
  <joint name="arm_left_2_joint" type="revolute">
    <origin rpy="1.57079632679 0 0" xyz="0 0 0.0915"/>
    <parent link="arm_left_1_link"/>
    <child link="arm_left_2_link"/>
    <axis xyz="0 0 1"/>
    <dynamics damping="0" friction="0"/>
    <limit effort="48" lower="-1.89" upper="1.89" velocity="1.57"/>
    <!--Theoretical limit +/-170 , Real Limit +/- 110 (self collision)-->
    <!--safety_controller k_position="20" k_velocity="50" soft_lower_limit="${-2.0943 + 0.01}" soft_upper_limit="${2.0943 - 0.01}" /-->
  </joint>
  <link name="arm_left_2_link">
    <inertial>
      <mass value="0.01"/>
      <origin xyz="0 0 0"/>
      <inertia ixx="0.001" ixy="0.0" ixz="0.0" iyy="0.001" iyz="0.0" izz="0.001"/>
    </inertial>
    <!--
      <inertial>
        <origin xyz="0 0.018 -0.018" rpy="0 0 0"/>
        <mass value="3.9"/>
        <inertia ixx="0.009780" ixy="0.0" ixz="0.0" iyy="0.013300" iyz="0.0" izz="0.009780" />
      </inertial>
-->
    <visual>
      <origin rpy="0 0 0" xyz="0 0 0"/>
      <geometry>
        <mesh filename="package://cob_description/meshes/cob4_arm/arm_2_link.dae"/>
      </geometry>
    </visual>
    <collision>
      <origin rpy="0 0 0" xyz="0 0 0"/>
      <geometry>
        <mesh filename="package://cob_description/meshes/cob4_arm/arm_2_collision.stl"/>
      </geometry>
    </collision>
  </link>
  <!-- joint between arm_2_link and arm_3_link -->
  <joint name="arm_left_3_joint" type="revolute">
    <origin rpy="-1.57079632679 0 0" xyz="0 0 0"/>
    <parent link="arm_left_2_link"/>
    <child link="arm_left_3_link"/>
    <axis xyz="0 0 1"/>
    <dynamics damping="0" friction="0"/>
    <limit effort="48" lower="-2.94" upper="2.94" velocity="1.57"/>
    <!--Theoretical limit +/-170 , Real Limit +/- 170-->
    <!--safety_controller k_position="20" k_velocity="25" soft_lower_limit="${-M_PI + 0.01}" soft_upper_limit="${M_PI - 0.01}" /-->
  </joint>
  <link name="arm_left_3_link">
    <inertial>
      <mass value="0.01"/>
      <origin xyz="0 0 0"/>
      <inertia ixx="0.001" ixy="0.0" ixz="0.0" iyy="0.001" iyz="0.0" izz="0.001"/>
    </inertial>
    <!--
      <inertial>
        <origin xyz="0.0 0.06247 0.23425" rpy="0 0 0"/>
        <mass value="1.94533"/>
        <inertia ixx="0.0344" ixy="0.0" ixz="0.0077" iyy="0.0362" iyz="0.0" izz="0.0052" />
      </inertial>
-->
    <visual>
      <origin rpy="0 0 0" xyz="0 0 0"/>
      <geometry>
        <mesh filename="package://cob_description/meshes/cob4_arm/arm_3_link.dae"/>
      </geometry>
    </visual>
    <collision>
      <origin rpy="0 0 0" xyz="0 0 0"/>
      <geometry>
        <mesh filename="package://cob_description/meshes/cob4_arm/arm_3_collision.stl"/>
      </geometry>
    </collision>
  </link>
  <!-- joint between arm_3_link and arm_4_link -->
  <joint name="arm_left_4_joint" type="revolute">
    <origin rpy="1.57079632679 0 0" xyz="0 0 0.45360"/>
    <parent link="arm_left_3_link"/>
    <child link="arm_left_4_link"/>
    <axis xyz="0 0 1"/>
    <dynamics damping="0" friction="0"/>
    <limit effort="48" lower="-2.59" upper="2.59" velocity="1.57"/>
    <!--Theoretical limit +/-170 , Real Limit +/- 150 (self collision)-->
    <!--safety_controller k_position="20" k_velocity="25" soft_lower_limit="${-2.0943951 + 0.01}" soft_upper_limit="${2.0943951 - 0.01}" /-->
  </joint>
  <link name="arm_left_4_link">
    <inertial>
      <mass value="0.01"/>
      <origin xyz="0 0 0"/>
      <inertia ixx="0.001" ixy="0.0" ixz="0.0" iyy="0.001" iyz="0.0" izz="0.001"/>
    </inertial>
    <!--
      <inertial>
        <origin xyz="0 0.018 -0.018" rpy="0 0 0"/>
        <mass value="3.9"/>
        <inertia ixx="0.009780" ixy="0.0" ixz="0.0" iyy="0.013300" iyz="0.0" izz="0.009780" />
      </inertial>
-->
    <visual>
      <origin rpy="0 0 0" xyz="0 0 0"/>
      <geometry>
        <mesh filename="package://cob_description/meshes/cob4_arm/arm_4_link.dae"/>
      </geometry>
    </visual>
    <collision>
      <origin rpy="0 0 0" xyz="0 0 0"/>
      <geometry>
        <mesh filename="package://cob_description/meshes/cob4_arm/arm_4_collision.stl"/>
      </geometry>
    </collision>
  </link>
  <!-- joint between arm_4_link and arm_5_link -->
  <joint name="arm_left_5_joint" type="revolute">
    <origin rpy="-1.57079632679 0 0" xyz="0 0 0"/>
    <parent link="arm_left_4_link"/>
    <child link="arm_left_5_link"/>
    <axis xyz="0 0 1"/>
    <dynamics damping="0" friction="0"/>
    <limit effort="48" lower="-2.94" upper="2.94" velocity="1.57"/>
    <!--Theoretical limit +/-170 , Real Limit +/- 170-->
    <!--safety_controller k_position="20" k_velocity="25" soft_lower_limit="${-M_PI + 0.01}" soft_upper_limit="${M_PI - 0.01}" /-->
  </joint>
  <link name="arm_left_5_link">
    <inertial>
      <mass value="0.01"/>
      <origin xyz="0 0 0"/>
      <inertia ixx="0.001" ixy="0.0" ixz="0.0" iyy="0.001" iyz="0.0" izz="0.001"/>
    </inertial>
    <!--
      <inertial>
        <origin xyz="0.0 0.04175 0.17026" rpy="0 0 0"/>
        <mass value="1.3297"/>
        <inertia ixx="0.01" ixy="0.0" ixz="-0.0031" iyy="0.0111" iyz="0.0" izz="0.0031" />
      </inertial>
-->
    <visual>
      <origin rpy="0 0 0" xyz="0 0 0"/>
      <geometry>
        <mesh filename="package://cob_description/meshes/cob4_arm/arm_5_link.dae"/>
      </geometry>
    </visual>
    <collision>
      <origin rpy="0 0 0" xyz="0 0 0"/>
      <geometry>
        <mesh filename="package://cob_description/meshes/cob4_arm/arm_5_collision.stl"/>
      </geometry>
    </collision>
  </link>
  <!-- joint between arm_5_link and arm_6_link -->
  <joint name="arm_left_6_joint" type="revolute">
    <origin rpy="1.57079632679 0 0" xyz="0 0 0.2986"/>
    <parent link="arm_left_5_link"/>
    <child link="arm_left_6_link"/>
    <axis xyz="0 0 1"/>
    <dynamics damping="0" friction="0"/>
    <limit effort="15" lower="-2.94" upper="2.94" velocity="2.09"/>
    <!--Theoretical limit +/-170 , Real Limit -140/+170 (self collision)-->
    <!--safety_controller k_position="20" k_velocity="25" soft_lower_limit="${-2.0943951 + 0.01}" soft_upper_limit="${2.0943951 - 0.01}" /-->
  </joint>
  <link name="arm_left_6_link">
    <inertial>
      <mass value="0.01"/>
      <origin xyz="0 0 0"/>
      <inertia ixx="0.001" ixy="0.0" ixz="0.0" iyy="0.001" iyz="0.0" izz="0.001"/>
    </inertial>
    <!--
      <inertial>
        <origin xyz="0 0.012 -0.012" rpy="0 0 0"/>
        <mass value="1.9"/>
        <inertia ixx="0.002750" ixy="0.0" ixz="0.0" iyy="0.004002" iyz="0.0" izz="0.002830" />
      </inertial>
-->
    <visual>
      <origin rpy="0 0 0" xyz="0 0 0"/>
      <geometry>
        <mesh filename="package://cob_description/meshes/cob4_arm/arm_6_link.dae"/>
      </geometry>
    </visual>
    <collision>
      <origin rpy="0 0 0" xyz="0 0 0"/>
      <geometry>
        <mesh filename="package://cob_description/meshes/cob4_arm/arm_6_collision.stl"/>
      </geometry>
    </collision>
  </link>
  <!-- joint between arm_6_link and arm_7_link -->
  <joint name="arm_left_7_joint" type="revolute">
    <origin rpy="-1.57079632679 0 0" xyz="0 0 0"/>
    <parent link="arm_left_6_link"/>
    <child link="arm_left_7_link"/>
    <axis xyz="0 0 1"/>
    <dynamics damping="0" friction="0"/>
    <limit effort="15" lower="-3.73" upper="2.16" velocity="2.09"/>
    <!--Theoretical limit +127/-215 , Real Limit +127/-215-->
    <!--safety_controller k_position="20" k_velocity="25" soft_lower_limit="${-2.0943951 + 0.01}" soft_upper_limit="${2.0943951 - 0.01}" /-->
  </joint>
  <link name="arm_left_7_link">
    <inertial>
      <mass value="0.01"/>
      <origin xyz="0 0 0"/>
      <inertia ixx="0.001" ixy="0.0" ixz="0.0" iyy="0.001" iyz="0.0" izz="0.001"/>
    </inertial>
    <!--
      <xacro:cylinder_inertial radius="0.03" length="0.035" mass="0.05">
        <origin xyz="0 0 0.06" rpy="0 0 0"/>
      </xacro:cylinder_inertial>
-->
    <visual>
      <origin rpy="0 0 0" xyz="0 0 0.06"/>
      <geometry>
        <cylinder length="0.035" radius="0.03"/>
      </geometry>
      <material name="IPA/LightGrey"/>
    </visual>
    <collision>
      <origin rpy="0 0 0" xyz="0 0 0.06"/>
      <geometry>
        <cylinder length="0.035" radius="0.03"/>
      </geometry>
    </collision>
  </link>
  <gazebo reference="arm_left_base_link">
    <gravity>true</gravity>
    <self_collide>false</self_collide>
  </gazebo>
  <gazebo reference="arm_left_1_link">
    <gravity>true</gravity>
    <self_collide>false</self_collide>
  </gazebo>
  <gazebo reference="arm_left_2_link">
    <gravity>true</gravity>
    <self_collide>false</self_collide>
  </gazebo>
  <gazebo reference="arm_left_3_link">
    <gravity>true</gravity>
    <self_collide>false</self_collide>
  </gazebo>
  <gazebo reference="arm_left_4_link">
    <gravity>true</gravity>
    <self_collide>false</self_collide>
  </gazebo>
  <gazebo reference="arm_left_5_link">
    <gravity>true</gravity>
    <self_collide>false</self_collide>
  </gazebo>
  <gazebo reference="arm_left_6_link">
    <gravity>true</gravity>
    <self_collide>false</self_collide>
  </gazebo>
  <gazebo reference="arm_left_7_link">
    <gravity>true</gravity>
    <self_collide>false</self_collide>
    <material value="IPA/LightGrey"/>
  </gazebo>
  <transmission name="arm_left_1_trans">
    <type>transmission_interface/SimpleTransmission</type>
    <joint name="arm_left_1_joint">
      <hardwareInterface>PositionJointInterface</hardwareInterface>
      <hardwareInterface>VelocityJointInterface</hardwareInterface>
      <!--hardwareInterface>EffortJointInterface</hardwareInterface-->
    </joint>
    <actuator name="arm_left_1_motor">
      <mechanicalReduction>1</mechanicalReduction>
    </actuator>
  </transmission>
  <transmission name="arm_left_2_trans">
    <type>transmission_interface/SimpleTransmission</type>
    <joint name="arm_left_2_joint">
      <hardwareInterface>PositionJointInterface</hardwareInterface>
      <hardwareInterface>VelocityJointInterface</hardwareInterface>
      <!--hardwareInterface>EffortJointInterface</hardwareInterface-->
    </joint>
    <actuator name="arm_left_2_motor">
      <mechanicalReduction>1</mechanicalReduction>
    </actuator>
  </transmission>
  <transmission name="arm_left_3_trans">
    <type>transmission_interface/SimpleTransmission</type>
    <joint name="arm_left_3_joint">
      <hardwareInterface>PositionJointInterface</hardwareInterface>
      <hardwareInterface>VelocityJointInterface</hardwareInterface>
      <!--hardwareInterface>EffortJointInterface</hardwareInterface-->
    </joint>
    <actuator name="arm_left_3_motor">
      <mechanicalReduction>1</mechanicalReduction>
    </actuator>
  </transmission>
  <transmission name="arm_left_4_trans">
    <type>transmission_interface/SimpleTransmission</type>
    <joint name="arm_left_4_joint">
      <hardwareInterface>PositionJointInterface</hardwareInterface>
      <hardwareInterface>VelocityJointInterface</hardwareInterface>
      <!--hardwareInterface>EffortJointInterface</hardwareInterface-->
    </joint>
    <actuator name="arm_left_4_motor">
      <mechanicalReduction>1</mechanicalReduction>
    </actuator>
  </transmission>
  <transmission name="arm_left_5_trans">
    <type>transmission_interface/SimpleTransmission</type>
    <joint name="arm_left_5_joint">
      <hardwareInterface>PositionJointInterface</hardwareInterface>
      <hardwareInterface>VelocityJointInterface</hardwareInterface>
      <!--hardwareInterface>EffortJointInterface</hardwareInterface-->
    </joint>
    <actuator name="arm_left_5_motor">
      <mechanicalReduction>1</mechanicalReduction>
    </actuator>
  </transmission>
  <transmission name="arm_left_6_trans">
    <type>transmission_interface/SimpleTransmission</type>
    <joint name="arm_left_6_joint">
      <hardwareInterface>PositionJointInterface</hardwareInterface>
      <hardwareInterface>VelocityJointInterface</hardwareInterface>
      <!--hardwareInterface>EffortJointInterface</hardwareInterface-->
    </joint>
    <actuator name="arm_left_6_motor">
      <mechanicalReduction>1</mechanicalReduction>
    </actuator>
  </transmission>
  <transmission name="arm_left_7_trans">
    <type>transmission_interface/SimpleTransmission</type>
    <joint name="arm_left_7_joint">
      <hardwareInterface>PositionJointInterface</hardwareInterface>
      <hardwareInterface>VelocityJointInterface</hardwareInterface>
      <!--hardwareInterface>EffortJointInterface</hardwareInterface-->
    </joint>
    <actuator name="arm_left_7_motor">
      <mechanicalReduction>1</mechanicalReduction>
    </actuator>
  </transmission>
  <!-- ros_control plugin -->
  <gazebo>
    <plugin filename="libhwi_switch_gazebo_ros_control.so" name="ros_control">
      <robotNamespace>arm_left</robotNamespace>
      <filterJointsParam>joint_names</filterJointsParam>
    </plugin>
  </gazebo>
  <!-- joint between base_link and gripper_base_link -->
  <joint name="gripper_right_base_joint" type="fixed">
    <origin rpy="0.0 0.0 3.14159" xyz="0.0 0.0 0.0748"/>
    <parent link="arm_right_7_link"/>
    <child link="gripper_right_base_link"/>
  </joint>
  <link name="gripper_right_base_link">
    <inertial>
      <mass value="0.01"/>
      <origin xyz="0 0 0"/>
      <inertia ixx="0.001" ixy="0.0" ixz="0.0" iyy="0.001" iyz="0.0" izz="0.001"/>
    </inertial>
    <visual>
      <origin rpy="0 0 0" xyz="0 0 0"/>
      <geometry>
        <box size="0.001 0.001 0.001"/>
      </geometry>
    </visual>
    <collision>
      <origin rpy="0 0 0" xyz="0 0 0"/>
      <geometry>
        <box size="0.001 0.001 0.001"/>
      </geometry>
    </collision>
  </link>
  <!-- joint between base_link and gripper_palm_link -->
  <joint name="gripper_right_palm_joint" type="fixed">
    <origin rpy="0 0 0" xyz="0 0 0"/>
    <parent link="gripper_right_base_link"/>
    <child link="gripper_right_palm_link"/>
  </joint>
  <link name="gripper_right_palm_link">
    <inertial>
      <mass value="0.01"/>
      <origin xyz="0 0 0"/>
      <inertia ixx="0.001" ixy="0.0" ixz="0.0" iyy="0.001" iyz="0.0" izz="0.001"/>
    </inertial>
    <visual>
      <origin rpy="0 0 0" xyz="0 0 0"/>
      <geometry>
        <mesh filename="package://cob_description/meshes/cob4_gripper/palm.dae"/>
      </geometry>
    </visual>
    <collision>
      <origin rpy="0 0 0" xyz="0 0 0"/>
      <geometry>
        <mesh filename="package://cob_description/meshes/cob4_gripper/palm.stl"/>
      </geometry>
    </collision>
  </link>
  <joint name="gripper_right_grasp_joint" type="fixed">
    <origin rpy="0 -1.57079632679 0" xyz="0 0 0.11"/>
    <parent link="gripper_right_base_link"/>
    <child link="gripper_right_grasp_link"/>
  </joint>
  <link name="gripper_right_grasp_link">
    <inertial>
      <mass value="0.01"/>
      <origin xyz="0 0 0"/>
      <inertia ixx="0.001" ixy="0.0" ixz="0.0" iyy="0.001" iyz="0.0" izz="0.001"/>
    </inertial>
    <visual>
      <origin rpy="0 0 0" xyz="0 0 0"/>
      <geometry>
        <box size="0.001 0.001 0.001"/>
      </geometry>
    </visual>
    <collision>
      <origin rpy="0 0 0" xyz="0 0 0"/>
      <geometry>
        <box size="0.001 0.001 0.001"/>
      </geometry>
    </collision>
  </link>
  <!-- joint between base_link and gripper_base_link -->
  <joint name="gripper_right_camera_joint" type="fixed">
    <origin rpy="0 1.57079632679 0" xyz="0 0 0"/>
    <parent link="gripper_right_palm_link"/>
    <child link="gripper_right_camera_link"/>
  </joint>
  <link name="gripper_right_camera_link">
    <inertial>
      <mass value="0.01"/>
      <origin xyz="0 0 0"/>
      <inertia ixx="0.001" ixy="0.0" ixz="0.0" iyy="0.001" iyz="0.0" izz="0.001"/>
    </inertial>
    <visual>
      <origin rpy="0 0 0" xyz="0 0 0"/>
      <geometry>
        <box size="0.001 0.001 0.001"/>
      </geometry>
    </visual>
    <collision>
      <origin rpy="0 0 0" xyz="0 0 0"/>
      <geometry>
        <box size="0.001 0.001 0.001"/>
      </geometry>
    </collision>
  </link>
  <!-- joint between gripper_palm_link and gripper_finger_1_link -->
  <joint name="gripper_right_finger_1_joint" type="revolute">
    <origin rpy="0 0 -0.2" xyz="-0.04409 0.02163  0"/>
    <parent link="gripper_right_camera_link"/>
    <child link="gripper_right_finger_1_link"/>
    <axis xyz="0 0 1"/>
    <dynamics damping="0.0" friction="0.0"/>
    <limit effort="200" lower="-1.047" upper="0.872" velocity="0.5"/>
  </joint>
  <link name="gripper_right_finger_1_link">
    <inertial>
      <mass value="0.01"/>
      <origin xyz="0 0 0"/>
      <inertia ixx="0.001" ixy="0.0" ixz="0.0" iyy="0.001" iyz="0.0" izz="0.001"/>
    </inertial>
    <visual>
      <origin rpy="0 0 0" xyz="0 0 0"/>
      <geometry>
        <mesh filename="package://cob_description/meshes/cob4_gripper/finger_1.dae"/>
      </geometry>
    </visual>
    <collision>
      <origin rpy="0 0 0" xyz="0 0 0"/>
      <geometry>
        <mesh filename="package://cob_description/meshes/cob4_gripper/finger_1.stl"/>
      </geometry>
    </collision>
  </link>
  <!-- joint between gripper_finger_1_link and gripper_finger_2_link -->
  <joint name="gripper_right_finger_2_joint" type="revolute">
    <origin rpy="0 0 0.3" xyz="-0.0712 0 0"/>
    <parent link="gripper_right_finger_1_link"/>
    <child link="gripper_right_finger_2_link"/>
    <axis xyz="0 0 1"/>
    <dynamics damping="0.0" friction="0.0"/>
    <limit effort="200" lower="-1.57079632679" upper="1.57079632679" velocity="0.5"/>
  </joint>
  <link name="gripper_right_finger_2_link">
    <inertial>
      <mass value="0.01"/>
      <origin xyz="0 0 0"/>
      <inertia ixx="0.001" ixy="0.0" ixz="0.0" iyy="0.001" iyz="0.0" izz="0.001"/>
    </inertial>
    <visual>
      <origin rpy="0 0 0" xyz="0 0 0"/>
      <geometry>
        <mesh filename="package://cob_description/meshes/cob4_gripper/finger_2.dae"/>
      </geometry>
    </visual>
    <collision>
      <origin rpy="0 0 0" xyz="0 0 0"/>
      <geometry>
        <mesh filename="package://cob_description/meshes/cob4_gripper/finger_2.stl"/>
      </geometry>
    </collision>
  </link>
  <gazebo reference="gripper_right_palm_link">
    <gravity>true</gravity>
    <self_collide>false</self_collide>
  </gazebo>
  <gazebo reference="gripper_right_finger_1_link">
    <gravity>true</gravity>
    <self_collide>false</self_collide>
  </gazebo>
  <gazebo reference="gripper_right_finger_2_link">
    <gravity>true</gravity>
    <self_collide>false</self_collide>
  </gazebo>
  <transmission name="gripper_right_finger_1_trans">
    <type>transmission_interface/SimpleTransmission</type>
    <joint name="gripper_right_finger_1_joint">
      <hardwareInterface>PositionJointInterface</hardwareInterface>
      <!--hardwareInterface>VelocityJointInterface</hardwareInterface-->
    </joint>
    <actuator name="gripper_right_finger_1_motor">
      <mechanicalReduction>1</mechanicalReduction>
    </actuator>
  </transmission>
  <transmission name="gripper_right_finger_2_trans">
    <type>transmission_interface/SimpleTransmission</type>
    <joint name="gripper_right_finger_2_joint">
      <hardwareInterface>PositionJointInterface</hardwareInterface>
      <!--hardwareInterface>VelocityJointInterface</hardwareInterface-->
    </joint>
    <actuator name="gripper_right_finger_2_motor">
      <mechanicalReduction>1</mechanicalReduction>
    </actuator>
  </transmission>
  <!-- ros_control plugin -->
  <gazebo>
    <plugin filename="libhwi_switch_gazebo_ros_control.so" name="ros_control">
      <robotNamespace>gripper_right</robotNamespace>
      <filterJointsParam>joint_names</filterJointsParam>
    </plugin>
  </gazebo>
  <!-- joint between base_link and gripper_base_link -->
  <joint name="gripper_left_base_joint" type="fixed">
    <origin rpy="0.0 0.0 3.14159" xyz="0.0 0.0 0.0748"/>
    <parent link="arm_left_7_link"/>
    <child link="gripper_left_base_link"/>
  </joint>
  <link name="gripper_left_base_link">
    <inertial>
      <mass value="0.01"/>
      <origin xyz="0 0 0"/>
      <inertia ixx="0.001" ixy="0.0" ixz="0.0" iyy="0.001" iyz="0.0" izz="0.001"/>
    </inertial>
    <visual>
      <origin rpy="0 0 0" xyz="0 0 0"/>
      <geometry>
        <box size="0.001 0.001 0.001"/>
      </geometry>
    </visual>
    <collision>
      <origin rpy="0 0 0" xyz="0 0 0"/>
      <geometry>
        <box size="0.001 0.001 0.001"/>
      </geometry>
    </collision>
  </link>
  <!-- joint between base_link and gripper_palm_link -->
  <joint name="gripper_left_palm_joint" type="fixed">
    <origin rpy="0 0 0" xyz="0 0 0"/>
    <parent link="gripper_left_base_link"/>
    <child link="gripper_left_palm_link"/>
  </joint>
  <link name="gripper_left_palm_link">
    <inertial>
      <mass value="0.01"/>
      <origin xyz="0 0 0"/>
      <inertia ixx="0.001" ixy="0.0" ixz="0.0" iyy="0.001" iyz="0.0" izz="0.001"/>
    </inertial>
    <visual>
      <origin rpy="0 0 0" xyz="0 0 0"/>
      <geometry>
        <mesh filename="package://cob_description/meshes/cob4_gripper/palm.dae"/>
      </geometry>
    </visual>
    <collision>
      <origin rpy="0 0 0" xyz="0 0 0"/>
      <geometry>
        <mesh filename="package://cob_description/meshes/cob4_gripper/palm.stl"/>
      </geometry>
    </collision>
  </link>
  <joint name="gripper_left_grasp_joint" type="fixed">
    <origin rpy="0 -1.57079632679 0" xyz="0 0 0.11"/>
    <parent link="gripper_left_base_link"/>
    <child link="gripper_left_grasp_link"/>
  </joint>
  <link name="gripper_left_grasp_link">
    <inertial>
      <mass value="0.01"/>
      <origin xyz="0 0 0"/>
      <inertia ixx="0.001" ixy="0.0" ixz="0.0" iyy="0.001" iyz="0.0" izz="0.001"/>
    </inertial>
    <visual>
      <origin rpy="0 0 0" xyz="0 0 0"/>
      <geometry>
        <box size="0.001 0.001 0.001"/>
      </geometry>
    </visual>
    <collision>
      <origin rpy="0 0 0" xyz="0 0 0"/>
      <geometry>
        <box size="0.001 0.001 0.001"/>
      </geometry>
    </collision>
  </link>
  <!-- joint between base_link and gripper_base_link -->
  <joint name="gripper_left_camera_joint" type="fixed">
    <origin rpy="0 1.57079632679 0" xyz="0 0 0"/>
    <parent link="gripper_left_palm_link"/>
    <child link="gripper_left_camera_link"/>
  </joint>
  <link name="gripper_left_camera_link">
    <inertial>
      <mass value="0.01"/>
      <origin xyz="0 0 0"/>
      <inertia ixx="0.001" ixy="0.0" ixz="0.0" iyy="0.001" iyz="0.0" izz="0.001"/>
    </inertial>
    <visual>
      <origin rpy="0 0 0" xyz="0 0 0"/>
      <geometry>
        <box size="0.001 0.001 0.001"/>
      </geometry>
    </visual>
    <collision>
      <origin rpy="0 0 0" xyz="0 0 0"/>
      <geometry>
        <box size="0.001 0.001 0.001"/>
      </geometry>
    </collision>
  </link>
  <!-- joint between gripper_palm_link and gripper_finger_1_link -->
  <joint name="gripper_left_finger_1_joint" type="revolute">
    <origin rpy="0 0 -0.2" xyz="-0.04409 0.02163  0"/>
    <parent link="gripper_left_camera_link"/>
    <child link="gripper_left_finger_1_link"/>
    <axis xyz="0 0 1"/>
    <dynamics damping="0.0" friction="0.0"/>
    <limit effort="200" lower="-1.047" upper="0.872" velocity="0.5"/>
  </joint>
  <link name="gripper_left_finger_1_link">
    <inertial>
      <mass value="0.01"/>
      <origin xyz="0 0 0"/>
      <inertia ixx="0.001" ixy="0.0" ixz="0.0" iyy="0.001" iyz="0.0" izz="0.001"/>
    </inertial>
    <visual>
      <origin rpy="0 0 0" xyz="0 0 0"/>
      <geometry>
        <mesh filename="package://cob_description/meshes/cob4_gripper/finger_1.dae"/>
      </geometry>
    </visual>
    <collision>
      <origin rpy="0 0 0" xyz="0 0 0"/>
      <geometry>
        <mesh filename="package://cob_description/meshes/cob4_gripper/finger_1.stl"/>
      </geometry>
    </collision>
  </link>
  <!-- joint between gripper_finger_1_link and gripper_finger_2_link -->
  <joint name="gripper_left_finger_2_joint" type="revolute">
    <origin rpy="0 0 0.3" xyz="-0.0712 0 0"/>
    <parent link="gripper_left_finger_1_link"/>
    <child link="gripper_left_finger_2_link"/>
    <axis xyz="0 0 1"/>
    <dynamics damping="0.0" friction="0.0"/>
    <limit effort="200" lower="-1.57079632679" upper="1.57079632679" velocity="0.5"/>
  </joint>
  <link name="gripper_left_finger_2_link">
    <inertial>
      <mass value="0.01"/>
      <origin xyz="0 0 0"/>
      <inertia ixx="0.001" ixy="0.0" ixz="0.0" iyy="0.001" iyz="0.0" izz="0.001"/>
    </inertial>
    <visual>
      <origin rpy="0 0 0" xyz="0 0 0"/>
      <geometry>
        <mesh filename="package://cob_description/meshes/cob4_gripper/finger_2.dae"/>
      </geometry>
    </visual>
    <collision>
      <origin rpy="0 0 0" xyz="0 0 0"/>
      <geometry>
        <mesh filename="package://cob_description/meshes/cob4_gripper/finger_2.stl"/>
      </geometry>
    </collision>
  </link>
  <gazebo reference="gripper_left_palm_link">
    <gravity>true</gravity>
    <self_collide>false</self_collide>
  </gazebo>
  <gazebo reference="gripper_left_finger_1_link">
    <gravity>true</gravity>
    <self_collide>false</self_collide>
  </gazebo>
  <gazebo reference="gripper_left_finger_2_link">
    <gravity>true</gravity>
    <self_collide>false</self_collide>
  </gazebo>
  <transmission name="gripper_left_finger_1_trans">
    <type>transmission_interface/SimpleTransmission</type>
    <joint name="gripper_left_finger_1_joint">
      <hardwareInterface>PositionJointInterface</hardwareInterface>
      <!--hardwareInterface>VelocityJointInterface</hardwareInterface-->
    </joint>
    <actuator name="gripper_left_finger_1_motor">
      <mechanicalReduction>1</mechanicalReduction>
    </actuator>
  </transmission>
  <transmission name="gripper_left_finger_2_trans">
    <type>transmission_interface/SimpleTransmission</type>
    <joint name="gripper_left_finger_2_joint">
      <hardwareInterface>PositionJointInterface</hardwareInterface>
      <!--hardwareInterface>VelocityJointInterface</hardwareInterface-->
    </joint>
    <actuator name="gripper_left_finger_2_motor">
      <mechanicalReduction>1</mechanicalReduction>
    </actuator>
  </transmission>
  <!-- ros_control plugin -->
  <gazebo>
    <plugin filename="libhwi_switch_gazebo_ros_control.so" name="ros_control">
      <robotNamespace>gripper_left</robotNamespace>
      <filterJointsParam>joint_names</filterJointsParam>
    </plugin>
  </gazebo>
</robot>

