<?xml version="1.0" ?>
<!-- =================================================================================== -->
<!-- |    This document was autogenerated by xacro from raw3-5.urdf.xacro              | -->
<!-- |    EDITING THIS FILE BY HAND IS NOT RECOMMENDED                                 | -->
<!-- =================================================================================== -->
<robot name="raw3-5" xmlns:xacro="http://www.ros.org/wiki/xacro">
  <!-- common stuff -->
  <!-- see https://secure.wikimedia.org/wikipedia/en/wiki/List_of_moment_of_inertia_tensors -->
  <material name="IPA/LightGrey">
    <color rgba="0.7 0.7 0.7 1.0"/>
  </material>
  <material name="IPA/DarkGrey">
    <color rgba="0.4 0.4 0.4 1.0"/>
  </material>
  <material name="IPA/Black">
    <color rgba="0.0 0.0 0.0 1.0"/>
  </material>
  <material name="IPA/Metall">
    <color rgba="0.7 0.7 0.7 1.0"/>
  </material>
  <material name="IPA/YellowRubber">
    <color rgba="0.4 0.27 0.16 1.0"/>
  </material>
  <material name="IPA/Orange">
    <color rgba="1.0 0.4 0.0 1.0"/>
  </material>
  <material name="IPA/Blue">
    <color rgba="0.0 0.0 0.5 1.0"/>
  </material>
  <!-- ***************** -->
  <!-- base calibration -->
  <!-- ***************** -->
  <!-- laser front mount positions | relative to base_link -->
  <!-- laser rear mount positions | relative to base_link -->
  <!-- ***************** -->
  <!-- base calibration -->
  <!-- ***************** -->
  <!-- laser front mount positions | relative to base_link -->
  <!-- laser rear mount positions | relative to base_link -->
  &gt;

	
  <!-- ***************** -->
  <!-- base calibration -->
  <!-- ***************** -->
  <!-- laser front mount positions | relative to base_link -->
  <!-- laser rear mount positions | relative to base_link -->
  <!-- raw base -->
  <!-- see https://secure.wikimedia.org/wikipedia/en/wiki/List_of_moment_of_inertia_tensors -->
  <!-- drive_wheel module -->
  <!--  Caster wheel transmission   -->
  <!-- Hub transmission only -->
  <!-- Macro for Caster hub only -->
  <!-- sensors -->
  <!--simple collision model for the laser -->
  <!-- properties -->
  <!--modify here-->
  <!-- battery macros-->
  <!-- composition of the robot -->
  <link name="base_footprint"/>
  <joint name="base_footprint_joint" type="fixed">
    <origin rpy="0 0 0" xyz="0 0 0"/>
    <parent link="base_footprint"/>
    <child link="base_link"/>
  </joint>
  <link name="base_link">
    <inertial>
      <origin xyz="0 0 0"/>
      <mass value="43.1"/>
      <inertia ixx="9.64" ixy="-0.02" ixz="0.44" iyy="11.33" iyz="-0.007" izz="3.07"/>
    </inertial>
    <visual>
      <origin rpy="0 0 0" xyz="0 0 0.209"/>
      <geometry>
        <mesh filename="package://raw_description/meshes/base/raw_base_short.dae"/>
      </geometry>
    </visual>
    <collision>
      <origin rpy="0 0 0" xyz="0 0 0.209"/>
      <geometry>
        <mesh filename="package://raw_description/meshes/base/raw_base_short.stl"/>
        <!--box size="0.758 0.573 0.096"/-->
      </geometry>
    </collision>
  </link>
  <!-- arrangement of the four drive_wheel modules -->
  <joint name="fl_caster_rotation_joint" type="continuous">
    <origin rpy="0 0 0" xyz="0.228 0.184 0.09"/>
    <parent link="base_link"/>
    <child link="fl_caster_rotation_link"/>
    <axis xyz="0 0 1"/>
    <limit effort="100" velocity="100"/>
    <!-- alpha tested velocity and effort limits -->
    <safety_controller k_velocity="10"/>
    <dynamics damping="0.0" friction="0.0"/>
  </joint>
  <link name="fl_caster_rotation_link">
    <inertial>
      <origin xyz="0 0 0"/>
      <mass value="5.9"/>
      <inertia ixx="0.04" ixy="-0.0007" ixz="0.0" iyy="0.02" iyz="-0.000004" izz="0.05"/>
    </inertial>
    <visual>
      <geometry>
        <mesh filename="package://cob_description/meshes/drive_wheel/caster.stl"/>
      </geometry>
      <material name="IPA/LightGrey"/>
    </visual>
    <collision>
      <geometry>
        <box size="0.001 0.001 0.001"/>
      </geometry>
    </collision>
  </link>
  <!-- extensions -->
  <transmission name="fl_caster_rotation_trans">
    <type>transmission_interface/SimpleTransmission</type>
    <joint name="fl_caster_rotation_joint">
      <hardwareInterface>VelocityJointInterface</hardwareInterface>
    </joint>
    <actuator name="fl_caster_rotation_motor">
      <mechanicalReduction>-79.2380952381</mechanicalReduction>
    </actuator>
  </transmission>
  <joint name="fl_caster_r_wheel_joint" type="continuous">
    <origin rpy="0 0 0" xyz="0 -0.0 0"/>
    <parent link="fl_caster_rotation_link"/>
    <child link="fl_caster_r_wheel_link"/>
    <axis xyz="0 1 0"/>
    <limit effort="100" velocity="100"/>
    <!-- alpha tested effort and velocity limits -->
    <safety_controller k_velocity="10"/>
    <dynamics damping="0.0" friction="0.0"/>
  </joint>
  <link name="fl_caster_r_wheel_link">
    <inertial>
      <origin xyz="0 0 0"/>
      <mass value="0.44036"/>
      <inertia ixx="0.012411765597" ixy="-0.000711733678" ixz="0.00050272983" iyy="0.015218160428" iyz="-0.000004273467" izz="0.011763977943"/>
    </inertial>
    <visual>
      <geometry>
        <mesh filename="package://cob_description/meshes/drive_wheel/wheel.dae"/>
      </geometry>
    </visual>
    <collision>
      <geometry>
        <mesh filename="package://cob_description/meshes/drive_wheel/wheel.stl"/>
      </geometry>
    </collision>
  </link>
  <!-- extensions -->
  <gazebo reference="fl_caster_r_wheel_link">
    <gravity>true</gravity>
    <self_collide>false</self_collide>
  </gazebo>
  <transmission name="fl_caster_r_wheel_trans">
    <type>transmission_interface/SimpleTransmission</type>
    <joint name="fl_caster_r_wheel_joint">
      <hardwareInterface>VelocityJointInterface</hardwareInterface>
    </joint>
    <actuator name="fl_caster_r_wheel_motor">
      <mechanicalReduction>-79.2380952381</mechanicalReduction>
    </actuator>
  </transmission>
  <!-- extensions -->
  <gazebo reference="fl_caster_rotation_link">
    <gravity>true</gravity>
    <self_collide>false</self_collide>
    <material value="IPA/Metal"/>
  </gazebo>
  <joint name="fr_caster_rotation_joint" type="continuous">
    <origin rpy="0 0 0" xyz="0.228 -0.134 0.09"/>
    <parent link="base_link"/>
    <child link="fr_caster_rotation_link"/>
    <axis xyz="0 0 1"/>
    <limit effort="100" velocity="100"/>
    <!-- alpha tested velocity and effort limits -->
    <safety_controller k_velocity="10"/>
    <dynamics damping="0.0" friction="0.0"/>
  </joint>
  <link name="fr_caster_rotation_link">
    <inertial>
      <origin xyz="0 0 0"/>
      <mass value="5.9"/>
      <inertia ixx="0.04" ixy="-0.0007" ixz="0.0" iyy="0.02" iyz="-0.000004" izz="0.05"/>
    </inertial>
    <visual>
      <geometry>
        <mesh filename="package://cob_description/meshes/drive_wheel/caster.stl"/>
      </geometry>
      <material name="IPA/LightGrey"/>
    </visual>
    <collision>
      <geometry>
        <box size="0.001 0.001 0.001"/>
      </geometry>
    </collision>
  </link>
  <!-- extensions -->
  <transmission name="fr_caster_rotation_trans">
    <type>transmission_interface/SimpleTransmission</type>
    <joint name="fr_caster_rotation_joint">
      <hardwareInterface>VelocityJointInterface</hardwareInterface>
    </joint>
    <actuator name="fr_caster_rotation_motor">
      <mechanicalReduction>-79.2380952381</mechanicalReduction>
    </actuator>
  </transmission>
  <joint name="fr_caster_r_wheel_joint" type="continuous">
    <origin rpy="0 0 0" xyz="0 -0.0 0"/>
    <parent link="fr_caster_rotation_link"/>
    <child link="fr_caster_r_wheel_link"/>
    <axis xyz="0 1 0"/>
    <limit effort="100" velocity="100"/>
    <!-- alpha tested effort and velocity limits -->
    <safety_controller k_velocity="10"/>
    <dynamics damping="0.0" friction="0.0"/>
  </joint>
  <link name="fr_caster_r_wheel_link">
    <inertial>
      <origin xyz="0 0 0"/>
      <mass value="0.44036"/>
      <inertia ixx="0.012411765597" ixy="-0.000711733678" ixz="0.00050272983" iyy="0.015218160428" iyz="-0.000004273467" izz="0.011763977943"/>
    </inertial>
    <visual>
      <geometry>
        <mesh filename="package://cob_description/meshes/drive_wheel/wheel.dae"/>
      </geometry>
    </visual>
    <collision>
      <geometry>
        <mesh filename="package://cob_description/meshes/drive_wheel/wheel.stl"/>
      </geometry>
    </collision>
  </link>
  <!-- extensions -->
  <gazebo reference="fr_caster_r_wheel_link">
    <gravity>true</gravity>
    <self_collide>false</self_collide>
  </gazebo>
  <transmission name="fr_caster_r_wheel_trans">
    <type>transmission_interface/SimpleTransmission</type>
    <joint name="fr_caster_r_wheel_joint">
      <hardwareInterface>VelocityJointInterface</hardwareInterface>
    </joint>
    <actuator name="fr_caster_r_wheel_motor">
      <mechanicalReduction>-79.2380952381</mechanicalReduction>
    </actuator>
  </transmission>
  <!-- extensions -->
  <gazebo reference="fr_caster_rotation_link">
    <gravity>true</gravity>
    <self_collide>false</self_collide>
    <material value="IPA/Metal"/>
  </gazebo>
  <joint name="bl_caster_rotation_joint" type="continuous">
    <origin rpy=" 0 0 0" xyz="-0.228 0.134 0.09"/>
    <parent link="base_link"/>
    <child link="bl_caster_rotation_link"/>
    <axis xyz="0 0 1"/>
    <limit effort="100" velocity="100"/>
    <!-- alpha tested velocity and effort limits -->
    <safety_controller k_velocity="10"/>
    <dynamics damping="0.0" friction="0.0"/>
  </joint>
  <link name="bl_caster_rotation_link">
    <inertial>
      <origin xyz="0 0 0"/>
      <mass value="5.9"/>
      <inertia ixx="0.04" ixy="-0.0007" ixz="0.0" iyy="0.02" iyz="-0.000004" izz="0.05"/>
    </inertial>
    <visual>
      <geometry>
        <mesh filename="package://cob_description/meshes/drive_wheel/caster.stl"/>
      </geometry>
      <material name="IPA/LightGrey"/>
    </visual>
    <collision>
      <geometry>
        <box size="0.001 0.001 0.001"/>
      </geometry>
    </collision>
  </link>
  <!-- extensions -->
  <transmission name="bl_caster_rotation_trans">
    <type>transmission_interface/SimpleTransmission</type>
    <joint name="bl_caster_rotation_joint">
      <hardwareInterface>VelocityJointInterface</hardwareInterface>
    </joint>
    <actuator name="bl_caster_rotation_motor">
      <mechanicalReduction>-79.2380952381</mechanicalReduction>
    </actuator>
  </transmission>
  <joint name="bl_caster_r_wheel_joint" type="continuous">
    <origin rpy="0 0 0" xyz="0 -0.0 0"/>
    <parent link="bl_caster_rotation_link"/>
    <child link="bl_caster_r_wheel_link"/>
    <axis xyz="0 1 0"/>
    <limit effort="100" velocity="100"/>
    <!-- alpha tested effort and velocity limits -->
    <safety_controller k_velocity="10"/>
    <dynamics damping="0.0" friction="0.0"/>
  </joint>
  <link name="bl_caster_r_wheel_link">
    <inertial>
      <origin xyz="0 0 0"/>
      <mass value="0.44036"/>
      <inertia ixx="0.012411765597" ixy="-0.000711733678" ixz="0.00050272983" iyy="0.015218160428" iyz="-0.000004273467" izz="0.011763977943"/>
    </inertial>
    <visual>
      <geometry>
        <mesh filename="package://cob_description/meshes/drive_wheel/wheel.dae"/>
      </geometry>
    </visual>
    <collision>
      <geometry>
        <mesh filename="package://cob_description/meshes/drive_wheel/wheel.stl"/>
      </geometry>
    </collision>
  </link>
  <!-- extensions -->
  <gazebo reference="bl_caster_r_wheel_link">
    <gravity>true</gravity>
    <self_collide>false</self_collide>
  </gazebo>
  <transmission name="bl_caster_r_wheel_trans">
    <type>transmission_interface/SimpleTransmission</type>
    <joint name="bl_caster_r_wheel_joint">
      <hardwareInterface>VelocityJointInterface</hardwareInterface>
    </joint>
    <actuator name="bl_caster_r_wheel_motor">
      <mechanicalReduction>-79.2380952381</mechanicalReduction>
    </actuator>
  </transmission>
  <!-- extensions -->
  <gazebo reference="bl_caster_rotation_link">
    <gravity>true</gravity>
    <self_collide>false</self_collide>
    <material value="IPA/Metal"/>
  </gazebo>
  <joint name="br_caster_rotation_joint" type="continuous">
    <origin rpy="0 0 0" xyz="-0.228 -0.184 0.09"/>
    <parent link="base_link"/>
    <child link="br_caster_rotation_link"/>
    <axis xyz="0 0 1"/>
    <limit effort="100" velocity="100"/>
    <!-- alpha tested velocity and effort limits -->
    <safety_controller k_velocity="10"/>
    <dynamics damping="0.0" friction="0.0"/>
  </joint>
  <link name="br_caster_rotation_link">
    <inertial>
      <origin xyz="0 0 0"/>
      <mass value="5.9"/>
      <inertia ixx="0.04" ixy="-0.0007" ixz="0.0" iyy="0.02" iyz="-0.000004" izz="0.05"/>
    </inertial>
    <visual>
      <geometry>
        <mesh filename="package://cob_description/meshes/drive_wheel/caster.stl"/>
      </geometry>
      <material name="IPA/LightGrey"/>
    </visual>
    <collision>
      <geometry>
        <box size="0.001 0.001 0.001"/>
      </geometry>
    </collision>
  </link>
  <!-- extensions -->
  <transmission name="br_caster_rotation_trans">
    <type>transmission_interface/SimpleTransmission</type>
    <joint name="br_caster_rotation_joint">
      <hardwareInterface>VelocityJointInterface</hardwareInterface>
    </joint>
    <actuator name="br_caster_rotation_motor">
      <mechanicalReduction>-79.2380952381</mechanicalReduction>
    </actuator>
  </transmission>
  <joint name="br_caster_r_wheel_joint" type="continuous">
    <origin rpy="0 0 0" xyz="0 -0.0 0"/>
    <parent link="br_caster_rotation_link"/>
    <child link="br_caster_r_wheel_link"/>
    <axis xyz="0 1 0"/>
    <limit effort="100" velocity="100"/>
    <!-- alpha tested effort and velocity limits -->
    <safety_controller k_velocity="10"/>
    <dynamics damping="0.0" friction="0.0"/>
  </joint>
  <link name="br_caster_r_wheel_link">
    <inertial>
      <origin xyz="0 0 0"/>
      <mass value="0.44036"/>
      <inertia ixx="0.012411765597" ixy="-0.000711733678" ixz="0.00050272983" iyy="0.015218160428" iyz="-0.000004273467" izz="0.011763977943"/>
    </inertial>
    <visual>
      <geometry>
        <mesh filename="package://cob_description/meshes/drive_wheel/wheel.dae"/>
      </geometry>
    </visual>
    <collision>
      <geometry>
        <mesh filename="package://cob_description/meshes/drive_wheel/wheel.stl"/>
      </geometry>
    </collision>
  </link>
  <!-- extensions -->
  <gazebo reference="br_caster_r_wheel_link">
    <gravity>true</gravity>
    <self_collide>false</self_collide>
  </gazebo>
  <transmission name="br_caster_r_wheel_trans">
    <type>transmission_interface/SimpleTransmission</type>
    <joint name="br_caster_r_wheel_joint">
      <hardwareInterface>VelocityJointInterface</hardwareInterface>
    </joint>
    <actuator name="br_caster_r_wheel_motor">
      <mechanicalReduction>-79.2380952381</mechanicalReduction>
    </actuator>
  </transmission>
  <!-- extensions -->
  <gazebo reference="br_caster_rotation_link">
    <gravity>true</gravity>
    <self_collide>false</self_collide>
    <material value="IPA/Metal"/>
  </gazebo>
  <!-- base laser front -->
  <joint name="base_laser_front_joint" type="fixed">
    <axis xyz="0 1 0"/>
    <origin rpy="3.14159265359 0.0 -0.785398163397" xyz="0.32501 -0.232 0.178"/>
    <parent link="base_link"/>
    <child link="base_laser_front_link"/>
  </joint>
  <link name="base_laser_front_link" type="laser">
    <inertial>
      <mass value="1.2"/>
      <origin rpy="0 0 0" xyz="0 0 0"/>
      <inertia ixx="0.0029999988" ixy="0.0" ixz="0.0" iyy="0.0029999988" iyz="0.0" izz="0.0015"/>
    </inertial>
    <visual>
      <origin rpy="0 0 0" xyz="0 0 0"/>
      <geometry>
        <mesh filename="package://cob_description/meshes/sensors/sick_s300_laser.dae"/>
        <!--box size="0.001 0.001 0.001" /-->
      </geometry>
      <material name="IPA/LightGrey"/>
    </visual>
    <collision>
      <origin rpy="0 0 0" xyz="0 0 0"/>
      <geometry>
        <mesh filename="package://cob_description/meshes/sensors/sick_s300_laser_collision.stl"/>
      </geometry>
    </collision>
  </link>
  <!-- gazebo extensions -->
  <gazebo reference="base_laser_front_link">
    <sensor name="base_laser_front" type="ray">
      <always_on>true</always_on>
      <update_rate>12.0</update_rate>
      <pose>0 0 0 0 0 0</pose>
      <visualize>false</visualize>
      <ray>
        <scan>
          <horizontal>
            <samples>541</samples>
            <resolution>1.0</resolution>
            <min_angle>-2.3562</min_angle>
            <max_angle>2.3562</max_angle>
          </horizontal>
        </scan>
        <range>
          <min>0.05</min>
          <max>30.0</max>
          <resolution>0.03</resolution>
        </range>
        <noise>
          <type>gaussian</type>
          <mean>0.0</mean>
          <stddev>0.005</stddev>
        </noise>
      </ray>
      <plugin filename="libgazebo_ros_laser.so" name="gazebo_ros_base_laser_front_controller">
        <topicName>base_laser_front/scan_raw</topicName>
        <frameName>base_laser_front_link</frameName>
      </plugin>
    </sensor>
  </gazebo>
  <!-- base laser rear -->
  <joint name="base_laser_rear_joint" type="fixed">
    <axis xyz="0 1 0"/>
    <origin rpy="3.14159265359 0.0 -3.92699081699" xyz="-0.32501 0.232 0.178"/>
    <parent link="base_link"/>
    <child link="base_laser_rear_link"/>
  </joint>
  <link name="base_laser_rear_link" type="laser">
    <inertial>
      <mass value="1.2"/>
      <origin rpy="0 0 0" xyz="0 0 0"/>
      <inertia ixx="0.0029999988" ixy="0.0" ixz="0.0" iyy="0.0029999988" iyz="0.0" izz="0.0015"/>
    </inertial>
    <visual>
      <origin rpy="0 0 0" xyz="0 0 0"/>
      <geometry>
        <mesh filename="package://cob_description/meshes/sensors/sick_s300_laser.dae"/>
        <!--box size="0.001 0.001 0.001" /-->
      </geometry>
      <material name="IPA/LightGrey"/>
    </visual>
    <collision>
      <origin rpy="0 0 0" xyz="0 0 0"/>
      <geometry>
        <mesh filename="package://cob_description/meshes/sensors/sick_s300_laser_collision.stl"/>
      </geometry>
    </collision>
  </link>
  <!-- gazebo extensions -->
  <gazebo reference="base_laser_rear_link">
    <sensor name="base_laser_rear" type="ray">
      <always_on>true</always_on>
      <update_rate>12.0</update_rate>
      <pose>0 0 0 0 0 0</pose>
      <visualize>false</visualize>
      <ray>
        <scan>
          <horizontal>
            <samples>541</samples>
            <resolution>1.0</resolution>
            <min_angle>-2.3562</min_angle>
            <max_angle>2.3562</max_angle>
          </horizontal>
        </scan>
        <range>
          <min>0.05</min>
          <max>30.0</max>
          <resolution>0.03</resolution>
        </range>
        <noise>
          <type>gaussian</type>
          <mean>0.0</mean>
          <stddev>0.005</stddev>
        </noise>
      </ray>
      <plugin filename="libgazebo_ros_laser.so" name="gazebo_ros_base_laser_rear_controller">
        <topicName>base_laser_rear/scan_raw</topicName>
        <frameName>base_laser_rear_link</frameName>
      </plugin>
    </sensor>
  </gazebo>
  <!-- cam3d -->
  <!--xacro:cob_kinect_v0 name="${name}_cam3d" ros_topic="cam3d" parent="${name}_link">
      <origin xyz="0.51 0.12 0.27" rpy="-${M_PI/2} 0 -${M_PI/2}" />
    </xacro:cob_kinect_v0-->
  <!-- battery-->
  <joint name="base_battery_battery_joint" type="fixed">
    <origin rpy="1.57079632679 0 -1.57079632679" xyz="-0.0 -0.008 0.065"/>
    <parent link="base_link"/>
    <child link="base_battery_battery"/>
  </joint>
  <link name="base_battery_battery">
    <inertial>
      <origin xyz="0 0 0"/>
      <mass value="40"/>
      <inertia ixx="0.01" ixy="0.0" ixz="0.0" iyy="0.01" iyz="0.0" izz="0.01"/>
    </inertial>
    <visual>
      <origin rpy="0 0 0" xyz="0 0 0"/>
      <geometry>
        <mesh filename="package://raw_description/meshes/base/raw_battery.stl"/>
      </geometry>
      <material name="Gazebo/Black"/>
    </visual>
    <collision>
      <origin rpy="0 0 0" xyz="0 0.075 0"/>
      <!-- TODO: Change the origin of the stl, so that collision model doesn't need to be translated  -->
      <geometry>
        <box size="0.5 0.148 0.26"/>
        <!--mesh filename="package://raw_description/meshes/base/raw_battery.stl"/-->
      </geometry>
    </collision>
  </link>
  <!-- extensions -->
  <gazebo reference="base_battery_battery">
    <gravity>true</gravity>
    <self_collide>false</self_collide>
    <material value="Gazebo/Black"/>
  </gazebo>
  <!-- gazebo extensions -->
  <gazebo reference="base_link">
    <gravity>true</gravity>
    <self_collide>false</self_collide>
    <sensor name="base_contact_sensor" type="contact">
      <always_on>true</always_on>
      <update_rate>100.0</update_rate>
      <contact>
        <collision>base_link_collision</collision>
        <topic>base_bumper</topic>
      </contact>
      <plugin filename="libgazebo_ros_bumper.so" name="base_gazebo_ros_bumper_controller">
        <frameName>world</frameName>
        <bumperTopicName>base_bumper</bumperTopicName>
      </plugin>
    </sensor>
  </gazebo>
  <gazebo>
    <plugin filename="libgazebo_ros_p3d.so" name="p3d_base_controller">
      <alwaysOn>true</alwaysOn>
      <updateRate>100.0</updateRate>
      <bodyName>base_link</bodyName>
      <topicName>base_pose_ground_truth</topicName>
      <frameName>map</frameName>
      <xyzOffsets>25.7 25.7 0</xyzOffsets>
      <!-- initialize odometry for fake localization-->
      <rpyOffsets>0 0 0</rpyOffsets>
      <gaussianNoise>0.01</gaussianNoise>
    </plugin>
    <canonicalBody>base_footprint</canonicalBody>
  </gazebo>
  <gazebo>
    <plugin filename="libhwi_switch_gazebo_ros_control.so" name="ros_control">
      <robotNamespace>base</robotNamespace>
      <filterJointsParam>joint_names</filterJointsParam>
    </plugin>
  </gazebo>
</robot>
