<?xml version="1.0" ?>
<!-- =================================================================================== -->
<!-- |    This document was autogenerated by xacro from cob4-1.urdf.xacro              | -->
<!-- |    EDITING THIS FILE BY HAND IS NOT RECOMMENDED                                 | -->
<!-- =================================================================================== -->
<robot name="cob4_1" xmlns:controller="http://playerstage.sourceforge.net/gazebo/xmlschema/#controller" xmlns:interface="http://playerstage.sourceforge.net/gazebo/xmlschema/#interface" xmlns:sensor="http://playerstage.sourceforge.net/gazebo/xmlschema/#sensor" xmlns:xacro="http://ros.org/wiki/xacro">
  <!-- common stuff -->
  <material name="IPA/LightGrey">
    <color rgba="0.7 0.7 0.7 1.0"/>
  </material>
  <material name="IPA/DarkGrey">
    <color rgba="0.4 0.4 0.4 1.0"/>
  </material>
  <material name="IPA/Orange">
    <color rgba="1.0 0.4 0.0 1.0"/>
  </material>
  <material name="IPA/Black">
    <color rgba="0.0 0.0 0.0 1.0"/>
  </material>
  <material name="IPA/Blue">
    <color rgba="0.0 0.0 0.5 1.0"/>
  </material>
  <material name="Schunk/LightGrey">
    <color rgba="0.7 0.7 0.7 1.0"/>
  </material>
  <material name="Schunk/DarkGrey">
    <color rgba="0.4 0.4 0.4 1.0"/>
  </material>
  <material name="Schunk/Black">
    <color rgba="0.0 0.0 0.0 1.0"/>
  </material>
  <material name="Schunk/DarkGolden">
    <color rgba="0.4 0.4 0.3 1.0"/>
  </material>
  <material name="Schunk/Blue">
    <color rgba="0.0 0.0 0.8 1.0"/>
  </material>
  <!-- calibration -->
  <!-- base -->
  <!-- torso -->
  <!-- arm -->
  <!-- head -->
  <!-- head_sensors -->
  <!-- generic simulator_gazebo plugins for starting mechanism control, ros time, ros battery -->
  <gazebo>
    <plugin filename="libgazebo_ros_controller_manager.so" name="gazebo_ros_controller_manager">
      <alwaysOn>true</alwaysOn>
      <updateRate>1000.0</updateRate>
    </plugin>
    <plugin filename="libgazebo_ros_power_monitor.so" name="gazebo_ros_power_monitor_controller">
      <alwaysOn>true</alwaysOn>
      <updateRate>1.0</updateRate>
      <timeout>5</timeout>
      <powerStateTopic>power_state</powerStateTopic>
      <powerStateRate>10.0</powerStateRate>
      <fullChargeCapacity>87.78</fullChargeCapacity>
      <dischargeRate>-474</dischargeRate>
      <chargeRate>525</chargeRate>
      <dischargeVoltage>15.52</dischargeVoltage>
      <chargeVoltage>16.41</chargeVoltage>
    </plugin>
  </gazebo>
  <!-- composition of the robot -->
  <link name="base_footprint">
    <inertial>
      <mass value="1.0"/>
      <origin xyz="0 0 0"/>
      <inertia ixx="0.01" ixy="0.0" ixz="0.0" iyy="0.01" iyz="0.0" izz="0.01"/>
    </inertial>
    <visual>
      <origin rpy="0 0 0" xyz="0 0 0"/>
      <geometry>
        <box size="0.01 0.01 0.01"/>
      </geometry>
      <material name="IPA/LightGrey"/>
    </visual>
    <collision>
      <origin rpy="0 0 0" xyz="0 0 0.1"/>
      <geometry>
        <box size="0.001 0.001 0.001"/>
      </geometry>
    </collision>
  </link>
  <joint name="base_footprint_joint" type="fixed">
    <origin rpy="0 0 0" xyz="0 0 0"/>
    <child link="base_link"/>
    <parent link="base_footprint"/>
  </joint>
  <link name="base_link">
    <inertial>
      <mass value="50"/>
      <origin xyz="0 0 0"/>
      <inertia ixx="5.652232699207" ixy="-0.009719934438" ixz="1.293988226423" iyy="5.669473158652" iyz="-0.007379583694" izz="3.683196351726"/>
    </inertial>
    <visual>
      <origin rpy="0 0 3.14159" xyz="0 0 0.05"/>
      <geometry>
        <mesh filename="package://cob_description/meshes/base_cob4/base_link.stl"/>
        <!--box size="0.01 0.01 0.01" /-->
      </geometry>
      <material name="IPA/LightGrey"/>
    </visual>
    <collision>
      <origin rpy="0 0 3.14159" xyz="0 0 0.05"/>
      <geometry>
        <mesh filename="package://cob_description/meshes/base_cob4/base_link.stl"/>
        <!--box size="0.01 0.01 0.01" /-->
      </geometry>
    </collision>
  </link>
  <joint name="base_laser_1_joint" type="fixed">
    <axis xyz="0 1 0"/>
    <origin rpy="0.0 0.0 0.0" xyz="0.244 0.0 0.08"/>
    <parent link="base_link"/>
    <child link="base_laser_1_link"/>
  </joint>
  <link name="base_laser_1_link" type="laser">
    <inertial>
      <mass value="0.001"/>
      <origin rpy="0 0 0" xyz="0 0 0"/>
      <inertia ixx="0.0001" ixy="0" ixz="0" iyy="0.000001" iyz="0" izz="0.0001"/>
    </inertial>
    <visual>
      <origin rpy="0 0 0" xyz="0 0 0"/>
      <geometry>
        <mesh filename="package://cob_description/meshes/sensors/sick_s300_laser.dae"/>
        <!--box size="0.001 0.001 0.001" /-->
      </geometry>
      <material name="IPA/LightGrey"/>
    </visual>
    <collision>
      <origin rpy="0 0 0" xyz="0 0 0"/>
      <geometry>
        <cylinder length="0.09" radius="0.044"/>
      </geometry>
    </collision>
  </link>
  <gazebo reference="base_laser_1_link">
    <sensor name="base_laser_1" type="ray">
      <always_on>true</always_on>
      <update_rate>12</update_rate>
      <pose>0 0 0 0 0 0</pose>
      <visualize>false</visualize>
      <ray>
        <scan>
          <horizontal>
            <samples>541</samples>
            <resolution>1.0</resolution>
            <min_angle>-2.094</min_angle>
            <max_angle>2.094</max_angle>
          </horizontal>
        </scan>
        <range>
          <min>0.05</min>
          <max>30.0</max>
          <resolution>0.03</resolution>
        </range>
      </ray>
      <plugin filename="libgazebo_ros_laser.so" name="gazebo_ros_base_laser_1_controller">
        <gaussianNoise>0.005</gaussianNoise>
        <alwaysOn>true</alwaysOn>
        <updateRate>12</updateRate>
        <topicName>scan_1_raw</topicName>
        <frameName>base_laser_1_link</frameName>
      </plugin>
    </sensor>
    <!--material value="IPA/LightGrey" /-->
  </gazebo>
  <joint name="base_laser_2_joint" type="fixed">
    <axis xyz="0 1 0"/>
    <origin rpy="0.0 0.0 2.094" xyz="-0.122 0.21131 0.08"/>
    <parent link="base_link"/>
    <child link="base_laser_2_link"/>
  </joint>
  <link name="base_laser_2_link" type="laser">
    <inertial>
      <mass value="0.001"/>
      <origin rpy="0 0 0" xyz="0 0 0"/>
      <inertia ixx="0.0001" ixy="0" ixz="0" iyy="0.000001" iyz="0" izz="0.0001"/>
    </inertial>
    <visual>
      <origin rpy="0 0 0" xyz="0 0 0"/>
      <geometry>
        <mesh filename="package://cob_description/meshes/sensors/sick_s300_laser.dae"/>
        <!--box size="0.001 0.001 0.001" /-->
      </geometry>
      <material name="IPA/LightGrey"/>
    </visual>
    <collision>
      <origin rpy="0 0 0" xyz="0 0 0"/>
      <geometry>
        <cylinder length="0.09" radius="0.044"/>
      </geometry>
    </collision>
  </link>
  <gazebo reference="base_laser_2_link">
    <sensor name="base_laser_2" type="ray">
      <always_on>true</always_on>
      <update_rate>12</update_rate>
      <pose>0 0 0 0 0 0</pose>
      <visualize>false</visualize>
      <ray>
        <scan>
          <horizontal>
            <samples>541</samples>
            <resolution>1.0</resolution>
            <min_angle>-2.094</min_angle>
            <max_angle>2.094</max_angle>
          </horizontal>
        </scan>
        <range>
          <min>0.05</min>
          <max>30.0</max>
          <resolution>0.03</resolution>
        </range>
      </ray>
      <plugin filename="libgazebo_ros_laser.so" name="gazebo_ros_base_laser_2_controller">
        <gaussianNoise>0.005</gaussianNoise>
        <alwaysOn>true</alwaysOn>
        <updateRate>12</updateRate>
        <topicName>scan_2_raw</topicName>
        <frameName>base_laser_2_link</frameName>
      </plugin>
    </sensor>
    <!--material value="IPA/LightGrey" /-->
  </gazebo>
  <joint name="base_laser_3_joint" type="fixed">
    <axis xyz="0 1 0"/>
    <origin rpy="0.0 0.0 -2.094" xyz="-0.122 -0.21131 0.08"/>
    <parent link="base_link"/>
    <child link="base_laser_3_link"/>
  </joint>
  <link name="base_laser_3_link" type="laser">
    <inertial>
      <mass value="0.001"/>
      <origin rpy="0 0 0" xyz="0 0 0"/>
      <inertia ixx="0.0001" ixy="0" ixz="0" iyy="0.000001" iyz="0" izz="0.0001"/>
    </inertial>
    <visual>
      <origin rpy="0 0 0" xyz="0 0 0"/>
      <geometry>
        <mesh filename="package://cob_description/meshes/sensors/sick_s300_laser.dae"/>
        <!--box size="0.001 0.001 0.001" /-->
      </geometry>
      <material name="IPA/LightGrey"/>
    </visual>
    <collision>
      <origin rpy="0 0 0" xyz="0 0 0"/>
      <geometry>
        <cylinder length="0.09" radius="0.044"/>
      </geometry>
    </collision>
  </link>
  <gazebo reference="base_laser_3_link">
    <sensor name="base_laser_3" type="ray">
      <always_on>true</always_on>
      <update_rate>12</update_rate>
      <pose>0 0 0 0 0 0</pose>
      <visualize>false</visualize>
      <ray>
        <scan>
          <horizontal>
            <samples>541</samples>
            <resolution>1.0</resolution>
            <min_angle>-2.094</min_angle>
            <max_angle>2.094</max_angle>
          </horizontal>
        </scan>
        <range>
          <min>0.05</min>
          <max>30.0</max>
          <resolution>0.03</resolution>
        </range>
      </ray>
      <plugin filename="libgazebo_ros_laser.so" name="gazebo_ros_base_laser_3_controller">
        <gaussianNoise>0.005</gaussianNoise>
        <alwaysOn>true</alwaysOn>
        <updateRate>12</updateRate>
        <topicName>scan_3_raw</topicName>
        <frameName>base_laser_3_link</frameName>
      </plugin>
    </sensor>
    <!--material value="IPA/LightGrey" /-->
  </gazebo>
  <joint name="fl_caster_rotation_joint" type="continuous">
    <axis xyz="0 0 1"/>
    <limit effort="100" velocity="100"/>
    <!-- alpha tested velocity and effort limits -->
    <safety_controller k_velocity="10"/>
    <calibration rising="0"/>
    <dynamics damping="0.0" friction="0.0"/>
    <origin rpy="0 0 0" xyz="0.12422 0.21515 0.08"/>
    <parent link="base_link"/>
    <child link="fl_caster_rotation_link"/>
  </joint>
  <link name="fl_caster_rotation_link">
    <inertial>
      <mass value="5.9"/>
      <origin xyz="0 0 0"/>
      <inertia ixx="0.04" ixy="-0.0007" ixz="0.0" iyy="0.02" iyz="-0.000004" izz="0.05"/>
    </inertial>
    <visual>
      <origin rpy="0 0 0" xyz="0 0 0"/>
      <geometry>
        <mesh filename="package://raw_description/meshes/base/raw_caster.stl"/>
      </geometry>
      <material name="IPA/LightGrey"/>
    </visual>
    <collision>
      <origin rpy="0 0 0" xyz="0 0 0"/>
      <geometry>
        <box size="0.001 0.001 0.001"/>
      </geometry>
    </collision>
  </link>
  <transmission name="fl_caster_rotation_trans" type="pr2_mechanism_model/SimpleTransmission">
    <actuator name="fl_caster_rotation_motor"/>
    <joint name="fl_caster_rotation_joint"/>
    <mechanicalReduction>-79.2380952381</mechanicalReduction>
  </transmission>
  <joint name="fl_caster_r_wheel_joint" type="continuous">
    <axis xyz="0 1 0"/>
    <limit effort="100" velocity="100"/>
    <!-- alpha tested effort and velocity limits -->
    <safety_controller k_velocity="10"/>
    <dynamics damping="0.0" friction="0.0"/>
    <origin rpy="0 0 0" xyz="0 -0.0 0"/>
    <parent link="fl_caster_rotation_link"/>
    <child link="fl_caster_r_wheel_link"/>
  </joint>
  <link name="fl_caster_r_wheel_link">
    <inertial>
      <mass value="0.44036"/>
      <origin xyz="0 0 0"/>
      <inertia ixx="0.012411765597" ixy="-0.000711733678" ixz="0.00050272983" iyy="0.015218160428" iyz="-0.000004273467" izz="0.011763977943"/>
    </inertial>
    <visual>
      <origin rpy="1.57079632679 0 0" xyz="0 0 0"/>
      <geometry>
        <cylinder length="0.025" radius="0.074792"/>
      </geometry>
      <material name="IPA/LightGrey"/>
    </visual>
    <collision>
      <origin rpy="1.57079632679 0 0" xyz="0 0 0"/>
      <!-- rotation because cyl. geom primitive has symmetry axis in +x direction -->
      <geometry>
        <cylinder length="0.025" radius="0.074792"/>
      </geometry>
    </collision>
  </link>
  <gazebo reference="fl_caster_r_wheel_link">
    <mu1 value="100.0"/>
    <mu2 value="100.0"/>
    <kp value="1000000.0"/>
    <kd value="1.0"/>
    <material>IPA/LightGrey</material>
  </gazebo>
  <transmission name="fl_caster_r_wheel_trans" type="pr2_mechanism_model/SimpleTransmission">
    <actuator name="fl_caster_r_wheel_motor"/>
    <joint name="fl_caster_r_wheel_joint"/>
    <mechanicalReduction>-79.2380952381</mechanicalReduction>
  </transmission>
  <gazebo reference="fl_caster_rotation_link">
    <material value="PR2/caster_texture"/>
  </gazebo>
  <joint name="bl_caster_rotation_joint" type="continuous">
    <axis xyz="0 0 1"/>
    <limit effort="100" velocity="100"/>
    <!-- alpha tested velocity and effort limits -->
    <safety_controller k_velocity="10"/>
    <calibration rising="0"/>
    <dynamics damping="0.0" friction="0.0"/>
    <origin rpy="0 0 0" xyz="-0.24844 0 0.08"/>
    <parent link="base_link"/>
    <child link="bl_caster_rotation_link"/>
  </joint>
  <link name="bl_caster_rotation_link">
    <inertial>
      <mass value="5.9"/>
      <origin xyz="0 0 0"/>
      <inertia ixx="0.04" ixy="-0.0007" ixz="0.0" iyy="0.02" iyz="-0.000004" izz="0.05"/>
    </inertial>
    <visual>
      <origin rpy="0 0 0" xyz="0 0 0"/>
      <geometry>
        <mesh filename="package://raw_description/meshes/base/raw_caster.stl"/>
      </geometry>
      <material name="IPA/LightGrey"/>
    </visual>
    <collision>
      <origin rpy="0 0 0" xyz="0 0 0"/>
      <geometry>
        <box size="0.001 0.001 0.001"/>
      </geometry>
    </collision>
  </link>
  <transmission name="bl_caster_rotation_trans" type="pr2_mechanism_model/SimpleTransmission">
    <actuator name="bl_caster_rotation_motor"/>
    <joint name="bl_caster_rotation_joint"/>
    <mechanicalReduction>-79.2380952381</mechanicalReduction>
  </transmission>
  <joint name="bl_caster_r_wheel_joint" type="continuous">
    <axis xyz="0 1 0"/>
    <limit effort="100" velocity="100"/>
    <!-- alpha tested effort and velocity limits -->
    <safety_controller k_velocity="10"/>
    <dynamics damping="0.0" friction="0.0"/>
    <origin rpy="0 0 0" xyz="0 -0.0 0"/>
    <parent link="bl_caster_rotation_link"/>
    <child link="bl_caster_r_wheel_link"/>
  </joint>
  <link name="bl_caster_r_wheel_link">
    <inertial>
      <mass value="0.44036"/>
      <origin xyz="0 0 0"/>
      <inertia ixx="0.012411765597" ixy="-0.000711733678" ixz="0.00050272983" iyy="0.015218160428" iyz="-0.000004273467" izz="0.011763977943"/>
    </inertial>
    <visual>
      <origin rpy="1.57079632679 0 0" xyz="0 0 0"/>
      <geometry>
        <cylinder length="0.025" radius="0.074792"/>
      </geometry>
      <material name="IPA/LightGrey"/>
    </visual>
    <collision>
      <origin rpy="1.57079632679 0 0" xyz="0 0 0"/>
      <!-- rotation because cyl. geom primitive has symmetry axis in +x direction -->
      <geometry>
        <cylinder length="0.025" radius="0.074792"/>
      </geometry>
    </collision>
  </link>
  <gazebo reference="bl_caster_r_wheel_link">
    <mu1 value="100.0"/>
    <mu2 value="100.0"/>
    <kp value="1000000.0"/>
    <kd value="1.0"/>
    <material>IPA/LightGrey</material>
  </gazebo>
  <transmission name="bl_caster_r_wheel_trans" type="pr2_mechanism_model/SimpleTransmission">
    <actuator name="bl_caster_r_wheel_motor"/>
    <joint name="bl_caster_r_wheel_joint"/>
    <mechanicalReduction>-79.2380952381</mechanicalReduction>
  </transmission>
  <gazebo reference="bl_caster_rotation_link">
    <material value="PR2/caster_texture"/>
  </gazebo>
  <joint name="br_caster_rotation_joint" type="continuous">
    <axis xyz="0 0 1"/>
    <limit effort="100" velocity="100"/>
    <!-- alpha tested velocity and effort limits -->
    <safety_controller k_velocity="10"/>
    <calibration rising="0"/>
    <dynamics damping="0.0" friction="0.0"/>
    <origin rpy="0 0 0" xyz="0.12422 -0.21515 0.08"/>
    <parent link="base_link"/>
    <child link="br_caster_rotation_link"/>
  </joint>
  <link name="br_caster_rotation_link">
    <inertial>
      <mass value="5.9"/>
      <origin xyz="0 0 0"/>
      <inertia ixx="0.04" ixy="-0.0007" ixz="0.0" iyy="0.02" iyz="-0.000004" izz="0.05"/>
    </inertial>
    <visual>
      <origin rpy="0 0 0" xyz="0 0 0"/>
      <geometry>
        <mesh filename="package://raw_description/meshes/base/raw_caster.stl"/>
      </geometry>
      <material name="IPA/LightGrey"/>
    </visual>
    <collision>
      <origin rpy="0 0 0" xyz="0 0 0"/>
      <geometry>
        <box size="0.001 0.001 0.001"/>
      </geometry>
    </collision>
  </link>
  <transmission name="br_caster_rotation_trans" type="pr2_mechanism_model/SimpleTransmission">
    <actuator name="br_caster_rotation_motor"/>
    <joint name="br_caster_rotation_joint"/>
    <mechanicalReduction>-79.2380952381</mechanicalReduction>
  </transmission>
  <joint name="br_caster_r_wheel_joint" type="continuous">
    <axis xyz="0 1 0"/>
    <limit effort="100" velocity="100"/>
    <!-- alpha tested effort and velocity limits -->
    <safety_controller k_velocity="10"/>
    <dynamics damping="0.0" friction="0.0"/>
    <origin rpy="0 0 0" xyz="0 -0.0 0"/>
    <parent link="br_caster_rotation_link"/>
    <child link="br_caster_r_wheel_link"/>
  </joint>
  <link name="br_caster_r_wheel_link">
    <inertial>
      <mass value="0.44036"/>
      <origin xyz="0 0 0"/>
      <inertia ixx="0.012411765597" ixy="-0.000711733678" ixz="0.00050272983" iyy="0.015218160428" iyz="-0.000004273467" izz="0.011763977943"/>
    </inertial>
    <visual>
      <origin rpy="1.57079632679 0 0" xyz="0 0 0"/>
      <geometry>
        <cylinder length="0.025" radius="0.074792"/>
      </geometry>
      <material name="IPA/LightGrey"/>
    </visual>
    <collision>
      <origin rpy="1.57079632679 0 0" xyz="0 0 0"/>
      <!-- rotation because cyl. geom primitive has symmetry axis in +x direction -->
      <geometry>
        <cylinder length="0.025" radius="0.074792"/>
      </geometry>
    </collision>
  </link>
  <gazebo reference="br_caster_r_wheel_link">
    <mu1 value="100.0"/>
    <mu2 value="100.0"/>
    <kp value="1000000.0"/>
    <kd value="1.0"/>
    <material>IPA/LightGrey</material>
  </gazebo>
  <transmission name="br_caster_r_wheel_trans" type="pr2_mechanism_model/SimpleTransmission">
    <actuator name="br_caster_r_wheel_motor"/>
    <joint name="br_caster_r_wheel_joint"/>
    <mechanicalReduction>-79.2380952381</mechanicalReduction>
  </transmission>
  <gazebo reference="br_caster_rotation_link">
    <material value="PR2/caster_texture"/>
  </gazebo>
  <gazebo reference="base_link">
    <selfCollide>true</selfCollide>
    <sensor name="base_contact_sensor" type="contact">
      <contact>
        <collision>base_link_geom</collision>
      </contact>
      <plugin filename="libgazebo_ros_bumper.so" name="base_gazebo_ros_bumper_controller">
        <alwaysOn>true</alwaysOn>
        <updateRate>100.0</updateRate>
        <bumperTopicName>base_bumper</bumperTopicName>
      </plugin>
    </sensor>
    <material>IPA/DarkGrey</material>
  </gazebo>
  <gazebo>
    <plugin filename="libgazebo_ros_p3d.so" name="p3d_base_controller">
      <alwaysOn>true</alwaysOn>
      <updateRate>100.0</updateRate>
      <bodyName>base_link</bodyName>
      <topicName>base_pose_ground_truth</topicName>
      <gaussianNoise>0.01</gaussianNoise>
      <frameName>map</frameName>
      <xyzOffsets>25.7 25.7 0</xyzOffsets>
      <!-- initialize odometry for fake localization-->
      <rpyOffsets>0 0 0</rpyOffsets>
    </plugin>
    <canonicalBody>base_footprint</canonicalBody>
  </gazebo>
  <joint name="torso_base_joint" type="fixed">
    <origin rpy="0.0 0.0 0.0" xyz="0.0 0.0 0.26411"/>
    <child link="torso_base_link"/>
    <parent link="base_link"/>
  </joint>
  <link name="torso_base_link"/>
  <joint name="torso_1_joint" type="revolute">
    <origin rpy="0 0 0" xyz="0 0 0.04642"/>
    <child link="torso_1_link"/>
    <parent link="torso_base_link"/>
    <calibration rising="0.0"/>
    <axis xyz="0 0 1"/>
    <dynamics damping="0.1"/>
    <limit effort="100" lower="-6.2831" upper="6.2831" velocity="1.4"/>
  </joint>
  <link name="torso_1_link"/>
  <joint name="torso_2_joint" type="revolute">
    <origin rpy="-0.5236 0 0" xyz="0 -0.14734 0.07547"/>
    <child link="torso_2_link"/>
    <parent link="torso_1_link"/>
    <calibration rising="0.0"/>
    <axis xyz="0 0 1"/>
    <dynamics damping="0.1"/>
    <limit effort="100" lower="-6.2831" upper="6.2831" velocity="1.4"/>
  </joint>
  <link name="torso_2_link"/>
  <joint name="torso_3_joint" type="revolute">
    <origin rpy="0.5236 0 0" xyz="0 0.06223 0.15206"/>
    <child link="torso_3_link"/>
    <parent link="torso_2_link"/>
    <calibration rising="0.0"/>
    <axis xyz="0 0 1"/>
    <dynamics damping="0.1"/>
    <limit effort="100" lower="-6.2831" upper="6.2831" velocity="1.4"/>
  </joint>
  <link name="torso_3_link">
    <inertial>
      <mass value="10"/>
      <origin xyz="0 0 0"/>
      <inertia ixx="5.652232699207" ixy="-0.009719934438" ixz="1.293988226423" iyy="5.669473158652" iyz="-0.007379583694" izz="3.683196351726"/>
    </inertial>
    <visual>
      <origin rpy="0 0 0" xyz="0 0 0"/>
      <geometry>
        <mesh filename="package://cob_description/meshes/torso_cob4/torso_link.stl"/>
      </geometry>
      <material name="IPA/LightGrey"/>
    </visual>
    <collision>
      <origin rpy="0 0 0" xyz="0 0 0"/>
      <geometry>
        <box size="0.001 0.001 0.001"/>
      </geometry>
    </collision>
  </link>
  <gazebo reference="torso_base_link">
    <material>IPA/LightGrey</material>
    <turnGravityOff>false</turnGravityOff>
  </gazebo>
  <gazebo reference="torso_1_link">
    <material>IPA/LightGrey</material>
    <turnGravityOff>false</turnGravityOff>
  </gazebo>
  <gazebo reference="torso_2_link">
    <material>IPA/LightGrey</material>
    <turnGravityOff>false</turnGravityOff>
  </gazebo>
  <gazebo reference="torso_3_link">
    <material>IPA/LightGrey</material>
    <turnGravityOff>false</turnGravityOff>
  </gazebo>
  <transmission name="torso_1_trans" type="pr2_mechanism_model/SimpleTransmission">
    <actuator name="torso_1_motor"/>
    <joint name="torso_1_joint"/>
    <mechanicalReduction>1</mechanicalReduction>
  </transmission>
  <transmission name="torso_2_trans" type="pr2_mechanism_model/SimpleTransmission">
    <actuator name="torso_2_motor"/>
    <joint name="torso_2_joint"/>
    <mechanicalReduction>1</mechanicalReduction>
  </transmission>
  <transmission name="torso_3_trans" type="pr2_mechanism_model/SimpleTransmission">
    <actuator name="torso_3_motor"/>
    <joint name="torso_3_joint"/>
    <mechanicalReduction>1</mechanicalReduction>
  </transmission>
  <joint name="head_base_joint" type="fixed">
    <origin rpy="0.0 0.0 0.0" xyz="0.0 0.0 0.61"/>
    <child link="head_base_link"/>
    <parent link="torso_3_link"/>
  </joint>
  <link name="head_base_link"/>
  <joint name="head_1_joint" type="revolute">
    <origin rpy="0 0 0" xyz="0 0 0.0305"/>
    <child link="head_1_link"/>
    <parent link="head_base_link"/>
    <calibration rising="0.0"/>
    <axis xyz="0 0 1"/>
    <dynamics damping="0.1"/>
    <limit effort="100" lower="-6.2831" upper="6.2831" velocity="1.4"/>
  </joint>
  <link name="head_1_link"/>
  <joint name="head_2_joint" type="revolute">
    <origin rpy="-0.349 0 0" xyz="0 -0.07725 -0.00439"/>
    <child link="head_2_link"/>
    <parent link="head_1_link"/>
    <calibration rising="0.0"/>
    <axis xyz="0 0 1"/>
    <dynamics damping="0.1"/>
    <limit effort="100" lower="-6.2831" upper="6.2831" velocity="1.4"/>
  </joint>
  <link name="head_2_link"/>
  <joint name="head_3_joint" type="revolute">
    <origin rpy="0.349 0 0" xyz="0 0.08001 0.06809"/>
    <child link="head_3_link"/>
    <parent link="head_2_link"/>
    <calibration rising="0.0"/>
    <axis xyz="0 0 1"/>
    <dynamics damping="0.1"/>
    <limit effort="100" lower="-6.2831" upper="6.2831" velocity="1.4"/>
  </joint>
  <link name="head_3_link">
    <inertial>
      <mass value="10"/>
      <origin xyz="0 0 0"/>
      <inertia ixx="5.652232699207" ixy="-0.009719934438" ixz="1.293988226423" iyy="5.669473158652" iyz="-0.007379583694" izz="3.683196351726"/>
    </inertial>
    <visual>
      <origin rpy="0 0 0" xyz="0 0 0"/>
      <geometry>
        <mesh filename="package://cob_description/meshes/head_cob4/head_link.stl"/>
      </geometry>
      <material name="IPA/LightGrey"/>
    </visual>
    <collision>
      <origin rpy="0 0 0" xyz="0 0 0"/>
      <geometry>
        <box size="0.001 0.001 0.001"/>
      </geometry>
    </collision>
  </link>
  <gazebo reference="head_base_link">
    <material>IPA/LightGrey</material>
    <turnGravityOff>false</turnGravityOff>
  </gazebo>
  <gazebo reference="head_1_link">
    <material>IPA/LightGrey</material>
    <turnGravityOff>false</turnGravityOff>
  </gazebo>
  <gazebo reference="head_2_link">
    <material>IPA/LightGrey</material>
    <turnGravityOff>false</turnGravityOff>
  </gazebo>
  <gazebo reference="head_3_link">
    <material>IPA/LightGrey</material>
    <turnGravityOff>false</turnGravityOff>
  </gazebo>
  <transmission name="head_1_trans" type="pr2_mechanism_model/SimpleTransmission">
    <actuator name="head_1_motor"/>
    <joint name="head_1_joint"/>
    <mechanicalReduction>1</mechanicalReduction>
  </transmission>
  <transmission name="head_2_trans" type="pr2_mechanism_model/SimpleTransmission">
    <actuator name="head_2_motor"/>
    <joint name="head_2_joint"/>
    <mechanicalReduction>1</mechanicalReduction>
  </transmission>
  <transmission name="head_3_trans" type="pr2_mechanism_model/SimpleTransmission">
    <actuator name="head_3_motor"/>
    <joint name="head_3_joint"/>
    <mechanicalReduction>1</mechanicalReduction>
  </transmission>
  <joint name="head_sensors_base_joint" type="revolute">
    <origin rpy="0.0 0.0 0.0" xyz="0.0 0.0 0.07"/>
    <child link="head_sensors_base_link"/>
    <parent link="head_3_link"/>
    <calibration rising="0.0"/>
    <axis xyz="0 0 1"/>
    <dynamics damping="0.1"/>
    <limit effort="100" lower="-6.2831" upper="6.2831" velocity="1.4"/>
  </joint>
  <link name="head_sensors_base_link"/>
  <joint name="arm_right_base_joint" type="fixed">
    <origin rpy="1.57097 0.0 0.0" xyz="0.0 -0.148 0.55"/>
    <parent link="torso_3_link"/>
    <child link="arm_right_base_link"/>
  </joint>
  <link name="arm_right_base_link"/>
  <joint name="arm_right_1_joint" type="revolute">
    <origin rpy="0 0 0" xyz="0 0 0"/>
    <parent link="arm_right_base_link"/>
    <child link="arm_right_1_link"/>
    <axis xyz="0 0 1"/>
    <calibration rising="0.0"/>
    <dynamics damping="10"/>
    <limit effort="370" lower="-6.2831853" upper="6.2831853" velocity="2.0"/>
    <safety_controller k_position="20" k_velocity="50" soft_lower_limit="-6.2731853" soft_upper_limit="6.2731853"/>
  </joint>
  <link name="arm_right_1_link"/>
  <joint name="arm_right_2_joint" type="revolute">
    <origin rpy="1.5708 0 0" xyz="0 0 0.0915"/>
    <parent link="arm_right_1_link"/>
    <child link="arm_right_2_link"/>
    <axis xyz="0 0 1"/>
    <calibration rising="0.0"/>
    <dynamics damping="10"/>
    <limit effort="370" lower="-2.0943951" upper="2.0943951" velocity="2.0"/>
    <safety_controller k_position="20" k_velocity="50" soft_lower_limit="-2.0843" soft_upper_limit="2.0843"/>
  </joint>
  <link name="arm_right_2_link"/>
  <joint name="arm_right_3_joint" type="revolute">
    <origin rpy="-1.5708 0 0" xyz="0 0 0"/>
    <parent link="arm_right_2_link"/>
    <child link="arm_right_3_link"/>
    <axis xyz="0 0 1"/>
    <calibration rising="0.0"/>
    <dynamics damping="5"/>
    <limit effort="176" lower="-6.2831853" upper="6.2831853" velocity="2.0"/>
    <safety_controller k_position="20" k_velocity="25" soft_lower_limit="-6.2731853" soft_upper_limit="6.2731853"/>
  </joint>
  <link name="arm_right_3_link"/>
  <joint name="arm_right_4_joint" type="revolute">
    <origin rpy="1.5708 0 0" xyz="0 0 0.45360"/>
    <parent link="arm_right_3_link"/>
    <child link="arm_right_4_link"/>
    <axis xyz="0 0 1"/>
    <calibration rising="0.0"/>
    <dynamics damping="5"/>
    <limit effort="176" lower="-2.0943951" upper="2.0943951" velocity="2.0"/>
    <safety_controller k_position="20" k_velocity="25" soft_lower_limit="-2.0843951" soft_upper_limit="2.0843951"/>
  </joint>
  <link name="arm_right_4_link"/>
  <joint name="arm_right_5_joint" type="revolute">
    <origin rpy="-1.5708 0 0" xyz="0 0 0"/>
    <parent link="arm_right_4_link"/>
    <child link="arm_right_5_link"/>
    <axis xyz="0 0 1"/>
    <calibration rising="0.0"/>
    <dynamics damping="5"/>
    <limit effort="41.6" lower="-6.2831853" upper="6.2831853" velocity="2.0"/>
    <safety_controller k_position="20" k_velocity="25" soft_lower_limit="-6.2731853" soft_upper_limit="6.2731853"/>
  </joint>
  <link name="arm_right_5_link"/>
  <joint name="arm_right_6_joint" type="revolute">
    <origin rpy="1.5708 0 0" xyz="0 0 0.2986"/>
    <parent link="arm_right_5_link"/>
    <child link="arm_right_6_link"/>
    <axis xyz="0 0 1"/>
    <calibration rising="0.0"/>
    <dynamics damping="5"/>
    <limit effort="20.1" lower="-2.0943951" upper="2.0943951" velocity="2.0"/>
    <safety_controller k_position="20" k_velocity="25" soft_lower_limit="-2.0843951" soft_upper_limit="2.0843951"/>
  </joint>
  <link name="arm_right_6_link"/>
  <joint name="arm_right_7_joint" type="revolute">
    <origin rpy="-1.5708 0 0" xyz="0 0 0"/>
    <parent link="arm_right_6_link"/>
    <child link="arm_right_7_link"/>
    <axis xyz="0 0 1"/>
    <calibration rising="0.0"/>
    <dynamics damping="5"/>
    <limit effort="20.1" lower="-2.0943951" upper="2.0943951" velocity="2.0"/>
    <safety_controller k_position="20" k_velocity="25" soft_lower_limit="-2.0843951" soft_upper_limit="2.0843951"/>
  </joint>
  <link name="arm_right_7_link"/>
  <gazebo reference="arm_right_0_link">
    <material value="Schunk/LightGrey"/>
    <turnGravityOff>false</turnGravityOff>
    <selfCollide>true</selfCollide>
  </gazebo>
  <gazebo reference="arm_right_1_link">
    <material value="Schunk/Blue"/>
    <turnGravityOff>false</turnGravityOff>
    <selfCollide>true</selfCollide>
  </gazebo>
  <gazebo reference="arm_right_2_link">
    <material value="Schunk/LightGrey"/>
    <turnGravityOff>false</turnGravityOff>
    <selfCollide>true</selfCollide>
  </gazebo>
  <gazebo reference="arm_right_3_link">
    <material value="Schunk/Blue"/>
    <turnGravityOff>false</turnGravityOff>
    <selfCollide>true</selfCollide>
  </gazebo>
  <gazebo reference="arm_right_4_link">
    <material value="Schunk/LightGrey"/>
    <turnGravityOff>false</turnGravityOff>
    <selfCollide>true</selfCollide>
  </gazebo>
  <gazebo reference="arm_right_5_link">
    <material value="Schunk/Blue"/>
    <turnGravityOff>false</turnGravityOff>
    <selfCollide>true</selfCollide>
  </gazebo>
  <gazebo reference="arm_right_6_link">
    <material value="Schunk/LightGrey"/>
    <turnGravityOff>false</turnGravityOff>
    <selfCollide>true</selfCollide>
  </gazebo>
  <gazebo reference="arm_right_7_link">
    <material value="Schunk/LightGrey"/>
    <turnGravityOff>false</turnGravityOff>
    <selfCollide>true</selfCollide>
  </gazebo>
  <transmission name="arm_right_1_trans" type="pr2_mechanism_model/SimpleTransmission">
    <actuator name="arm_right_1_motor"/>
    <joint name="arm_right_1_joint"/>
    <mechanicalReduction>1</mechanicalReduction>
  </transmission>
  <transmission name="arm_right_2_trans" type="pr2_mechanism_model/SimpleTransmission">
    <actuator name="arm_right_2_motor"/>
    <joint name="arm_right_2_joint"/>
    <mechanicalReduction>1</mechanicalReduction>
  </transmission>
  <transmission name="arm_right_3_trans" type="pr2_mechanism_model/SimpleTransmission">
    <actuator name="arm_right_3_motor"/>
    <joint name="arm_right_3_joint"/>
    <mechanicalReduction>1</mechanicalReduction>
  </transmission>
  <transmission name="arm_right_4_trans" type="pr2_mechanism_model/SimpleTransmission">
    <actuator name="arm_right_4_motor"/>
    <joint name="arm_right_4_joint"/>
    <mechanicalReduction>1</mechanicalReduction>
  </transmission>
  <transmission name="arm_right_5_trans" type="pr2_mechanism_model/SimpleTransmission">
    <actuator name="arm_right_5_motor"/>
    <joint name="arm_right_5_joint"/>
    <mechanicalReduction>1</mechanicalReduction>
  </transmission>
  <transmission name="arm_right_6_trans" type="pr2_mechanism_model/SimpleTransmission">
    <actuator name="arm_right_6_motor"/>
    <joint name="arm_right_6_joint"/>
    <mechanicalReduction>1</mechanicalReduction>
  </transmission>
  <transmission name="arm_right_7_trans" type="pr2_mechanism_model/SimpleTransmission">
    <actuator name="arm_right_7_motor"/>
    <joint name="arm_right_7_joint"/>
    <mechanicalReduction>1</mechanicalReduction>
  </transmission>
  <joint name="arm_left_base_joint" type="fixed">
    <origin rpy="1.57097 0.0 3.14159" xyz="0.0 0.148 0.55"/>
    <parent link="torso_3_link"/>
    <child link="arm_left_base_link"/>
  </joint>
  <link name="arm_left_base_link"/>
  <joint name="arm_left_1_joint" type="revolute">
    <origin rpy="0 0 0" xyz="0 0 0"/>
    <parent link="arm_left_base_link"/>
    <child link="arm_left_1_link"/>
    <axis xyz="0 0 1"/>
    <calibration rising="0.0"/>
    <dynamics damping="10"/>
    <limit effort="370" lower="-6.2831853" upper="6.2831853" velocity="2.0"/>
    <safety_controller k_position="20" k_velocity="50" soft_lower_limit="-6.2731853" soft_upper_limit="6.2731853"/>
  </joint>
  <link name="arm_left_1_link"/>
  <joint name="arm_left_2_joint" type="revolute">
    <origin rpy="1.5708 0 0" xyz="0 0 0.0915"/>
    <parent link="arm_left_1_link"/>
    <child link="arm_left_2_link"/>
    <axis xyz="0 0 1"/>
    <calibration rising="0.0"/>
    <dynamics damping="10"/>
    <limit effort="370" lower="-2.0943951" upper="2.0943951" velocity="2.0"/>
    <safety_controller k_position="20" k_velocity="50" soft_lower_limit="-2.0843" soft_upper_limit="2.0843"/>
  </joint>
  <link name="arm_left_2_link"/>
  <joint name="arm_left_3_joint" type="revolute">
    <origin rpy="-1.5708 0 0" xyz="0 0 0"/>
    <parent link="arm_left_2_link"/>
    <child link="arm_left_3_link"/>
    <axis xyz="0 0 1"/>
    <calibration rising="0.0"/>
    <dynamics damping="5"/>
    <limit effort="176" lower="-6.2831853" upper="6.2831853" velocity="2.0"/>
    <safety_controller k_position="20" k_velocity="25" soft_lower_limit="-6.2731853" soft_upper_limit="6.2731853"/>
  </joint>
  <link name="arm_left_3_link"/>
  <joint name="arm_left_4_joint" type="revolute">
    <origin rpy="1.5708 0 0" xyz="0 0 0.45360"/>
    <parent link="arm_left_3_link"/>
    <child link="arm_left_4_link"/>
    <axis xyz="0 0 1"/>
    <calibration rising="0.0"/>
    <dynamics damping="5"/>
    <limit effort="176" lower="-2.0943951" upper="2.0943951" velocity="2.0"/>
    <safety_controller k_position="20" k_velocity="25" soft_lower_limit="-2.0843951" soft_upper_limit="2.0843951"/>
  </joint>
  <link name="arm_left_4_link"/>
  <joint name="arm_left_5_joint" type="revolute">
    <origin rpy="-1.5708 0 0" xyz="0 0 0"/>
    <parent link="arm_left_4_link"/>
    <child link="arm_left_5_link"/>
    <axis xyz="0 0 1"/>
    <calibration rising="0.0"/>
    <dynamics damping="5"/>
    <limit effort="41.6" lower="-6.2831853" upper="6.2831853" velocity="2.0"/>
    <safety_controller k_position="20" k_velocity="25" soft_lower_limit="-6.2731853" soft_upper_limit="6.2731853"/>
  </joint>
  <link name="arm_left_5_link"/>
  <joint name="arm_left_6_joint" type="revolute">
    <origin rpy="1.5708 0 0" xyz="0 0 0.2986"/>
    <parent link="arm_left_5_link"/>
    <child link="arm_left_6_link"/>
    <axis xyz="0 0 1"/>
    <calibration rising="0.0"/>
    <dynamics damping="5"/>
    <limit effort="20.1" lower="-2.0943951" upper="2.0943951" velocity="2.0"/>
    <safety_controller k_position="20" k_velocity="25" soft_lower_limit="-2.0843951" soft_upper_limit="2.0843951"/>
  </joint>
  <link name="arm_left_6_link"/>
  <joint name="arm_left_7_joint" type="revolute">
    <origin rpy="-1.5708 0 0" xyz="0 0 0"/>
    <parent link="arm_left_6_link"/>
    <child link="arm_left_7_link"/>
    <axis xyz="0 0 1"/>
    <calibration rising="0.0"/>
    <dynamics damping="5"/>
    <limit effort="20.1" lower="-2.0943951" upper="2.0943951" velocity="2.0"/>
    <safety_controller k_position="20" k_velocity="25" soft_lower_limit="-2.0843951" soft_upper_limit="2.0843951"/>
  </joint>
  <link name="arm_left_7_link"/>
  <gazebo reference="arm_left_0_link">
    <material value="Schunk/LightGrey"/>
    <turnGravityOff>false</turnGravityOff>
    <selfCollide>true</selfCollide>
  </gazebo>
  <gazebo reference="arm_left_1_link">
    <material value="Schunk/Blue"/>
    <turnGravityOff>false</turnGravityOff>
    <selfCollide>true</selfCollide>
  </gazebo>
  <gazebo reference="arm_left_2_link">
    <material value="Schunk/LightGrey"/>
    <turnGravityOff>false</turnGravityOff>
    <selfCollide>true</selfCollide>
  </gazebo>
  <gazebo reference="arm_left_3_link">
    <material value="Schunk/Blue"/>
    <turnGravityOff>false</turnGravityOff>
    <selfCollide>true</selfCollide>
  </gazebo>
  <gazebo reference="arm_left_4_link">
    <material value="Schunk/LightGrey"/>
    <turnGravityOff>false</turnGravityOff>
    <selfCollide>true</selfCollide>
  </gazebo>
  <gazebo reference="arm_left_5_link">
    <material value="Schunk/Blue"/>
    <turnGravityOff>false</turnGravityOff>
    <selfCollide>true</selfCollide>
  </gazebo>
  <gazebo reference="arm_left_6_link">
    <material value="Schunk/LightGrey"/>
    <turnGravityOff>false</turnGravityOff>
    <selfCollide>true</selfCollide>
  </gazebo>
  <gazebo reference="arm_left_7_link">
    <material value="Schunk/LightGrey"/>
    <turnGravityOff>false</turnGravityOff>
    <selfCollide>true</selfCollide>
  </gazebo>
  <transmission name="arm_left_1_trans" type="pr2_mechanism_model/SimpleTransmission">
    <actuator name="arm_left_1_motor"/>
    <joint name="arm_left_1_joint"/>
    <mechanicalReduction>1</mechanicalReduction>
  </transmission>
  <transmission name="arm_left_2_trans" type="pr2_mechanism_model/SimpleTransmission">
    <actuator name="arm_left_2_motor"/>
    <joint name="arm_left_2_joint"/>
    <mechanicalReduction>1</mechanicalReduction>
  </transmission>
  <transmission name="arm_left_3_trans" type="pr2_mechanism_model/SimpleTransmission">
    <actuator name="arm_left_3_motor"/>
    <joint name="arm_left_3_joint"/>
    <mechanicalReduction>1</mechanicalReduction>
  </transmission>
  <transmission name="arm_left_4_trans" type="pr2_mechanism_model/SimpleTransmission">
    <actuator name="arm_left_4_motor"/>
    <joint name="arm_left_4_joint"/>
    <mechanicalReduction>1</mechanicalReduction>
  </transmission>
  <transmission name="arm_left_5_trans" type="pr2_mechanism_model/SimpleTransmission">
    <actuator name="arm_left_5_motor"/>
    <joint name="arm_left_5_joint"/>
    <mechanicalReduction>1</mechanicalReduction>
  </transmission>
  <transmission name="arm_left_6_trans" type="pr2_mechanism_model/SimpleTransmission">
    <actuator name="arm_left_6_motor"/>
    <joint name="arm_left_6_joint"/>
    <mechanicalReduction>1</mechanicalReduction>
  </transmission>
  <transmission name="arm_left_7_trans" type="pr2_mechanism_model/SimpleTransmission">
    <actuator name="arm_left_7_motor"/>
    <joint name="arm_left_7_joint"/>
    <mechanicalReduction>1</mechanicalReduction>
  </transmission>
</robot>

