<?xml version="1.0" ?>
<!-- =================================================================================== -->
<!-- |    This document was autogenerated by xacro from cob3-6.urdf.xacro              | -->
<!-- |    EDITING THIS FILE BY HAND IS NOT RECOMMENDED                                 | -->
<!-- =================================================================================== -->
<robot name="cob3_4" xmlns:controller="http://playerstage.sourceforge.net/gazebo/xmlschema/#controller" xmlns:interface="http://playerstage.sourceforge.net/gazebo/xmlschema/#interface" xmlns:sensor="http://playerstage.sourceforge.net/gazebo/xmlschema/#sensor" xmlns:xacro="http://ros.org/wiki/xacro">
  <!-- common stuff -->
  <material name="Blue">
    <color rgba="0.0 0.0 0.8 1.0"/>
  </material>
  <material name="Green">
    <color rgba="0.0 0.8 0.0 1.0"/>
  </material>
  <material name="Grey">
    <color rgba="0.7 0.7 0.7 1.0"/>
  </material>
  <material name="Grey2">
    <color rgba="0.9 0.9 0.9 1.0"/>
  </material>
  <material name="Red">
    <color rgba="0.8 0.0 0.0 1.0"/>
  </material>
  <material name="White">
    <color rgba="1.0 1.0 1.0 1.0"/>
  </material>
  <material name="Black">
    <color rgba="0.0 0.0 0.0 1.0"/>
  </material>
  <material name="Caster">
    <texture filename="package://pr2_ogre/Media/materials/textures/pr2_caster_texture.png"/>
  </material>
  <material name="Wheel_l">
    <texture filename="package://pr2_ogre/Media/materials/textures/pr2_wheel_left.png"/>
  </material>
  <material name="Wheel_r">
    <texture filename="package://pr2_ogre/Media/materials/textures/pr2_wheel_right.png"/>
  </material>
  <material name="RollLinks">
    <texture filename="package://pr2_ogre/Media/materials/textures/pr2_wheel_left.png"/>
  </material>
  <!-- calibration -->
  <!-- base -->
  <!-- tray -->
  <!-- torso -->
  <!-- head -->
  <!-- arm -->
  <!-- sdh -->
  <!-- generic simulator_gazebo plugins for starting mechanism control, ros time, ros battery -->
  <gazebo>
    <controller:gazebo_ros_controller_manager name="gazebo_ros_controller_manager" plugin="libgazebo_ros_controller_manager.so">
      <alwaysOn>true</alwaysOn>
      <updateRate>1000.0</updateRate>
      <interface:audio name="gazebo_ros_controller_manager_dummy_iface"/>
    </controller:gazebo_ros_controller_manager>
    <controller:gazebo_ros_power_monitor name="gazebo_ros_power_monitor_controller" plugin="libgazebo_ros_power_monitor.so">
      <alwaysOn>true</alwaysOn>
      <updateRate>1.0</updateRate>
      <timeout>5</timeout>
      <interface:audio name="power_monitor_dummy_interface"/>
      <powerStateTopic>power_state</powerStateTopic>
      <powerStateRate>10.0</powerStateRate>
      <fullChargeCapacity>87.78</fullChargeCapacity>
      <dischargeRate>-474</dischargeRate>
      <chargeRate>525</chargeRate>
      <dischargeVoltage>15.52</dischargeVoltage>
      <chargeVoltage>16.41</chargeVoltage>
    </controller:gazebo_ros_power_monitor>
  </gazebo>
  <!-- composition of the robot -->
  <link name="base_link">
    <inertial>
      <mass value="116.0"/>
      <origin xyz="0 0 0"/>
      <inertia ixx="5.652232699207" ixy="-0.009719934438" ixz="1.293988226423" iyy="5.669473158652" iyz="-0.007379583694" izz="3.683196351726"/>
    </inertial>
    <visual>
      <origin rpy="0 0 0" xyz="0 0 0"/>
      <geometry>
        <mesh filename="package://cob_description/meshes/base/base.stl"/>
        <!--box size="${base_size_x} ${base_size_y} ${base_collision_size_z}" /-->
      </geometry>
      <material name="Grey"/>
    </visual>
    <collision>
      <origin rpy="0 0 0" xyz="0 0 0"/>
      <geometry>
        <!--box size="0.001 0.001 0.001" /-->
        <mesh filename="package://cob_description/meshes/base/base_collision.stlb"/>
        <!--box size="${base_size_x} ${base_size_y} ${base_collision_size_z}" /-->
      </geometry>
    </collision>
  </link>
  <link name="base_footprint">
    <inertial>
      <mass value="1.0"/>
      <origin xyz="0 0 0"/>
      <inertia ixx="0.01" ixy="0.0" ixz="0.0" iyy="0.01" iyz="0.0" izz="0.01"/>
    </inertial>
    <visual>
      <origin rpy="0 0 0" xyz="0 0 0"/>
      <geometry>
        <box size="0.01 0.01 0.01"/>
      </geometry>
      <material name="Red"/>
    </visual>
    <collision>
      <origin rpy="0 0 0" xyz="0 0 0.1"/>
      <geometry>
        <box size="0.001 0.001 0.001"/>
      </geometry>
    </collision>
  </link>
  <joint name="base_footprint_joint" type="fixed">
    <origin rpy="0 0 0" xyz="0 0 0"/>
    <child link="base_link"/>
    <parent link="base_footprint"/>
  </joint>
  <joint name="base_laser_front_joint" type="fixed">
    <axis xyz="0 1 0"/>
    <origin rpy="0 0 0" xyz="0.325 0.0 0.135"/>
    <parent link="base_link"/>
    <child link="base_laser_front_link"/>
  </joint>
  <link name="base_laser_front_link" type="laser">
    <inertial>
      <mass value="0.001"/>
      <origin rpy="0 0 0" xyz="0 0 0"/>
      <inertia ixx="0.0001" ixy="0" ixz="0" iyy="0.000001" iyz="0" izz="0.0001"/>
    </inertial>
    <visual>
      <origin rpy="0 0 0" xyz="0 0 0"/>
      <geometry>
        <box size="0.001 0.001 0.001"/>
      </geometry>
      <material name="Red"/>
    </visual>
    <collision>
      <origin rpy="0 0 0" xyz="0 0 0"/>
      <geometry>
        <box size=".001 .001 .001"/>
      </geometry>
    </collision>
  </link>
  <gazebo reference="base_laser_front_link">
    <sensor:ray name="base_laser_front">
      <rayCount>541</rayCount>
      <rangeCount>541</rangeCount>
      <laserCount>1</laserCount>
      <origin>0.0 0.0 0.0</origin>
      <displayRays>false</displayRays>
      <minAngle>-135.000315689</minAngle>
      <maxAngle>135.000315689</maxAngle>
      <minRange>0.05</minRange>
      <maxRange>30.0</maxRange>
      <resRange>0.03</resRange>
      <updateRate>10</updateRate>
      <controller:gazebo_ros_laser name="gazebo_ros_base_laser_front_controller" plugin="libgazebo_ros_laser.so">
        <gaussianNoise>0.005</gaussianNoise>
        <alwaysOn>true</alwaysOn>
        <updateRate>10</updateRate>
        <topicName>scan_front_raw</topicName>
        <frameName>/base_laser_front_link</frameName>
        <interface:laser name="gazebo_ros_base_laser_front_iface"/>
      </controller:gazebo_ros_laser>
    </sensor:ray>
  </gazebo>
  <joint name="base_laser_rear_joint" type="fixed">
    <axis xyz="0 1 0"/>
    <origin rpy="0 0 3.1415926" xyz="-0.325 0.0 0.135"/>
    <parent link="base_link"/>
    <child link="base_laser_rear_link"/>
  </joint>
  <link name="base_laser_rear_link" type="laser">
    <inertial>
      <mass value="0.001"/>
      <origin rpy="0 0 0" xyz="0 0 0"/>
      <inertia ixx="0.0001" ixy="0" ixz="0" iyy="0.000001" iyz="0" izz="0.0001"/>
    </inertial>
    <visual>
      <origin rpy="0 0 0" xyz="0 0 0"/>
      <geometry>
        <box size="0.001 0.001 0.001"/>
      </geometry>
      <material name="Red"/>
    </visual>
    <collision>
      <origin rpy="0 0 0" xyz="0 0 0"/>
      <geometry>
        <box size=".001 .001 .001"/>
      </geometry>
    </collision>
  </link>
  <gazebo reference="base_laser_rear_link">
    <sensor:ray name="base_laser_rear">
      <rayCount>541</rayCount>
      <rangeCount>541</rangeCount>
      <laserCount>1</laserCount>
      <origin>0.0 0.0 0.0</origin>
      <displayRays>false</displayRays>
      <minAngle>-135.000315689</minAngle>
      <maxAngle>135.000315689</maxAngle>
      <minRange>0.05</minRange>
      <maxRange>30.0</maxRange>
      <resRange>0.03</resRange>
      <updateRate>10</updateRate>
      <controller:gazebo_ros_laser name="gazebo_ros_base_laser_rear_controller" plugin="libgazebo_ros_laser.so">
        <gaussianNoise>0.005</gaussianNoise>
        <alwaysOn>true</alwaysOn>
        <updateRate>10</updateRate>
        <topicName>scan_rear_raw</topicName>
        <frameName>/base_laser_rear_link</frameName>
        <interface:laser name="gazebo_ros_base_laser_rear_iface"/>
      </controller:gazebo_ros_laser>
    </sensor:ray>
  </gazebo>
  <joint name="base_laser_top_joint" type="fixed">
    <axis xyz="0 1 0"/>
    <origin rpy="0 0 0" xyz="-0.252 0.0 0.42"/>
    <parent link="base_link"/>
    <child link="base_laser_top_link"/>
  </joint>
  <link name="base_laser_top_link" type="laser">
    <inertial>
      <mass value="0.001"/>
      <origin rpy="0 0 0" xyz="0 0 0"/>
      <inertia ixx="0.0001" ixy="0" ixz="0" iyy="0.000001" iyz="0" izz="0.0001"/>
    </inertial>
    <visual>
      <origin rpy="0 0 0" xyz="0 0 0"/>
      <geometry>
        <box size="0.001 0.001 0.001"/>
      </geometry>
      <material name="Red"/>
    </visual>
    <collision>
      <origin rpy="0 0 0" xyz="0 0 0"/>
      <geometry>
        <box size=".001 .001 .001"/>
      </geometry>
    </collision>
  </link>
  <gazebo reference="base_laser_top_link">
    <sensor:ray name="base_laser_top">
      <rayCount>640</rayCount>
      <rangeCount>640</rangeCount>
      <laserCount>1</laserCount>
      <origin>0.0 0.0 0.0</origin>
      <displayRays>false</displayRays>
      <minAngle>-135.000315689</minAngle>
      <maxAngle>135.000315689</maxAngle>
      <minRange>0.05</minRange>
      <maxRange>10.0</maxRange>
      <resRange>0.01</resRange>
      <updateRate>10</updateRate>
      <controller:gazebo_ros_laser name="gazebo_ros_base_laser_top_controller" plugin="libgazebo_ros_laser.so">
        <gaussianNoise>0.005</gaussianNoise>
        <alwaysOn>true</alwaysOn>
        <updateRate>10</updateRate>
        <topicName>scan_top</topicName>
        <frameName>/base_laser_top_link</frameName>
        <interface:laser name="gazebo_ros_base_laser_top_iface"/>
      </controller:gazebo_ros_laser>
    </sensor:ray>
  </gazebo>
  <joint name="fl_caster_rotation_joint" type="continuous">
    <axis xyz="0 0 1"/>
    <limit effort="100" velocity="100"/>
    <!-- alpha tested velocity and effort limits -->
    <safety_controller k_velocity="10"/>
    <calibration rising="-0.785398163397"/>
    <dynamics damping="0.0" friction="0.0"/>
    <origin rpy="0 0 0" xyz="0.235 0.185 0.075"/>
    <parent link="base_link"/>
    <child link="fl_caster_rotation_link"/>
  </joint>
  <link name="fl_caster_rotation_link">
    <inertial>
      <mass value="3.473082"/>
      <origin xyz="0 0 0.07"/>
      <inertia ixx="0.012411765597" ixy="-0.000711733678" ixz="0.00050272983" iyy="0.015218160428" iyz="-0.000004273467" izz="0.011763977943"/>
    </inertial>
    <visual>
      <!--origin xyz="0 0 0.085" rpy="0 0 0" /-->
      <!--modified by jie-->
      <origin rpy="0.0 0.0 0.0" xyz="0 0 0.002"/>
      <geometry>
        <!--mesh filename="package://cob_description/meshes/base/caster.stl" /-->
        <!--modified by jie-->
        <!--box size="0.192 0.164 0.013" /-->
        <box size="0.001 0.001 0.001"/>
      </geometry>
      <material name="Green"/>
    </visual>
    <collision>
      <origin rpy="0.0 0.0 0.0" xyz="0 0 0.002"/>
      <geometry>
        <box size="0.001 0.001 0.001"/>
      </geometry>
    </collision>
  </link>
  <transmission name="fl_caster_rotation_trans" type="pr2_mechanism_model/SimpleTransmission">
    <actuator name="fl_caster_rotation_motor"/>
    <joint name="fl_caster_rotation_joint"/>
    <mechanicalReduction>-79.2380952381</mechanicalReduction>
  </transmission>
  <joint name="fl_caster_r_wheel_joint" type="continuous">
    <axis xyz="0 1 0"/>
    <limit effort="100" velocity="100"/>
    <!-- alpha tested effort and velocity limits -->
    <safety_controller k_velocity="10"/>
    <dynamics damping="0.0" friction="0.0"/>
    <origin rpy="0 0 0" xyz="0 -0.0 0"/>
    <parent link="fl_caster_rotation_link"/>
    <child link="fl_caster_r_wheel_link"/>
  </joint>
  <link name="fl_caster_r_wheel_link">
    <inertial>
      <mass value="0.44036"/>
      <origin xyz="0 0 0"/>
      <inertia ixx="0.012411765597" ixy="-0.000711733678" ixz="0.00050272983" iyy="0.015218160428" iyz="-0.000004273467" izz="0.011763977943"/>
    </inertial>
    <visual>
      <origin rpy="1.57079632679 0 0" xyz="0 0 0"/>
      <geometry>
        <cylinder length="0.034" radius="0.074792"/>
      </geometry>
      <material name="Wheel_r"/>
    </visual>
    <collision>
      <origin rpy="1.57079632679 0 0" xyz="0 0 0"/>
      <!-- rotation because cyl. geom primitive has symmetry axis in +x direction -->
      <geometry>
        <cylinder length="0.034" radius="0.074792"/>
      </geometry>
    </collision>
  </link>
  <gazebo reference="fl_caster_r_wheel_link">
    <mu1 value="100.0"/>
    <mu2 value="100.0"/>
    <kp value="1000000.0"/>
    <kd value="1.0"/>
    <material value="PR2/wheel_r"/>
  </gazebo>
  <transmission name="fl_caster_r_wheel_trans" type="pr2_mechanism_model/SimpleTransmission">
    <actuator name="fl_caster_r_wheel_motor"/>
    <joint name="fl_caster_r_wheel_joint"/>
    <mechanicalReduction>-79.2380952381</mechanicalReduction>
  </transmission>
  <gazebo reference="fl_caster_rotation_link">
    <material value="PR2/caster_texture"/>
  </gazebo>
  <joint name="fr_caster_rotation_joint" type="continuous">
    <axis xyz="0 0 1"/>
    <limit effort="100" velocity="100"/>
    <!-- alpha tested velocity and effort limits -->
    <safety_controller k_velocity="10"/>
    <calibration rising="-0.785398163397"/>
    <dynamics damping="0.0" friction="0.0"/>
    <origin rpy="0 0 0" xyz="0.235 -0.185 0.075"/>
    <parent link="base_link"/>
    <child link="fr_caster_rotation_link"/>
  </joint>
  <link name="fr_caster_rotation_link">
    <inertial>
      <mass value="3.473082"/>
      <origin xyz="0 0 0.07"/>
      <inertia ixx="0.012411765597" ixy="-0.000711733678" ixz="0.00050272983" iyy="0.015218160428" iyz="-0.000004273467" izz="0.011763977943"/>
    </inertial>
    <visual>
      <!--origin xyz="0 0 0.085" rpy="0 0 0" /-->
      <!--modified by jie-->
      <origin rpy="0.0 0.0 0.0" xyz="0 0 0.002"/>
      <geometry>
        <!--mesh filename="package://cob_description/meshes/base/caster.stl" /-->
        <!--modified by jie-->
        <!--box size="0.192 0.164 0.013" /-->
        <box size="0.001 0.001 0.001"/>
      </geometry>
      <material name="Green"/>
    </visual>
    <collision>
      <origin rpy="0.0 0.0 0.0" xyz="0 0 0.002"/>
      <geometry>
        <box size="0.001 0.001 0.001"/>
      </geometry>
    </collision>
  </link>
  <transmission name="fr_caster_rotation_trans" type="pr2_mechanism_model/SimpleTransmission">
    <actuator name="fr_caster_rotation_motor"/>
    <joint name="fr_caster_rotation_joint"/>
    <mechanicalReduction>-79.2380952381</mechanicalReduction>
  </transmission>
  <joint name="fr_caster_r_wheel_joint" type="continuous">
    <axis xyz="0 1 0"/>
    <limit effort="100" velocity="100"/>
    <!-- alpha tested effort and velocity limits -->
    <safety_controller k_velocity="10"/>
    <dynamics damping="0.0" friction="0.0"/>
    <origin rpy="0 0 0" xyz="0 -0.0 0"/>
    <parent link="fr_caster_rotation_link"/>
    <child link="fr_caster_r_wheel_link"/>
  </joint>
  <link name="fr_caster_r_wheel_link">
    <inertial>
      <mass value="0.44036"/>
      <origin xyz="0 0 0"/>
      <inertia ixx="0.012411765597" ixy="-0.000711733678" ixz="0.00050272983" iyy="0.015218160428" iyz="-0.000004273467" izz="0.011763977943"/>
    </inertial>
    <visual>
      <origin rpy="1.57079632679 0 0" xyz="0 0 0"/>
      <geometry>
        <cylinder length="0.034" radius="0.074792"/>
      </geometry>
      <material name="Wheel_r"/>
    </visual>
    <collision>
      <origin rpy="1.57079632679 0 0" xyz="0 0 0"/>
      <!-- rotation because cyl. geom primitive has symmetry axis in +x direction -->
      <geometry>
        <cylinder length="0.034" radius="0.074792"/>
      </geometry>
    </collision>
  </link>
  <gazebo reference="fr_caster_r_wheel_link">
    <mu1 value="100.0"/>
    <mu2 value="100.0"/>
    <kp value="1000000.0"/>
    <kd value="1.0"/>
    <material value="PR2/wheel_r"/>
  </gazebo>
  <transmission name="fr_caster_r_wheel_trans" type="pr2_mechanism_model/SimpleTransmission">
    <actuator name="fr_caster_r_wheel_motor"/>
    <joint name="fr_caster_r_wheel_joint"/>
    <mechanicalReduction>-79.2380952381</mechanicalReduction>
  </transmission>
  <gazebo reference="fr_caster_rotation_link">
    <material value="PR2/caster_texture"/>
  </gazebo>
  <joint name="bl_caster_rotation_joint" type="continuous">
    <axis xyz="0 0 1"/>
    <limit effort="100" velocity="100"/>
    <!-- alpha tested velocity and effort limits -->
    <safety_controller k_velocity="10"/>
    <calibration rising="2.35619449019"/>
    <dynamics damping="0.0" friction="0.0"/>
    <origin rpy="0 0 0" xyz="-0.235 0.185 0.075"/>
    <parent link="base_link"/>
    <child link="bl_caster_rotation_link"/>
  </joint>
  <link name="bl_caster_rotation_link">
    <inertial>
      <mass value="3.473082"/>
      <origin xyz="0 0 0.07"/>
      <inertia ixx="0.012411765597" ixy="-0.000711733678" ixz="0.00050272983" iyy="0.015218160428" iyz="-0.000004273467" izz="0.011763977943"/>
    </inertial>
    <visual>
      <!--origin xyz="0 0 0.085" rpy="0 0 0" /-->
      <!--modified by jie-->
      <origin rpy="0.0 0.0 0.0" xyz="0 0 0.002"/>
      <geometry>
        <!--mesh filename="package://cob_description/meshes/base/caster.stl" /-->
        <!--modified by jie-->
        <!--box size="0.192 0.164 0.013" /-->
        <box size="0.001 0.001 0.001"/>
      </geometry>
      <material name="Green"/>
    </visual>
    <collision>
      <origin rpy="0.0 0.0 0.0" xyz="0 0 0.002"/>
      <geometry>
        <box size="0.001 0.001 0.001"/>
      </geometry>
    </collision>
  </link>
  <transmission name="bl_caster_rotation_trans" type="pr2_mechanism_model/SimpleTransmission">
    <actuator name="bl_caster_rotation_motor"/>
    <joint name="bl_caster_rotation_joint"/>
    <mechanicalReduction>-79.2380952381</mechanicalReduction>
  </transmission>
  <joint name="bl_caster_r_wheel_joint" type="continuous">
    <axis xyz="0 1 0"/>
    <limit effort="100" velocity="100"/>
    <!-- alpha tested effort and velocity limits -->
    <safety_controller k_velocity="10"/>
    <dynamics damping="0.0" friction="0.0"/>
    <origin rpy="0 0 0" xyz="0 -0.0 0"/>
    <parent link="bl_caster_rotation_link"/>
    <child link="bl_caster_r_wheel_link"/>
  </joint>
  <link name="bl_caster_r_wheel_link">
    <inertial>
      <mass value="0.44036"/>
      <origin xyz="0 0 0"/>
      <inertia ixx="0.012411765597" ixy="-0.000711733678" ixz="0.00050272983" iyy="0.015218160428" iyz="-0.000004273467" izz="0.011763977943"/>
    </inertial>
    <visual>
      <origin rpy="1.57079632679 0 0" xyz="0 0 0"/>
      <geometry>
        <cylinder length="0.034" radius="0.074792"/>
      </geometry>
      <material name="Wheel_r"/>
    </visual>
    <collision>
      <origin rpy="1.57079632679 0 0" xyz="0 0 0"/>
      <!-- rotation because cyl. geom primitive has symmetry axis in +x direction -->
      <geometry>
        <cylinder length="0.034" radius="0.074792"/>
      </geometry>
    </collision>
  </link>
  <gazebo reference="bl_caster_r_wheel_link">
    <mu1 value="100.0"/>
    <mu2 value="100.0"/>
    <kp value="1000000.0"/>
    <kd value="1.0"/>
    <material value="PR2/wheel_r"/>
  </gazebo>
  <transmission name="bl_caster_r_wheel_trans" type="pr2_mechanism_model/SimpleTransmission">
    <actuator name="bl_caster_r_wheel_motor"/>
    <joint name="bl_caster_r_wheel_joint"/>
    <mechanicalReduction>-79.2380952381</mechanicalReduction>
  </transmission>
  <gazebo reference="bl_caster_rotation_link">
    <material value="PR2/caster_texture"/>
  </gazebo>
  <joint name="br_caster_rotation_joint" type="continuous">
    <axis xyz="0 0 1"/>
    <limit effort="100" velocity="100"/>
    <!-- alpha tested velocity and effort limits -->
    <safety_controller k_velocity="10"/>
    <calibration rising="2.35619449019"/>
    <dynamics damping="0.0" friction="0.0"/>
    <origin rpy="0 0 0" xyz="-0.235 -0.185 0.075"/>
    <parent link="base_link"/>
    <child link="br_caster_rotation_link"/>
  </joint>
  <link name="br_caster_rotation_link">
    <inertial>
      <mass value="3.473082"/>
      <origin xyz="0 0 0.07"/>
      <inertia ixx="0.012411765597" ixy="-0.000711733678" ixz="0.00050272983" iyy="0.015218160428" iyz="-0.000004273467" izz="0.011763977943"/>
    </inertial>
    <visual>
      <!--origin xyz="0 0 0.085" rpy="0 0 0" /-->
      <!--modified by jie-->
      <origin rpy="0.0 0.0 0.0" xyz="0 0 0.002"/>
      <geometry>
        <!--mesh filename="package://cob_description/meshes/base/caster.stl" /-->
        <!--modified by jie-->
        <!--box size="0.192 0.164 0.013" /-->
        <box size="0.001 0.001 0.001"/>
      </geometry>
      <material name="Green"/>
    </visual>
    <collision>
      <origin rpy="0.0 0.0 0.0" xyz="0 0 0.002"/>
      <geometry>
        <box size="0.001 0.001 0.001"/>
      </geometry>
    </collision>
  </link>
  <transmission name="br_caster_rotation_trans" type="pr2_mechanism_model/SimpleTransmission">
    <actuator name="br_caster_rotation_motor"/>
    <joint name="br_caster_rotation_joint"/>
    <mechanicalReduction>-79.2380952381</mechanicalReduction>
  </transmission>
  <joint name="br_caster_r_wheel_joint" type="continuous">
    <axis xyz="0 1 0"/>
    <limit effort="100" velocity="100"/>
    <!-- alpha tested effort and velocity limits -->
    <safety_controller k_velocity="10"/>
    <dynamics damping="0.0" friction="0.0"/>
    <origin rpy="0 0 0" xyz="0 -0.0 0"/>
    <parent link="br_caster_rotation_link"/>
    <child link="br_caster_r_wheel_link"/>
  </joint>
  <link name="br_caster_r_wheel_link">
    <inertial>
      <mass value="0.44036"/>
      <origin xyz="0 0 0"/>
      <inertia ixx="0.012411765597" ixy="-0.000711733678" ixz="0.00050272983" iyy="0.015218160428" iyz="-0.000004273467" izz="0.011763977943"/>
    </inertial>
    <visual>
      <origin rpy="1.57079632679 0 0" xyz="0 0 0"/>
      <geometry>
        <cylinder length="0.034" radius="0.074792"/>
      </geometry>
      <material name="Wheel_r"/>
    </visual>
    <collision>
      <origin rpy="1.57079632679 0 0" xyz="0 0 0"/>
      <!-- rotation because cyl. geom primitive has symmetry axis in +x direction -->
      <geometry>
        <cylinder length="0.034" radius="0.074792"/>
      </geometry>
    </collision>
  </link>
  <gazebo reference="br_caster_r_wheel_link">
    <mu1 value="100.0"/>
    <mu2 value="100.0"/>
    <kp value="1000000.0"/>
    <kd value="1.0"/>
    <material value="PR2/wheel_r"/>
  </gazebo>
  <transmission name="br_caster_r_wheel_trans" type="pr2_mechanism_model/SimpleTransmission">
    <actuator name="br_caster_r_wheel_motor"/>
    <joint name="br_caster_r_wheel_joint"/>
    <mechanicalReduction>-79.2380952381</mechanicalReduction>
  </transmission>
  <gazebo reference="br_caster_rotation_link">
    <material value="PR2/caster_texture"/>
  </gazebo>
  <gazebo reference="base_link">
    <selfCollide>true</selfCollide>
    <sensor:contact name="base_contact_sensor">
      <geom>base_link_geom</geom>
      <updateRate>100.0</updateRate>
      <controller:gazebo_ros_bumper name="base_gazebo_ros_bumper_controller" plugin="libgazebo_ros_bumper.so">
        <alwaysOn>true</alwaysOn>
        <updateRate>100.0</updateRate>
        <bumperTopicName>base_bumper</bumperTopicName>
        <interface:bumper name="base_bumper_iface"/>
      </controller:gazebo_ros_bumper>
    </sensor:contact>
    <material>Gazebo/Grey</material>
  </gazebo>
  <gazebo>
    <controller:gazebo_ros_p3d name="p3d_base_controller" plugin="libgazebo_ros_p3d.so">
      <alwaysOn>true</alwaysOn>
      <updateRate>100.0</updateRate>
      <bodyName>base_link</bodyName>
      <topicName>base_pose_ground_truth</topicName>
      <gaussianNoise>0.01</gaussianNoise>
      <frameName>map</frameName>
      <xyzOffsets>25.7 25.7 0</xyzOffsets>
      <!-- initialize odometry for fake localization-->
      <rpyOffsets>0 0 0</rpyOffsets>
      <interface:position name="p3d_base_position"/>
    </controller:gazebo_ros_p3d>
    <canonicalBody>base_footprint</canonicalBody>
  </gazebo>
  <joint name="tray_joint" type="revolute">
    <origin rpy="2.3561 0 0" xyz="0.2406 0.19 0.732"/>
    <parent link="base_link"/>
    <child link="tray_link"/>
    <axis xyz="0 0 1"/>
    <calibration rising="-0.2"/>
    <dynamics damping="5.0" friction="0.5"/>
    <limit effort="100" lower="-3.31612" upper="0.2" velocity="5"/>
  </joint>
  <link name="tray_link">
    <inertial>
      <origin rpy="0 0 0" xyz="0 0 0"/>
      <mass value="0.1"/>
      <inertia ixx="0.01" ixy="0" ixz="0" iyy="0.01" iyz="0" izz="0.01"/>
    </inertial>
    <visual>
      <origin rpy="0 0 0" xyz="0 0 0"/>
      <geometry>
        <mesh filename="package://cob_description/meshes/tray/tray.stl"/>
      </geometry>
      <material name="Green"/>
    </visual>
    <collision>
      <origin rpy="0 0 0" xyz="0 0 0"/>
      <geometry>
        <mesh filename="package://cob_description/meshes/tray/tray_collision.stlb"/>
      </geometry>
    </collision>
  </link>
  <joint name="tray_base_joint" type="fixed">
    <origin rpy="-2.3561 0 0" xyz="0 0 0"/>
    <parent link="tray_link"/>
    <child link="tray_base_link"/>
  </joint>
  <link name="tray_base_link"/>
  <joint name="tray_right_joint" type="fixed">
    <origin rpy="0 0 0" xyz="0.4 -0.3 0.1"/>
    <parent link="tray_base_link"/>
    <child link="tray_right_link"/>
  </joint>
  <link name="tray_right_link"/>
  <joint name="tray_left_joint" type="fixed">
    <origin rpy="0 0 0" xyz="0.4 0.05 0.1"/>
    <parent link="tray_base_link"/>
    <child link="tray_left_link"/>
  </joint>
  <link name="tray_left_link"/>
  <gazebo reference="tray_link">
    <material>Gazebo/Green</material>
    <turnGravityOff>false</turnGravityOff>
  </gazebo>
  <transmission name="tray_trans" type="pr2_mechanism_model/SimpleTransmission">
    <actuator name="tray_motor"/>
    <joint name="tray_joint"/>
    <mechanicalReduction>1</mechanicalReduction>
  </transmission>
  <joint name="torso_lower_neck_tilt_joint" type="revolute">
    <origin rpy="1.5968312791 -0.0587251265 0.0660275925" xyz="0.1535525935 0.0 0.8743916288"/>
    <parent link="base_link"/>
    <child link="torso_lower_neck_tilt_link"/>
    <axis xyz="0 0 1"/>
    <dynamics damping="25.0" friction="10.0"/>
    <calibration rising="-0.24501037"/>
    <limit effort="41.4" lower="-6.2831" upper="6.2831" velocity="0.5"/>
  </joint>
  <link name="torso_lower_neck_tilt_link">
    <inertial>
      <origin rpy="0 0 0" xyz="0 0 0"/>
      <mass value="6.209720"/>
      <inertia ixx="0.171118" ixy="0.002544" ixz="-0.000000" iyy="0.083077" iyz="0.000000" izz="0.120948"/>
    </inertial>
    <visual>
      <origin rpy="3.14 0 0" xyz="0 0 0"/>
      <geometry>
        <mesh filename="package://cob_description/meshes/torso/lower_neck.stl"/>
      </geometry>
      <material name="Red"/>
    </visual>
    <collision>
      <origin rpy="3.14 0 0" xyz="0 0 0"/>
      <geometry>
        <mesh filename="package://cob_description/meshes/torso/lower_neck_collision.stlb"/>
      </geometry>
    </collision>
  </link>
  <joint name="torso_pan_joint" type="revolute">
    <origin rpy="1.5708 0 0" xyz="0 0 0"/>
    <parent link="torso_lower_neck_tilt_link"/>
    <child link="torso_pan_link"/>
    <axis xyz="0 0 1"/>
    <dynamics damping="25.0" friction="10.0"/>
    <calibration rising="-0.0146"/>
    <limit effort="41.4" lower="-6.2831" upper="6.2831" velocity="0.5"/>
  </joint>
  <link name="torso_pan_link">
    <inertial>
      <origin rpy="0 0 0" xyz="0 0 0"/>
      <mass value="1.0"/>
      <inertia ixx="0.200549" ixy="0.001322" ixz="-0.000000" iyy="0.123664" iyz="-0.000000" izz="0.104101"/>
    </inertial>
    <visual>
      <origin rpy="0 0 0" xyz="0 0 0.005"/>
      <geometry>
        <box size="0.01 0.01 0.01"/>
      </geometry>
      <material name="Blue"/>
    </visual>
    <collision>
      <origin rpy="0 0 0" xyz="0 0 0.0005"/>
      <geometry>
        <box size="0.001 0.001 0.001"/>
      </geometry>
    </collision>
  </link>
  <joint name="torso_upper_neck_tilt_joint" type="revolute">
    <origin rpy="-1.5708 0 0" xyz="0 0 -0.2565"/>
    <parent link="torso_pan_link"/>
    <child link="torso_upper_neck_tilt_link"/>
    <axis xyz="0 0 1"/>
    <dynamics damping="25.0" friction="10.0"/>
    <calibration rising="0.14419551"/>
    <limit effort="41.4" lower="-6.2831" upper="6.2831" velocity="0.5"/>
  </joint>
  <link name="torso_upper_neck_tilt_link">
    <inertial>
      <origin rpy="0 0 0" xyz="0 0 0"/>
      <mass value="6.744238"/>
      <inertia ixx="0.01" ixy="0" ixz="0" iyy="0.01" iyz="0" izz="0.01"/>
    </inertial>
    <visual>
      <origin rpy="3.1415926 0 0" xyz="0 0 0"/>
      <geometry>
        <mesh filename="package://cob_description/meshes/torso/upper_neck.stl"/>
      </geometry>
      <material name="Grey"/>
    </visual>
    <collision>
      <origin rpy="3.1415926 0 0" xyz="0 0 0"/>
      <geometry>
        <mesh filename="package://cob_description/meshes/torso/upper_neck_collision.stlb"/>
      </geometry>
    </collision>
  </link>
  <joint name="head_cover_joint" type="fixed">
    <origin rpy="3.1415926 0 0" xyz="0 0 0"/>
    <parent link="torso_upper_neck_tilt_link"/>
    <child link="head_cover_link"/>
  </joint>
  <link name="head_cover_link">
    <inertial>
      <origin rpy="0 0 0" xyz="0 0 0"/>
      <mass value="0.5"/>
      <inertia ixx="0.01" ixy="0" ixz="0" iyy="0.01" iyz="0" izz="0.01"/>
    </inertial>
    <visual>
      <origin rpy="0 0 0" xyz="0 0 0"/>
      <geometry>
        <mesh filename="package://cob_description/meshes/torso/head_cover.stl"/>
      </geometry>
      <material name="Blue"/>
    </visual>
    <collision>
      <origin rpy="0 0 0" xyz="0 0 0"/>
      <geometry>
        <mesh filename="package://cob_description/meshes/torso/head_cover_collision.stlb"/>
      </geometry>
    </collision>
  </link>
  <gazebo reference="torso_lower_neck_tilt_link">
    <material>Gazebo/Red</material>
    <turnGravityOff>false</turnGravityOff>
  </gazebo>
  <gazebo reference="torso_pan_link">
    <material>Gazebo/Blue</material>
    <turnGravityOff>false</turnGravityOff>
  </gazebo>
  <gazebo reference="torso_upper_neck_tilt_link">
    <material>Gazebo/Grey</material>
    <turnGravityOff>false</turnGravityOff>
  </gazebo>
  <gazebo reference="head_cover_link">
    <material>Gazebo/Blue</material>
    <turnGravityOff>false</turnGravityOff>
  </gazebo>
  <transmission name="torso_lower_neck_tilt_trans" type="pr2_mechanism_model/SimpleTransmission">
    <actuator name="torso_lower_neck_tilt_motor"/>
    <joint name="torso_lower_neck_tilt_joint"/>
    <mechanicalReduction>1</mechanicalReduction>
  </transmission>
  <transmission name="torso_pan_trans" type="pr2_mechanism_model/SimpleTransmission">
    <actuator name="torso_pan_motor"/>
    <joint name="torso_pan_joint"/>
    <mechanicalReduction>1</mechanicalReduction>
  </transmission>
  <transmission name="torso_upper_neck_tilt_trans" type="pr2_mechanism_model/SimpleTransmission">
    <actuator name="torso_upper_neck_tilt_motor"/>
    <joint name="torso_upper_neck_tilt_joint"/>
    <mechanicalReduction>1</mechanicalReduction>
  </transmission>
  <joint name="arm_0_joint" type="fixed">
    <origin rpy="0.8188441679 0.0073986966 -0.2545901695" xyz="-0.0135247781 -0.0461165405 0.8737003446"/>
    <parent link="base_link"/>
    <child link="arm_0_link"/>
  </joint>
  <link name="arm_0_link">
    <inertial>
      <origin rpy="0 0 0" xyz="0 0 0"/>
      <mass value="1.0"/>
      <inertia ixx="0.01" ixy="0" ixz="0" iyy="0.01" iyz="0" izz="0.01"/>
    </inertial>
    <visual>
      <origin rpy="0 0 0" xyz="0 0 0.004"/>
      <geometry>
        <cylinder length="0.08" radius="0.045"/>
      </geometry>
      <material name="Red"/>
    </visual>
    <collision>
      <origin rpy="0 0 0" xyz="0 0 0.005"/>
      <geometry>
        <box size="0.01 0.01 0.01"/>
      </geometry>
    </collision>
  </link>
  <joint name="arm_1_joint" type="revolute">
    <origin rpy="0 0 3.1415926" xyz="0 0 -0.250"/>
    <parent link="arm_0_link"/>
    <child link="arm_1_link"/>
    <axis xyz="0 0 1"/>
    <calibration rising="0.0"/>
    <dynamics damping="10"/>
    <limit effort="370" lower="-6.2831853" upper="6.2831853" velocity="2.0"/>
    <safety_controller k_position="20" k_velocity="50" soft_lower_limit="-6.2731853" soft_upper_limit="6.2731853"/>
  </joint>
  <link name="arm_1_link">
    <inertial>
      <origin rpy="0 0 0" xyz="0 0 0"/>
      <!--mass value="5.9907"/-->
      <mass value="2.0"/>
      <inertia ixx="0.01" ixy="0" ixz="0" iyy="0.01" iyz="0" izz="0.01"/>
    </inertial>
    <visual>
      <origin rpy="0 0 0" xyz="0 0 0"/>
      <geometry>
        <mesh filename="package://schunk_description/meshes/lwa/lwa1.stl"/>
      </geometry>
      <material name="Blue"/>
    </visual>
    <collision>
      <origin rpy="0 0 0" xyz="0 0 0"/>
      <geometry>
        <mesh filename="package://schunk_description/meshes/lwa/lwa1.stlb"/>
      </geometry>
    </collision>
  </link>
  <joint name="arm_2_joint" type="revolute">
    <origin rpy="1.5708 0 0" xyz="0 0 0"/>
    <parent link="arm_1_link"/>
    <child link="arm_2_link"/>
    <axis xyz="0 0 1"/>
    <calibration rising="0.0"/>
    <dynamics damping="10"/>
    <limit effort="370" lower="-2.0943951" upper="2.0943951" velocity="2.0"/>
    <safety_controller k_position="20" k_velocity="50" soft_lower_limit="-2.0843" soft_upper_limit="2.0843"/>
  </joint>
  <link name="arm_2_link">
    <inertial>
      <origin rpy="0 0 0" xyz="0 0 0"/>
      <!--mass value="5.734939"/-->
      <mass value="2.0"/>
      <inertia ixx="0.03" ixy="0" ixz="0" iyy="0.03" iyz="0" izz="0.03"/>
    </inertial>
    <visual>
      <origin rpy="0 0 0" xyz="0 0 0"/>
      <geometry>
        <mesh filename="package://schunk_description/meshes/lwa/lwa2.stl"/>
      </geometry>
      <material name="Red"/>
    </visual>
    <collision>
      <origin rpy="0 0 0" xyz="0 0 0"/>
      <geometry>
        <mesh filename="package://schunk_description/meshes/lwa/lwa2.stlb"/>
      </geometry>
    </collision>
  </link>
  <joint name="arm_3_joint" type="revolute">
    <origin rpy="-1.5708 0 0" xyz="0 -0.408 0"/>
    <parent link="arm_2_link"/>
    <child link="arm_3_link"/>
    <axis xyz="0 0 1"/>
    <calibration rising="0.0"/>
    <dynamics damping="5"/>
    <limit effort="176" lower="-6.2831853" upper="6.2831853" velocity="2.0"/>
    <safety_controller k_position="20" k_velocity="25" soft_lower_limit="-6.2731853" soft_upper_limit="6.2731853"/>
  </joint>
  <link name="arm_3_link">
    <inertial>
      <origin rpy="0 0 0" xyz="0 0 0"/>
      <!--mass value="4.214668"/-->
      <mass value="2.0"/>
      <inertia ixx="0.03" ixy="0" ixz="0" iyy="0.03" iyz="0" izz="0.03"/>
    </inertial>
    <visual>
      <origin rpy="0 0 0" xyz="0 0 0"/>
      <geometry>
        <mesh filename="package://schunk_description/meshes/lwa/lwa3.stl"/>
      </geometry>
      <material name="Blue"/>
    </visual>
    <collision>
      <origin rpy="0 0 0" xyz="0 0 0"/>
      <geometry>
        <mesh filename="package://schunk_description/meshes/lwa/lwa3.stlb"/>
      </geometry>
    </collision>
  </link>
  <joint name="arm_4_joint" type="revolute">
    <origin rpy="1.5708 0 0" xyz="0 0 0"/>
    <parent link="arm_3_link"/>
    <child link="arm_4_link"/>
    <axis xyz="0 0 1"/>
    <calibration rising="0.0"/>
    <dynamics damping="5"/>
    <limit effort="176" lower="-2.0943951" upper="2.0943951" velocity="2.0"/>
    <safety_controller k_position="20" k_velocity="25" soft_lower_limit="-2.0843951" soft_upper_limit="2.0843951"/>
  </joint>
  <link name="arm_4_link">
    <inertial>
      <origin rpy="0 0 0" xyz="0 0 0"/>
      <!--mass value="3.669819"/-->
      <mass value="2.0"/>
      <inertia ixx="0.03" ixy="0" ixz="0" iyy="0.03" iyz="0" izz="0.03"/>
    </inertial>
    <visual>
      <origin rpy="0 0 0" xyz="0 0 0"/>
      <geometry>
        <mesh filename="package://schunk_description/meshes/lwa/lwa4.stl"/>
      </geometry>
      <material name="Red"/>
    </visual>
    <collision>
      <origin rpy="0 0 0" xyz="0 0 0"/>
      <geometry>
        <mesh filename="package://schunk_description/meshes/lwa/lwa4.stlb"/>
      </geometry>
    </collision>
  </link>
  <joint name="arm_5_joint" type="revolute">
    <origin rpy="-1.5708 0 0" xyz="0 -0.3165 0"/>
    <parent link="arm_4_link"/>
    <child link="arm_5_link"/>
    <axis xyz="0 0 1"/>
    <calibration rising="0.0"/>
    <dynamics damping="5"/>
    <limit effort="41.6" lower="-6.2831853" upper="6.2831853" velocity="2.0"/>
    <safety_controller k_position="20" k_velocity="25" soft_lower_limit="-6.2731853" soft_upper_limit="6.2731853"/>
  </joint>
  <link name="arm_5_link">
    <inertial>
      <origin rpy="0 0 0" xyz="0 0 0"/>
      <mass value="2.313272"/>
      <inertia ixx="0.03" ixy="0" ixz="0" iyy="0.03" iyz="0" izz="0.03"/>
    </inertial>
    <visual>
      <origin rpy="0 0 0" xyz="0 0 0"/>
      <geometry>
        <mesh filename="package://schunk_description/meshes/lwa/lwa5.stl"/>
      </geometry>
      <material name="Blue"/>
    </visual>
    <collision>
      <origin rpy="0 0 0" xyz="0 0 0"/>
      <geometry>
        <mesh filename="package://schunk_description/meshes/lwa/lwa5.stlb"/>
      </geometry>
    </collision>
  </link>
  <joint name="arm_6_joint" type="revolute">
    <origin rpy="1.5708 0 0" xyz="0 0 0"/>
    <parent link="arm_5_link"/>
    <child link="arm_6_link"/>
    <axis xyz="0 0 1"/>
    <calibration rising="0.0"/>
    <dynamics damping="5"/>
    <limit effort="20.1" lower="-2.0943951" upper="2.0943951" velocity="2.0"/>
    <safety_controller k_position="20" k_velocity="25" soft_lower_limit="-2.0843951" soft_upper_limit="2.0843951"/>
  </joint>
  <link name="arm_6_link">
    <inertial>
      <origin rpy="0 0 0" xyz="0 0 0"/>
      <mass value="2.057856"/>
      <inertia ixx="0.01" ixy="0" ixz="0" iyy="0.01" iyz="0" izz="0.01"/>
    </inertial>
    <visual>
      <origin rpy="0 0 0" xyz="0 0 0"/>
      <geometry>
        <mesh filename="package://schunk_description/meshes/lwa/lwa6.stl"/>
      </geometry>
      <material name="Red"/>
    </visual>
    <collision>
      <origin rpy="0 0 0" xyz="0 0 0"/>
      <geometry>
        <mesh filename="package://schunk_description/meshes/lwa/lwa6.stlb"/>
      </geometry>
    </collision>
  </link>
  <joint name="arm_7_joint" type="revolute">
    <origin rpy="-1.5708 0 0" xyz="0 -0.1927 0"/>
    <parent link="arm_6_link"/>
    <child link="arm_7_link"/>
    <axis xyz="0 0 1"/>
    <calibration rising="0.0"/>
    <dynamics damping="5"/>
    <limit effort="9.6" lower="-6.2831853" upper="6.2831853" velocity="2.0"/>
    <safety_controller k_position="20" k_velocity="25" soft_lower_limit="-6.2731853" soft_upper_limit="6.2731853"/>
  </joint>
  <link name="arm_7_link">
    <inertial>
      <origin rpy="0 0 0" xyz="0 0 0"/>
      <mass value="1.120198"/>
      <inertia ixx="0.01" ixy="0" ixz="0" iyy="0.01" iyz="0" izz="0.01"/>
    </inertial>
    <visual>
      <origin rpy="0 0 0" xyz="0 0 0"/>
      <geometry>
        <mesh filename="package://schunk_description/meshes/lwa/lwa7.stl"/>
      </geometry>
      <material name="Blue"/>
    </visual>
    <collision>
      <origin rpy="0 0 0" xyz="0 0 0"/>
      <geometry>
        <mesh filename="package://schunk_description/meshes/lwa/lwa7.stlb"/>
      </geometry>
    </collision>
  </link>
  <gazebo reference="arm_0_link">
    <material value="PR2/Red"/>
    <turnGravityOff>false</turnGravityOff>
  </gazebo>
  <gazebo reference="arm_1_link">
    <material value="PR2/Blue"/>
    <turnGravityOff>false</turnGravityOff>
  </gazebo>
  <gazebo reference="arm_2_link">
    <material value="PR2/Red"/>
    <turnGravityOff>false</turnGravityOff>
  </gazebo>
  <gazebo reference="arm_3_link">
    <material value="PR2/Blue"/>
    <turnGravityOff>false</turnGravityOff>
  </gazebo>
  <gazebo reference="arm_4_link">
    <material value="PR2/Red"/>
    <turnGravityOff>false</turnGravityOff>
  </gazebo>
  <gazebo reference="arm_5_link">
    <material value="PR2/Blue"/>
    <turnGravityOff>false</turnGravityOff>
  </gazebo>
  <gazebo reference="arm_6_link">
    <material value="PR2/Red"/>
    <turnGravityOff>false</turnGravityOff>
  </gazebo>
  <gazebo reference="arm_7_link">
    <material value="PR2/Blue"/>
    <turnGravityOff>false</turnGravityOff>
  </gazebo>
  <transmission name="arm_1_trans" type="pr2_mechanism_model/SimpleTransmission">
    <actuator name="arm_1_motor"/>
    <joint name="arm_1_joint"/>
    <mechanicalReduction>1</mechanicalReduction>
  </transmission>
  <transmission name="arm_2_trans" type="pr2_mechanism_model/SimpleTransmission">
    <actuator name="arm_2_motor"/>
    <joint name="arm_2_joint"/>
    <mechanicalReduction>1</mechanicalReduction>
  </transmission>
  <transmission name="arm_3_trans" type="pr2_mechanism_model/SimpleTransmission">
    <actuator name="arm_3_motor"/>
    <joint name="arm_3_joint"/>
    <mechanicalReduction>1</mechanicalReduction>
  </transmission>
  <transmission name="arm_4_trans" type="pr2_mechanism_model/SimpleTransmission">
    <actuator name="arm_4_motor"/>
    <joint name="arm_4_joint"/>
    <mechanicalReduction>1</mechanicalReduction>
  </transmission>
  <transmission name="arm_5_trans" type="pr2_mechanism_model/SimpleTransmission">
    <actuator name="arm_5_motor"/>
    <joint name="arm_5_joint"/>
    <mechanicalReduction>1</mechanicalReduction>
  </transmission>
  <transmission name="arm_6_trans" type="pr2_mechanism_model/SimpleTransmission">
    <actuator name="arm_6_motor"/>
    <joint name="arm_6_joint"/>
    <mechanicalReduction>1</mechanicalReduction>
  </transmission>
  <transmission name="arm_7_trans" type="pr2_mechanism_model/SimpleTransmission">
    <actuator name="arm_7_motor"/>
    <joint name="arm_7_joint"/>
    <mechanicalReduction>1</mechanicalReduction>
  </transmission>
  <joint name="head_axis_joint" type="revolute">
    <origin rpy="0 0 0" xyz="0 0.173 0"/>
    <parent link="torso_upper_neck_tilt_link"/>
    <child link="head_axis_link"/>
    <axis xyz="0 0 1"/>
    <dynamics damping="0.1"/>
    <calibration rising="-0.1"/>
    <limit effort="100" lower="-3.2" upper="0.1" velocity="1.4"/>
  </joint>
  <link name="head_axis_link">
    <inertial>
      <origin rpy="0 0 0" xyz="0 0 0"/>
      <mass value="0.1"/>
      <inertia ixx="0.0001" ixy="0" ixz="0" iyy="0.0001" iyz="0" izz="0.0001"/>
    </inertial>
    <visual>
      <origin rpy="0 0 0" xyz="0 0 0"/>
      <geometry>
        <box size="0.01 0.01 0.01"/>
      </geometry>
      <material name="Green"/>
    </visual>
    <collision>
      <origin rpy="0 0 0" xyz="0 0 0"/>
      <geometry>
        <box size="0.01 0.01 0.01"/>
      </geometry>
    </collision>
  </link>
  <joint name="head_color_camera_l_joint" type="fixed">
    <origin rpy="0.8665791516 -1.5610273707 -0.9246703056" xyz="-0.0168918076 -0.0331605618 -0.1227576067"/>
    <parent link="head_axis_link"/>
    <child link="head_color_camera_l_link"/>
  </joint>
  <link name="head_color_camera_l_link">
    <inertial>
      <mass value="0.01"/>
      <origin rpy="0 0 0" xyz="0 0 0"/>
      <inertia ixx="0.0001" ixy="0" ixz="0" iyy="0.0001" iyz="0" izz="0.0001"/>
    </inertial>
    <visual>
      <origin rpy="0 0 0" xyz="0 0 0.015"/>
      <geometry>
        <cylinder length="0.075" radius="0.01"/>
      </geometry>
      <material name="Red"/>
    </visual>
    <collision>
      <origin rpy="0 0 0" xyz="0 0 0.015"/>
      <geometry>
        <cylinder length="0.075" radius="0.01"/>
      </geometry>
    </collision>
  </link>
  <joint name="head_color_camera_l_frame_joint" type="fixed">
    <origin rpy="1.5708 -1.5708 0" xyz="0 0 0"/>
    <parent link="head_color_camera_l_link"/>
    <child link="head_color_camera_l_frame"/>
  </joint>
  <link name="head_color_camera_l_frame">
    <inertial>
      <mass value="0.01"/>
      <origin rpy="0 0 0" xyz="0 0 0"/>
      <inertia ixx="0.0001" ixy="0" ixz="0" iyy="0.0001" iyz="0" izz="0.0001"/>
    </inertial>
    <visual>
      <origin rpy="0 0 0" xyz="0 0 0"/>
      <geometry>
        <box size="0.01 0.01 0.01"/>
      </geometry>
      <material name="Red"/>
    </visual>
    <collision>
      <origin rpy="0 0 0" xyz="0 0 0"/>
      <geometry>
        <box size="0.01 0.01 0.01"/>
      </geometry>
    </collision>
  </link>
  <gazebo reference="head_color_camera_l_frame">
    <sensor:camera name="head_color_camera_l_sensor">
      <!--geom>${name}_link</geom-->
      <imageFormat>R8G8B8</imageFormat>
      <imageSize>1338 1038</imageSize>
      <hfov>45</hfov>
      <nearClip>0.1</nearClip>
      <farClip>100</farClip>
      <updateRate>10.0</updateRate>
      <controller:gazebo_ros_prosilica name="head_color_camera_l_controller" plugin="libgazebo_ros_prosilica.so">
        <alwaysOn>true</alwaysOn>
        <updateRate>10.0</updateRate>
        <topicName>stereo/left_image_data</topicName>
        <imageTopicName>/stereo/left/image_raw</imageTopicName>
        <cameraInfoTopicName>/stereo/left/camera_info</cameraInfoTopicName>
        <pollServiceName>/head_color_camera_l/request_image</pollServiceName>
        <frameName>/head_color_camera_l_link</frameName>
        <CxPrime>697.69</CxPrime>
        <Cx>697.69</Cx>
        <Cy>530.51</Cy>
        <focal_length>1615</focal_length>
        <!-- image_width / (2*tan(hfov_radian /2)) -->
        <distortion_k1>0.00000001</distortion_k1>
        <distortion_k2>0.00000001</distortion_k2>
        <distortion_k3>0.00000001</distortion_k3>
        <distortion_t1>0.00000001</distortion_t1>
        <distortion_t2>0.00000001</distortion_t2>
        <interface:camera name="head_color_camera_l_iface"/>
      </controller:gazebo_ros_prosilica>
    </sensor:camera>
    <material value="Gazebo/Red"/>
    <turnGravityOff>true</turnGravityOff>
  </gazebo>
  <joint name="head_color_camera_r_joint" type="fixed">
    <origin rpy="0.00400056610075 0.0120185944721 0.0118234806514" xyz="0.120625576659 0.00069791469442 -0.000529628535957"/>
    <parent link="head_color_camera_l_link"/>
    <child link="head_color_camera_r_link"/>
  </joint>
  <link name="head_color_camera_r_link">
    <inertial>
      <mass value="0.01"/>
      <origin rpy="0 0 0" xyz="0 0 0"/>
      <inertia ixx="0.0001" ixy="0" ixz="0" iyy="0.0001" iyz="0" izz="0.0001"/>
    </inertial>
    <visual>
      <origin rpy="0 0 0" xyz="0 0 0.015"/>
      <geometry>
        <cylinder length="0.075" radius="0.01"/>
      </geometry>
      <material name="Red"/>
    </visual>
    <collision>
      <origin rpy="0 0 0" xyz="0 0 0.015"/>
      <geometry>
        <cylinder length="0.075" radius="0.01"/>
      </geometry>
    </collision>
  </link>
  <joint name="head_color_camera_r_frame_joint" type="fixed">
    <origin rpy="1.5708 -1.5708 0" xyz="0 0 0"/>
    <parent link="head_color_camera_r_link"/>
    <child link="head_color_camera_r_frame"/>
  </joint>
  <link name="head_color_camera_r_frame">
    <inertial>
      <mass value="0.01"/>
      <origin rpy="0 0 0" xyz="0 0 0"/>
      <inertia ixx="0.0001" ixy="0" ixz="0" iyy="0.0001" iyz="0" izz="0.0001"/>
    </inertial>
    <visual>
      <origin rpy="0 0 0" xyz="0 0 0"/>
      <geometry>
        <box size="0.01 0.01 0.01"/>
      </geometry>
      <material name="Red"/>
    </visual>
    <collision>
      <origin rpy="0 0 0" xyz="0 0 0"/>
      <geometry>
        <box size="0.01 0.01 0.01"/>
      </geometry>
    </collision>
  </link>
  <gazebo reference="head_color_camera_r_frame">
    <sensor:camera name="head_color_camera_r_sensor">
      <!--geom>${name}_link</geom-->
      <imageFormat>R8G8B8</imageFormat>
      <imageSize>1338 1038</imageSize>
      <hfov>45</hfov>
      <nearClip>0.1</nearClip>
      <farClip>100</farClip>
      <updateRate>10.0</updateRate>
      <controller:gazebo_ros_prosilica name="head_color_camera_r_controller" plugin="libgazebo_ros_prosilica.so">
        <alwaysOn>true</alwaysOn>
        <updateRate>10.0</updateRate>
        <topicName>stereo/right_image_data</topicName>
        <imageTopicName>/stereo/right/image_raw</imageTopicName>
        <cameraInfoTopicName>/stereo/right/camera_info</cameraInfoTopicName>
        <pollServiceName>/head_color_camera_r/request_image</pollServiceName>
        <frameName>/head_color_camera_r_link</frameName>
        <CxPrime>697.69</CxPrime>
        <Cx>697.69</Cx>
        <Cy>530.51</Cy>
        <focal_length>1615</focal_length>
        <!-- image_width / (2*tan(hfov_radian /2)) -->
        <distortion_k1>0.00000001</distortion_k1>
        <distortion_k2>0.00000001</distortion_k2>
        <distortion_k3>0.00000001</distortion_k3>
        <distortion_t1>0.00000001</distortion_t1>
        <distortion_t2>0.00000001</distortion_t2>
        <interface:camera name="head_color_camera_r_iface"/>
      </controller:gazebo_ros_prosilica>
    </sensor:camera>
    <material value="Gazebo/Red"/>
    <turnGravityOff>true</turnGravityOff>
  </gazebo>
  <joint name="head_cam3d_joint" type="fixed">
    <origin rpy="-0.0652253986 -1.5552469375 0.0523406338" xyz="-0.037555729 -0.0651598868 -0.0442883082"/>
    <parent link="head_axis_link"/>
    <child link="head_cam3d_link"/>
  </joint>
  <link name="head_cam3d_link">
    <inertial>
      <mass value="0.01"/>
      <origin rpy="0 0 0" xyz="0 0 0"/>
      <inertia ixx="0.0001" ixy="0" ixz="0" iyy="0.0001" iyz="0" izz="0.0001"/>
    </inertial>
    <visual>
      <origin rpy="0 0 0" xyz="0 0 0.015"/>
      <geometry>
        <box size="0.02 0.02 0.075"/>
      </geometry>
      <material name="Red"/>
    </visual>
    <collision>
      <origin rpy="0 0 0" xyz="0 0 0.015"/>
      <geometry>
        <box size="0.02 0.02 0.075"/>
      </geometry>
    </collision>
  </link>
  <joint name="head_cam3d_frame_joint" type="fixed">
    <origin rpy="1.5708 -1.5708 0" xyz="0 0 0"/>
    <parent link="head_cam3d_link"/>
    <child link="head_cam3d_frame"/>
  </joint>
  <link name="head_cam3d_frame">
    <inertial>
      <mass value="0.01"/>
      <origin rpy="0 0 0" xyz="0 0 0"/>
      <inertia ixx="0.0001" ixy="0" ixz="0" iyy="0.0001" iyz="0" izz="0.0001"/>
    </inertial>
    <visual>
      <origin rpy="0 0 0" xyz="0 0 0"/>
      <geometry>
        <box size="0.01 0.01 0.01"/>
      </geometry>
      <material name="Red"/>
    </visual>
    <collision>
      <origin rpy="0 0 0" xyz="0 0 0"/>
      <geometry>
        <box size="0.01 0.01 0.01"/>
      </geometry>
    </collision>
  </link>
  <gazebo reference="head_cam3d_frame">
    <sensor:camera name="head_cam3d_frame_sensor">
      <imageFormat>R8G8B8</imageFormat>
      <imageSize>640 480</imageSize>
      <hfov>57</hfov>
      <nearClip>0.1</nearClip>
      <farClip>5</farClip>
      <updateRate>20.0</updateRate>
      <baseline>0.2</baseline>
      <controller:gazebo_ros_camera name="head_cam3d_frame_controller" plugin="libgazebo_ros_camera.so">
        <alwaysOn>true</alwaysOn>
        <updateRate>20.0</updateRate>
        <imageTopicName>cam3d/rgb/image_raw</imageTopicName>
        <pointCloudTopicName>cam3d/depth/points</pointCloudTopicName>
        <cameraInfoTopicName>cam3d/camera_info</cameraInfoTopicName>
        <frameName>/head_cam3d_link</frameName>
        <pointCloudCutoff>0.5</pointCloudCutoff>
        <distortion_k1>0.00000001</distortion_k1>
        <distortion_k2>0.00000001</distortion_k2>
        <distortion_k3>0.00000001</distortion_k3>
        <distortion_t1>0.00000001</distortion_t1>
        <distortion_t2>0.00000001</distortion_t2>
      </controller:gazebo_ros_camera>
    </sensor:camera>
  </gazebo>
  <gazebo reference="head_axis_link">
    <material>Gazebo/Green</material>
    <turnGravityOff>false</turnGravityOff>
  </gazebo>
  <transmission name="head_axis_trans" type="pr2_mechanism_model/SimpleTransmission">
    <actuator name="head_axis_motor"/>
    <joint name="head_axis_joint"/>
    <mechanicalReduction>1</mechanicalReduction>
  </transmission>
  <joint name="sdh_palm_joint" type="fixed">
    <origin rpy="0 0 1.5708" xyz="0 0 0.032"/>
    <parent link="arm_7_link"/>
    <child link="sdh_palm_link"/>
  </joint>
  <link name="sdh_palm_link">
    <inertial>
      <origin rpy="0 0 0" xyz="0 0 0"/>
      <mass value="1"/>
      <inertia ixx="0.01" ixy="0" ixz="0" iyy="0.01" iyz="0" izz="0.01"/>
    </inertial>
    <visual>
      <origin rpy="0 0 0" xyz="0 0 0"/>
      <geometry>
        <mesh filename="package://schunk_description/meshes/sdh/palm.stl"/>
      </geometry>
      <material name="Grey"/>
    </visual>
    <collision>
      <origin rpy="0 0 0" xyz="0 0 0"/>
      <geometry>
        <mesh filename="package://schunk_description/meshes/sdh/palm.stlb"/>
      </geometry>
    </collision>
  </link>
  <joint name="sdh_grasp_joint" type="fixed">
    <origin rpy="0 0 0" xyz="0 0 0.15"/>
    <parent link="sdh_palm_link"/>
    <child link="sdh_grasp_link"/>
  </joint>
  <link name="sdh_grasp_link"/>
  <joint name="sdh_tip_joint" type="fixed">
    <origin rpy="0 0 0" xyz="0 0 0.22"/>
    <parent link="sdh_palm_link"/>
    <child link="sdh_tip_link"/>
  </joint>
  <link name="sdh_tip_link"/>
  <joint name="sdh_knuckle_joint" type="revolute">
    <origin rpy="0 0 3.14159265" xyz="0.01905 0.033 0.0745"/>
    <parent link="sdh_palm_link"/>
    <child link="sdh_finger_11_link"/>
    <axis xyz="0 0 1"/>
    <dynamics damping="1"/>
    <limit effort="100" lower="0" upper="1.570796327" velocity="5"/>
  </joint>
  <link name="sdh_finger_11_link">
    <inertial>
      <origin rpy="0 0 0" xyz="0 0 0"/>
      <mass value="0.1"/>
      <inertia ixx="0.01" ixy="0" ixz="0" iyy="0.01" iyz="0" izz="0.01"/>
    </inertial>
    <visual>
      <origin rpy="0 0 0" xyz="0 0 0"/>
      <geometry>
        <mesh filename="package://schunk_description/meshes/sdh/knuckle.stl"/>
      </geometry>
      <material name="Black"/>
    </visual>
    <collision>
      <origin rpy="0 0 0" xyz="0 0 0"/>
      <geometry>
        <mesh filename="package://schunk_description/meshes/sdh/knuckle.stlb"/>
      </geometry>
    </collision>
  </link>
  <joint name="sdh_finger_12_joint" type="revolute">
    <origin rpy="0 0 0" xyz="0 0 0.0165"/>
    <parent link="sdh_finger_11_link"/>
    <child link="sdh_finger_12_link"/>
    <axis xyz="0 1 0"/>
    <dynamics damping="1"/>
    <limit effort="100" lower="-1.570796327" upper="1.570796327" velocity="5"/>
  </joint>
  <link name="sdh_finger_12_link">
    <inertial>
      <origin rpy="0 0 0" xyz="0 0 0"/>
      <mass value="0.1"/>
      <inertia ixx="0.01" ixy="0" ixz="0" iyy="0.01" iyz="0" izz="0.01"/>
    </inertial>
    <visual>
      <origin rpy="0 0 0" xyz="0 0 0"/>
      <geometry>
        <mesh filename="package://schunk_description/meshes/sdh/finger.stl"/>
      </geometry>
      <material name="Red"/>
    </visual>
    <collision>
      <origin rpy="0 0 0" xyz="0 0 0"/>
      <geometry>
        <mesh filename="package://schunk_description/meshes/sdh/finger.stlb"/>
      </geometry>
    </collision>
  </link>
  <joint name="sdh_finger_13_joint" type="revolute">
    <origin rpy="0 0 0" xyz="0 0 0.0865"/>
    <parent link="sdh_finger_12_link"/>
    <child link="sdh_finger_13_link"/>
    <axis xyz="0 1 0"/>
    <dynamics damping="1"/>
    <limit effort="100" lower="-1.570796327" upper="1.570796327" velocity="5"/>
  </joint>
  <link name="sdh_finger_13_link">
    <inertial>
      <origin rpy="0 0 0" xyz="0 0 0"/>
      <mass value="0.1"/>
      <inertia ixx="0.01" ixy="0" ixz="0" iyy="0.01" iyz="0" izz="0.01"/>
    </inertial>
    <visual>
      <origin rpy="0 0 0" xyz="0 0 0"/>
      <geometry>
        <mesh filename="package://schunk_description/meshes/sdh/finger_tip.stl"/>
      </geometry>
      <material name="Blue"/>
    </visual>
    <collision>
      <origin rpy="0 0 0" xyz="0 0 0"/>
      <geometry>
        <mesh filename="package://schunk_description/meshes/sdh/finger_tip.stlb"/>
      </geometry>
    </collision>
  </link>
  <joint name="sdh_finger_21_joint" type="revolute">
    <mimic joint="sdh_knuckle_joint" multiplier="1" offset="0"/>
    <origin rpy="0 0 3.14159265" xyz="0.01905 -0.033 0.0745"/>
    <parent link="sdh_palm_link"/>
    <child link="sdh_finger_21_link"/>
    <axis xyz="0 0 -1"/>
    <dynamics damping="1"/>
    <limit effort="100" lower="0" upper="1.570796327" velocity="5"/>
  </joint>
  <link name="sdh_finger_21_link">
    <inertial>
      <origin rpy="0 0 0" xyz="0 0 0"/>
      <mass value="0.1"/>
      <inertia ixx="0.01" ixy="0" ixz="0" iyy="0.01" iyz="0" izz="0.01"/>
    </inertial>
    <visual>
      <origin rpy="0 0 0" xyz="0 0 0"/>
      <geometry>
        <mesh filename="package://schunk_description/meshes/sdh/knuckle.stl"/>
      </geometry>
      <material name="Black"/>
    </visual>
    <collision>
      <origin rpy="0 0 0" xyz="0 0 0"/>
      <geometry>
        <mesh filename="package://schunk_description/meshes/sdh/knuckle.stlb"/>
      </geometry>
    </collision>
  </link>
  <joint name="sdh_finger_22_joint" type="revolute">
    <origin rpy="0 0 0" xyz="0 0 0.0165"/>
    <parent link="sdh_finger_21_link"/>
    <child link="sdh_finger_22_link"/>
    <axis xyz="0 1 0"/>
    <dynamics damping="1"/>
    <limit effort="100" lower="-1.570796327" upper="1.570796327" velocity="5"/>
  </joint>
  <link name="sdh_finger_22_link">
    <inertial>
      <origin rpy="0 0 0" xyz="0 0 0"/>
      <mass value="0.1"/>
      <inertia ixx="0.01" ixy="0" ixz="0" iyy="0.01" iyz="0" izz="0.01"/>
    </inertial>
    <visual>
      <origin rpy="0 0 0" xyz="0 0 0"/>
      <geometry>
        <mesh filename="package://schunk_description/meshes/sdh/finger.stl"/>
      </geometry>
      <material name="Red"/>
    </visual>
    <collision>
      <origin rpy="0 0 0" xyz="0 0 0"/>
      <geometry>
        <mesh filename="package://schunk_description/meshes/sdh/finger.stlb"/>
      </geometry>
    </collision>
  </link>
  <joint name="sdh_finger_23_joint" type="revolute">
    <origin rpy="0 0 0" xyz="0 0 0.0865"/>
    <parent link="sdh_finger_22_link"/>
    <child link="sdh_finger_23_link"/>
    <axis xyz="0 1 0"/>
    <dynamics damping="1"/>
    <limit effort="100" lower="-1.570796327" upper="1.570796327" velocity="5"/>
  </joint>
  <link name="sdh_finger_23_link">
    <inertial>
      <origin rpy="0 0 0" xyz="0 0 0"/>
      <mass value="0.1"/>
      <inertia ixx="0.01" ixy="0" ixz="0" iyy="0.01" iyz="0" izz="0.01"/>
    </inertial>
    <visual>
      <origin rpy="0 0 0" xyz="0 0 0"/>
      <geometry>
        <mesh filename="package://schunk_description/meshes/sdh/finger_tip.stl"/>
      </geometry>
      <material name="Blue"/>
    </visual>
    <collision>
      <origin rpy="0 0 0" xyz="0 0 0"/>
      <geometry>
        <mesh filename="package://schunk_description/meshes/sdh/finger_tip.stlb"/>
      </geometry>
    </collision>
  </link>
  <joint name="sdh_thumb_1_joint" type="fixed">
    <origin rpy="0 0 0" xyz="-0.03811 0 0.0745 "/>
    <parent link="sdh_palm_link"/>
    <child link="sdh_thumb_1_link"/>
  </joint>
  <link name="sdh_thumb_1_link">
    <inertial>
      <origin rpy="0 0 0" xyz="0 0 0"/>
      <mass value="0.1"/>
      <inertia ixx="0.01" ixy="0" ixz="0" iyy="0.01" iyz="0" izz="0.01"/>
    </inertial>
    <visual>
      <origin rpy="0 0 0" xyz="0 0 0"/>
      <geometry>
        <mesh filename="package://schunk_description/meshes/sdh/knuckle.stl"/>
      </geometry>
      <material name="Black"/>
    </visual>
    <collision>
      <origin rpy="0 0 0" xyz="0 0 0"/>
      <geometry>
        <mesh filename="package://schunk_description/meshes/sdh/knuckle.stlb"/>
      </geometry>
    </collision>
  </link>
  <joint name="sdh_thumb_2_joint" type="revolute">
    <origin rpy="0 0 0" xyz="0 0 0.0165"/>
    <parent link="sdh_thumb_1_link"/>
    <child link="sdh_thumb_2_link"/>
    <axis xyz="0 1 0"/>
    <dynamics damping="1"/>
    <limit effort="100" lower="-1.570796327" upper="1.570796327" velocity="5"/>
  </joint>
  <link name="sdh_thumb_2_link">
    <inertial>
      <origin rpy="0 0 0" xyz="0 0 0"/>
      <mass value="0.1"/>
      <inertia ixx="0.01" ixy="0" ixz="0" iyy="0.01" iyz="0" izz="0.01"/>
    </inertial>
    <visual>
      <origin rpy="0 0 0" xyz="0 0 0"/>
      <geometry>
        <mesh filename="package://schunk_description/meshes/sdh/finger.stl"/>
      </geometry>
      <material name="Red"/>
    </visual>
    <collision>
      <origin rpy="0 0 0" xyz="0 0 0"/>
      <geometry>
        <mesh filename="package://schunk_description/meshes/sdh/finger.stlb"/>
      </geometry>
    </collision>
  </link>
  <joint name="sdh_thumb_3_joint" type="revolute">
    <origin rpy="0 0 0" xyz="0 0 0.0865"/>
    <parent link="sdh_thumb_2_link"/>
    <child link="sdh_thumb_3_link"/>
    <axis xyz="0 1 0"/>
    <dynamics damping="1"/>
    <limit effort="100" lower="-1.570796327" upper="1.570796327" velocity="5"/>
  </joint>
  <link name="sdh_thumb_3_link">
    <inertial>
      <origin rpy="0 0 0" xyz="0 0 0"/>
      <mass value="0.1"/>
      <inertia ixx="0.01" ixy="0" ixz="0" iyy="0.01" iyz="0" izz="0.01"/>
    </inertial>
    <visual>
      <origin rpy="0 0 0" xyz="0 0 0"/>
      <geometry>
        <mesh filename="package://schunk_description/meshes/sdh/finger_tip.stl"/>
      </geometry>
      <material name="Blue"/>
    </visual>
    <collision>
      <origin rpy="0 0 0" xyz="0 0 0"/>
      <geometry>
        <mesh filename="package://schunk_description/meshes/sdh/finger_tip.stlb"/>
      </geometry>
    </collision>
  </link>
  <gazebo reference="sdh_palm_link">
    <material>Gazebo/Grey</material>
    <turnGravityOff>false</turnGravityOff>
  </gazebo>
  <gazebo reference="sdh_finger_11_link">
    <material>Gazebo/Black</material>
    <turnGravityOff>false</turnGravityOff>
  </gazebo>
  <gazebo reference="sdh_finger_12_link">
    <selfCollide>true</selfCollide>
    <sensor:contact name="sdh_finger_12_contact_sensor">
      <geom>sdh_finger_12_link_geom</geom>
      <updateRate>100.0</updateRate>
      <controller:gazebo_ros_bumper name="sdh_finger_12_gazebo_ros_bumper_controller" plugin="libgazebo_ros_bumper.so">
        <alwaysOn>true</alwaysOn>
        <updateRate>100.0</updateRate>
        <frameName>sdh_finger_12_link</frameName>
        <bumperTopicName>sdh_finger_12_bumper</bumperTopicName>
        <interface:bumper name="sdh_finger_12_bumper_iface"/>
      </controller:gazebo_ros_bumper>
    </sensor:contact>
    <material>Gazebo/Red</material>
    <turnGravityOff>false</turnGravityOff>
  </gazebo>
  <gazebo reference="sdh_finger_13_link">
    <selfCollide>true</selfCollide>
    <sensor:contact name="sdh_finger_13_contact_sensor">
      <geom>sdh_finger_13_link_geom</geom>
      <updateRate>100.0</updateRate>
      <controller:gazebo_ros_bumper name="sdh_finger_13_gazebo_ros_bumper_controller" plugin="libgazebo_ros_bumper.so">
        <alwaysOn>true</alwaysOn>
        <updateRate>100.0</updateRate>
        <frameName>sdh_finger_13_link</frameName>
        <bumperTopicName>sdh_finger_13_bumper</bumperTopicName>
        <interface:bumper name="sdh_finger_13_bumper_iface"/>
      </controller:gazebo_ros_bumper>
    </sensor:contact>
    <material>Gazebo/Blue</material>
  </gazebo>
  <gazebo reference="sdh_finger_21_link">
    <material>Gazebo/Black</material>
    <turnGravityOff>false</turnGravityOff>
  </gazebo>
  <gazebo reference="sdh_finger_22_link">
    <selfCollide>true</selfCollide>
    <sensor:contact name="sdh_finger_22_contact_sensor">
      <geom>sdh_finger_22_link_geom</geom>
      <updateRate>100.0</updateRate>
      <controller:gazebo_ros_bumper name="sdh_finger_22_gazebo_ros_bumper_controller" plugin="libgazebo_ros_bumper.so">
        <alwaysOn>true</alwaysOn>
        <updateRate>100.0</updateRate>
        <frameName>sdh_finger_22_link</frameName>
        <bumperTopicName>sdh_finger_22_bumper</bumperTopicName>
        <interface:bumper name="sdh_finger_22_bumper_iface"/>
      </controller:gazebo_ros_bumper>
    </sensor:contact>
    <material>Gazebo/Red</material>
    <turnGravityOff>false</turnGravityOff>
  </gazebo>
  <gazebo reference="sdh_finger_23_link">
    <selfCollide>true</selfCollide>
    <sensor:contact name="sdh_finger_23_contact_sensor">
      <geom>sdh_finger_23_link_geom</geom>
      <updateRate>100.0</updateRate>
      <controller:gazebo_ros_bumper name="sdh_finger_23_gazebo_ros_bumper_controller" plugin="libgazebo_ros_bumper.so">
        <alwaysOn>true</alwaysOn>
        <updateRate>100.0</updateRate>
        <frameName>sdh_finger_23_link</frameName>
        <bumperTopicName>sdh_finger_23_bumper</bumperTopicName>
        <interface:bumper name="sdh_finger_23_bumper_iface"/>
      </controller:gazebo_ros_bumper>
    </sensor:contact>
    <material>Gazebo/Blue</material>
  </gazebo>
  <gazebo reference="sdh_thumb_1_link">
    <material>Gazebo/Black</material>
    <turnGravityOff>false</turnGravityOff>
  </gazebo>
  <gazebo reference="sdh_thumb_2_link">
    <selfCollide>true</selfCollide>
    <sensor:contact name="sdh_thumb_2_contact_sensor">
      <geom>sdh_thumb_2_link_geom</geom>
      <updateRate>100.0</updateRate>
      <controller:gazebo_ros_bumper name="sdh_thumb_2_gazebo_ros_bumper_controller" plugin="libgazebo_ros_bumper.so">
        <alwaysOn>true</alwaysOn>
        <updateRate>100.0</updateRate>
        <frameName>sdh_thumb_2_link</frameName>
        <bumperTopicName>sdh_thumb_2_bumper</bumperTopicName>
        <interface:bumper name="sdh_thumb_2_bumper_iface"/>
      </controller:gazebo_ros_bumper>
    </sensor:contact>
    <material>Gazebo/Red</material>
    <turnGravityOff>false</turnGravityOff>
  </gazebo>
  <gazebo reference="sdh_thumb_3_link">
    <selfCollide>true</selfCollide>
    <sensor:contact name="sdh_thumb_3_contact_sensor">
      <geom>sdh_thumb_3_link_geom</geom>
      <updateRate>100.0</updateRate>
      <controller:gazebo_ros_bumper name="sdh_thumb_3_gazebo_ros_bumper_controller" plugin="libgazebo_ros_bumper.so">
        <alwaysOn>true</alwaysOn>
        <updateRate>100.0</updateRate>
        <frameName>sdh_thumb_3_link</frameName>
        <bumperTopicName>sdh_thumb_3_bumper</bumperTopicName>
        <interface:bumper name="sdh_thumb_3_bumper_iface"/>
      </controller:gazebo_ros_bumper>
    </sensor:contact>
    <material>Gazebo/Blue</material>
  </gazebo>
  <transmission name="sdh_knuckle_trans" type="pr2_mechanism_model/SimpleTransmission">
    <actuator name="sdh_knuckle_motor"/>
    <joint name="sdh_finger_21_joint"/>
    <mechanicalReduction>1</mechanicalReduction>
  </transmission>
  <transmission name="sdh_knuckle_trans" type="pr2_mechanism_model/SimpleTransmission">
    <actuator name="sdh_knuckle_motor"/>
    <joint name="sdh_knuckle_joint"/>
    <mechanicalReduction>1</mechanicalReduction>
  </transmission>
  <transmission name="sdh_finger_12_trans" type="pr2_mechanism_model/SimpleTransmission">
    <actuator name="sdh_finger_12_motor"/>
    <joint name="sdh_finger_12_joint"/>
    <mechanicalReduction>1</mechanicalReduction>
  </transmission>
  <transmission name="sdh_finger_13_trans" type="pr2_mechanism_model/SimpleTransmission">
    <actuator name="sdh_finger_13_motor"/>
    <joint name="sdh_finger_13_joint"/>
    <mechanicalReduction>1</mechanicalReduction>
  </transmission>
  <transmission name="sdh_finger_22_trans" type="pr2_mechanism_model/SimpleTransmission">
    <actuator name="sdh_finger_22_motor"/>
    <joint name="sdh_finger_22_joint"/>
    <mechanicalReduction>1</mechanicalReduction>
  </transmission>
  <transmission name="sdh_finger_23_trans" type="pr2_mechanism_model/SimpleTransmission">
    <actuator name="sdh_finger_23_motor"/>
    <joint name="sdh_finger_23_joint"/>
    <mechanicalReduction>1</mechanicalReduction>
  </transmission>
  <transmission name="sdh_thumb_2_trans" type="pr2_mechanism_model/SimpleTransmission">
    <actuator name="sdh_thumb_2_motor"/>
    <joint name="sdh_thumb_2_joint"/>
    <mechanicalReduction>1</mechanicalReduction>
  </transmission>
  <transmission name="sdh_thumb_3_trans" type="pr2_mechanism_model/SimpleTransmission">
    <actuator name="sdh_thumb_3_motor"/>
    <joint name="sdh_thumb_3_joint"/>
    <mechanicalReduction>1</mechanicalReduction>
  </transmission>
</robot>

